Workbook
Name \M: #REF!
Name \Q: #REF!
Name \S: #REF!
Name \W: #REF!
Name \WQ: '[1]BAG-2'!#REF!
Name __ahu100: #REF!
Name __ahu150: #REF!
Name __bsc100: #REF!
Name __ewr4: #REF!
Name __grc1: #REF!
Name __gyp7: '[3]Harga Material'!#REF!
Name __ker1020: #REF!
Name __ker40: '[4]HB '!#REF!
Name __pah150: #REF!
Name __pav8: #REF!
Name __ph100: #REF!
Name __ph150: #REF!
Name __phf100: #REF!
Name __phf150: #REF!
Name __pv100: #REF!
Name __pv50: #REF!
Name __pv80: #REF!
Name __pvc1: #REF!
Name __pvc12: #REF!
Name __pvc3: #REF!
Name __pvc34: #REF!
Name __pvf100: #REF!
Name __pvf80: #REF!
Name __vnt100: #REF!
Name __vnt50: #REF!
Name __vnt80: #REF!
Name _abs100: #REF!
Name _ako100: #REF!
Name _ako150: #REF!
Name _ako50: #REF!
Name _ako80: #REF!
Name _aku100: #REF!
Name _aku150: #REF!
Name _bcv100: #REF!
Name _bcv125: #REF!
Name _bcv150: #REF!
Name _cas80: #REF!
Name _cvd100: #REF!
Name _cvd15: #REF!
Name _cvd150: #REF!
Name _cvd50: #REF!
Name _cvd65: #REF!
Name _dia6: #REF!
Name _fjd100: #REF!
Name _fjd150: #REF!
Name _fjd50: #REF!
Name _fjd65: #REF!
Name _fmd150: #REF!
Name _gra4040: #REF!
Name _gvd100: #REF!
Name _gvd15: #REF!
Name _gvd150: #REF!
Name _gvd25: #REF!
Name _gvd50: #REF!
Name _gvd65: #REF!

Sheet REKAP (Final Harga Kontrak)
A1: REKAPITULASI RENCANA ANGGARAN BIAYA
A2: PEKERJAAN | C2: : | D2: RUMAH Qur'an Az'Zakir
A3: OWNER | C3: : | D3: PT. Cipta Karya Serasi
A4: LOKASI | C4: : | D4: Cibinong, Bogor
A5: No | B5: URAIAN PEKERJAAN | E5: JUMLAH
E6: (Rp)
A8: ='BOQ (Final Harga Kontrak)'!A11 -> I | B8: ='BOQ (Final Harga Kontrak)'!B11 -> PEKERJAAN PERSIAPAN | E8: ='BOQ (Final Harga Kontrak)'!I21 -> 48550323
A9: ='BOQ (Final Harga Kontrak)'!A23 -> II | B9: ='BOQ (Final Harga Kontrak)'!B23 -> PEKERJAAN TANAH + PONDASI | E9: ='BOQ (Final Harga Kontrak)'!I62 -> 3.3891559e+08
A10: ='BOQ (Final Harga Kontrak)'!A65 -> III | B10: ='BOQ (Final Harga Kontrak)'!B65 -> PEKERJAAN BETON | E10: ='BOQ (Final Harga Kontrak)'!I87 -> 1.9741013e+08
A11: ='BOQ (Final Harga Kontrak)'!A89 -> IV | B11: ='BOQ (Final Harga Kontrak)'!B89 -> PEKERJAAN STRUKTUR BAJA | E11: ='BOQ (Final Harga Kontrak)'!I95 -> 2.0728286e+08
A12: ='BOQ (Final Harga Kontrak)'!A97 -> V | B12: ='BOQ (Final Harga Kontrak)'!B97 -> PEKERJAAN PASANGAN DINDING, LANTAI, PLESTERAN DAN ACIAN | E12: ='BOQ (Final Harga Kontrak)'!I109 -> 2.2252371e+08
A13: ='BOQ (Final Harga Kontrak)'!A111 -> VI | B13: ='BOQ (Final Harga Kontrak)'!B111 -> PEKERJAAN M & E | E13: ='BOQ (Final Harga Kontrak)'!I116 -> 14497640
A14: ='BOQ (Final Harga Kontrak)'!A118 -> VII | B14: ='BOQ (Final Harga Kontrak)'!B118 -> PEKERJAAN SANITAIR | E14: ='BOQ (Final Harga Kontrak)'!I124 -> 47623613
A15: ='BOQ (Final Harga Kontrak)'!A127 -> VIII | B15: ='BOQ (Final Harga Kontrak)'!B127 -> PEKERJAAN ATAP | E15: ='BOQ (Final Harga Kontrak)'!I135 -> 1.4153106e+08
A16: ='BOQ (Final Harga Kontrak)'!A137 -> IX | B16: ='BOQ (Final Harga Kontrak)'!B137 -> PEKERJAAN CARPORT | E16: ='BOQ (Final Harga Kontrak)'!I140 -> 24658510
A17: ='BOQ (Final Harga Kontrak)'!A142 -> X | B17: ='BOQ (Final Harga Kontrak)'!B142 -> PEKERJAAN LAIN-LAIN | E17: ='BOQ (Final Harga Kontrak)'!I149 -> 55506571
D18: JUMLAH I | E18: =SUM(E8:E17) -> 1.2985e+09
D19: PPH 23 (2%) | E19: ='BOQ (Final Harga Kontrak)'!I151 -> 26500000
E21: =E18+E19 -> 1.325e+09
D22: DIBULATKAN | E22: =ROUND(E21,-6) -> 1325000000

Sheet BOQ (Final Harga Kontrak)
A1: RENCANA ANGGARAN BIAYA | K1: NK Incl. PPh | L1: 1325000000
A2: PEKERJAAN | C2: : | D2: RUMAH Qur'an Az'Zakir | K2: PPh 2% | L2: =L1*2% -> 26500000
A3: OWNER | C3: : | D3: PT. Cipta Karya Serasi
A4: LOKASI | C4: : | D4: Cibinong, Bogor
A5: OWNER | C5: : | D5: PT. Cipta Karya Serasi | L5: =L1-L2 -> 1298500000
A6: LOKASI | C6: : | D6: Cibinong, Bogor
A8: NO | B8: URAIAN PEKERJAAN | E8: VOLUME | H8: Harga Satuan Material + Upah | I8: Jumlah Material + Upah
H9: (Rp) | I9: (Rp)
A10: I | B10: LANTAI 1
A11: I | B11: PEKERJAAN PERSIAPAN
A12: 1 | B12: Uitzet / Bowplank : | E12: 128 | F12: m1 | G12: 0.0020935991 | H12: =I12/E12 -> 21238.581 | I12: =$L$5*G12 -> 2718538.4
A13: 2 | B13: Pembersihan | E13: 854 | F13: m2 | G13: 0.0013968231 | H13: =I13/E13 -> 2123.8581 | I13: =$L$5*G13 -> 1813774.8
A14: 3 | B14: Instalasi Air Bersih, Sumur Bor | E14: 30 | F14: m | G14: 0.006951395 | H14: =I14/E14 -> 300879.55 | I14: =$L$5*G14 -> 9026386.5
A15: 4 | B15: Token Listrik | D15: (Daya Listrik 2200 Watt By owner) | E15: 1 | F15: ls | G15: 0.0020445304 | H15: =I15/E15 -> 2654822.7 | I15: =$L$5*G15 -> 2654822.7
A16: 5 | B16: Mobilisasi dan Remobilisasi | E16: 1 | F16: ls | G16: 0.0053335575 | H16: =I16/E16 -> 6925624.4 | I16: =$L$5*G16 -> 6925624.4
A17: 6 | B17: MCK | E17: 3 | F17: unit | G17: 0.00036883246 | H17: =I17/E17 -> 159642.98 | I17: =$L$5*G17 -> 478928.95
A18: 7 | B18: K3 Tools | E18: 1 | F18: ls | G18: 0.0071114099 | H18: =I18/E18 -> 9234165.8 | I18: =$L$5*G18 -> 9234165.8
A19: 8 | B19: Keamanan | E19: 8 | F19: ls | G19: 0.005689128 | H19: =I19/E19 -> 923416.58 | I19: =$L$5*G19 -> 7387332.7
A20: 9 | B20: Direksi Keet, Bedeng tenaga dan gudang material | E20: 30 | F20: m2 | G20: 0.006400269 | H20: =I20/E20 -> 277024.97 | I20: =$L$5*G20 -> 8310749.2
H21: 0 | I21: =SUM(I12:I20) -> 48550323
H22: 0
A23: II | B23: PEKERJAAN TANAH + PONDASI | H23: 0
A24: 1 | B24: Urugan Field | E24: 1 | F24: ls | G24: 0.04977987 | H24: =I24/E24 -> 64639161 | I24: =$L$5*G24 -> 64639161
A25: =A24+1 -> 2 | B25: Pekerjaan Beton Bore Pile BP-01 - K175 | E25: =3.14*0.15*0.15*6*18 -> 7.6302 | F25: m3 | G25: 0.0063336713 | H25: =I25/E25 -> 1077858 | I25: =$L$5*G25 -> 8224272.1
A26: =A25+1 -> 3 | B26: Pekerjaan Beton Bore Pile BP-02 - K175 | E26: =3.14*0.1*0.1*4*42 -> 5.2752 | F26: m3 | G26: 0.0043788345 | H26: =I26/E26 -> 1077858 | I26: =$L$5*G26 -> 5685916.5
A27: =A26+1 -> 4 | B27: Pekerjaan Pembesian Bore Pile BP-01 | E27: 877.61 | F27: kg | G27: 0.0080671741 | H27: =I27/E27 -> 11936.083 | I27: =$L$5*G27 -> 10475226
A28: =A27+1 -> 5 | B28: Pekerjaan Pembesian Bore Pile BP-02 | E28: 1411.64 | F28: kg | G28: 0.012976089 | H28: =I28/E28 -> 11936.083 | I28: =$L$5*G28 -> 16849452
A29: =A28+1 -> 6 | B29: Galian Tanah : PC-01 (0,6x0,6) | E29: =0.6*0.6*0.3*50 -> 5.4 | F29: m3 | G29: 0.00034465448 | H29: =I29/E29 -> 82876.638 | I29: =$L$5*G29 -> 447533.85
A30: =A29+1 -> 7 | B30: Galian Tanah : PC-02 (0,8x0,8) | E30: =0.8*0.8*0.3*30 -> 5.76 | F30: m3 | G30: 0.00036763145 | H30: =I30/E30 -> 82876.638 | I30: =$L$5*G30 -> 477369.44
A31: =A30+1 -> 8 | B31: Pasir Urug : PC-01 (Tebal 5 cm) | E31: =(0.6*0.6*0.05)*50 -> 0.9 | F31: m3 | G31: 5.5896749e-05 | H31: =I31/E31 -> 80646.587 | I31: =$L$5*G31 -> 72581.928
A32: =A31+1 -> 9 | B32: Pasir Urug : PC-02 (Tebal 5 cm) | E32: =(0.8*0.8*0.05)*30 -> 0.96 | F32: m3 | G32: 5.9623199e-05 | H32: =I32/E32 -> 80646.587 | I32: =$L$5*G32 -> 77420.724
A33: =A32+1 -> 10 | B33: Lantai Kerja : PC-01 (Tebal 5 cm) | E33: =0.6*0.6*50 -> 18 | F33: m2 | G33: 0.0009162625 | H33: =I33/E33 -> 66098.159 | I33: =$L$5*G33 -> 1189766.9
A34: =A33+1 -> 11 | B34: Lantai Kerja : PC-02 (Tebal 5 cm) | E34: =0.8*0.8*30 -> 19.2 | F34: m2 | G34: 0.00097734667 | H34: =I34/E34 -> 66098.159 | I34: =$L$5*G34 -> 1269084.7
A35: =A34+1 -> 12 | B35: Pekerjaan Beton Pile Cap : PC-01 | E35: ='[40]VOLUME PC'!G16 -> 5.4 | F35: m3 | G35: 0.0044824284 | H35: =I35/E35 -> 1077858 | I35: =$L$5*G35 -> 5820433.2
A36: =A35+1 -> 13 | B36: Pekerjaan Beton Pile Cap : PC-02 | E36: ='[40]VOLUME PC'!G17 -> 7.488 | F36: m3 | G36: 0.006215634 | H36: =I36/E36 -> 1077858 | I36: =$L$5*G36 -> 8071000.7
A37: =A36+1 -> 14 | B37: Pekerjaan Pembesian Pile Cap : PC-01 | E37: 588.6 | F37: kg | G37: 0.0054105339 | H37: =I37/E37 -> 11936.083 | I37: =$L$5*G37 -> 7025578.3
A38: =A37+1 -> 15 | B38: Pekerjaan Pembesian Pile Cap : PC-02 | E38: 900.25 | F38: kg | G38: 0.0082752857 | H38: =I38/E38 -> 11936.083 | I38: =$L$5*G38 -> 10745458
A39: =A38+1 -> 16 | B39: Pekerjaan Bekisting Pile Cap : PC-01 | E39: ='[40]VOLUME PC'!I10 -> 39.6 | F39: m2 | G39: 0.0045987212 | H39: =I39/E39 -> 150793.93 | I39: =$L$5*G39 -> 5971439.5
A40: =A39+1 -> 17 | B40: Pekerjaan Bekisting Pile Cap : PC-02 | E40: ='[40]VOLUME PC'!I11 -> 62.4 | F40: m2 | G40: 0.0072464698 | H40: =I40/E40 -> 150793.93 | I40: =$L$5*G40 -> 9409541.1
A41: =A40+1 -> 18 | B41: Galian Tie Footplate F2 | E41: =(0.6*0.6*0.3)*17 -> 1.836 | F41: m3 | G41: 0.00011718252 | H41: =I41/E41 -> 82876.638 | I41: =$L$5*G41 -> 152161.51
...

Sheet Schedule & S-Cuve 
A1: RENCANA ANGGARAN BIAYA | S1: NK | T1: 1325000000 | Z1: Set | AA1: 350 | AB1: M2 | AD1: =1.8*1.2 -> 2.16 | AE1: M2/Set | AF1: =(AA1/AD1)*2.5 -> 405.09259 | AG1: set | AH1: 35000
A2: PEKERJAAN | C2: : | D2: RUMAH Qur'an Az'Zakir | Q2: Nilai Kontrak | R2: 1325000000 | T2: =21500000 -> 21500000 | V2: =T2/T1 -> 0.016226415 | AF2: =AF1*20% -> 81.018519 | AG2: set | AW2: Total
A3: OWNER | C3: : | D3: PT. Cipta Karya Serasi | Q3: BOQ | R3: =REKAP!E16 -> 26703560 | S3: RAP | T3: =T4*#REF! -> #REF! | X3: =#REF!*X4 -> #REF! | AB3: =#REF!*AB4 -> #REF! | AF3: =AF4*#REF! -> #REF! | AJ3: =AJ4*#REF! -> #REF! | AW3: =SUM(T3:AU3) -> #REF!
A4: LOKASI | C4: : | D4: Cibinong, Bogor | R4: =#REF!-R3 -> #REF! | T4: =SUM(T6:W6) -> 1.6018858e+08 | X4: =SUM(X6:Z6) -> 2.4688701e+08 | AB4: =SUM(AB6:AD6) -> 1.2978999e+08 | AF4: =SUM(AF6:AH6) -> 2.4755137e+08 | AJ4: =SUM(AJ6:AL6) -> 2.2569665e+08 | AW4: =SUM(T4:AU4) -> 1.0101136e+09
A5: OWNER | C5: : | D5: PT. Cipta Karya Serasi | S5: DP | T5: 0.2 | U5: =T1*T5 -> 265000000 | X5: =U5/7 -> 37857143 | AB5: =X5/U5 -> 0.14285714
A6: LOKASI | C6: : | D6: Cibinong, Bogor | Q6: BOQ | R6: =REKAP!E18 -> 1.4061909e+09 | S6: BOQ | T6: =T8*T1 -> 1.6018858e+08 | X6: =T1*X8 -> 2.4688701e+08 | AB6: =T1*AB8 -> 1.2978999e+08 | AF6: =AF8*T1 -> 2.4755137e+08 | AJ6: =AJ8*$T$1 -> 2.2569665e+08 | AN6: =AN8*$T$1 -> 1.8172446e+08 | AR6: =AR8*$T$1 -> 1.3316195e+08 | AW6: =SUM(T6:AU6) -> 1.325e+09
Q7: BOQ | R7: =REKAP!E19 -> 28123818 | S7: Rencana Pembayaran | T7: =T6-$X$5 -> 1.2233144e+08 | X7: =X6-$X$5 -> 2.0902987e+08 | AB7: =AB6-$X$5 -> 91932843 | AF7: =AF6-$X$5 -> 2.0969423e+08 | AJ7: =AJ6-$X$5 -> 1.878395e+08 | AN7: =AN6-$X$5 -> 1.4386732e+08 | AR7: =AR6-$X$5 -> 95304807 | AW7: =SUM(T7:AU7) -> 1.06e+09 | AX7: =AW6-AW7-U5 -> 2.3841858e-07
R8: =R2-R6 -> -81190907 | S8: Rencana Bobot Perbulan | T8: =SUM(T9:W9) -> 0.12089704 | X8: =SUM(X9:AA9) -> 0.18632982 | AB8: =SUM(AB9:AE9) -> 0.097954706 | AF8: =SUM(AF9:AI9) -> 0.18683122 | AJ8: =SUM(AJ9:AM9) -> 0.17033709 | AN8: =SUM(AN9:AQ9) -> 0.13715053 | AR8: =SUM(AR9:AU9) -> 0.10049958 | AW8: =SUM(T8:AU8) -> 1 | AX8: =1-AW8 -> 0
T9: =SUM(T13:T152) -> 0.039571671 | U9: =SUM(U13:U152) -> 0.039571671 | V9: =SUM(V13:V152) -> 0.028493141 | W9: =SUM(W13:W152) -> 0.013260559 | X9: =SUM(X13:X152) -> 0.025336916 | Y9: =SUM(Y13:Y152) -> 0.057689753 | Z9: =SUM(Z13:Z152) -> 0.057689753 | AA9: =SUM(AA13:AA152) -> 0.045613395 | ... AU9: =SUM(AU13:AU152) -> 0.0013145949 | AX9: Balance
A10: NO | B10: URAIAN PEKERJAAN | E10: VOLUME | G10: Haga Satuan Material | H10: Harga Satuan Upah | I10: Material + Upah | J10: Jumlah Harga Material | K10: Jumlah Harga Upah | L10: Jumlah Material + Upah | M10: K1 (10%) | N10: K2 (2,5%) | O10: K3 (2,5%) | P10: GM (15%) | Q10: Harga Satuan Material + Upah | R10: Total | S10: Bobot | T10: Juli 24 | X10: Agustus 24 | AB10: September 24 | AF10: Oktober 24 | AJ10: November 24 | AN10: Desember 24 | AR10: Januari 25
G11: (Rp) | H11: (Rp) | I11: (Rp) | J11: (Rp) | K11: (Rp) | L11: (Rp) | S11: (%) | T11: M1 | U11: M2 | V11: M3 | W11: M4 | X11: M5 | Y11: M6 | Z11: M7 | AA11: M8 | AB11: M9 | AC11: M10 | AD11: M11 | AE11: M12 | AF11: M13 | AG11: M14 | AH11: M15 | AI11: M16 | AJ11: M17 | AK11: M18 | AL11: M19 | AM11: M20 | AN11: M21 | AO11: M22 | AP11: M23 | AQ11: M24 | AR11: M25 | AS11: M26 | AT11: M27 | AU11: M28
A12: I | B12: LANTAI 1
A13: I | B13: PEKERJAAN PERSIAPAN
A14: 1 | B14: Uitzet / Bowplank : | E14: 128 | F14: m1 | G14: 10000 | H14: 10000 | I14: =H14+G14 -> 20000 | J14: =E14*G14 -> 1280000 | K14: =E14*H14 -> 1280000 | L14: 2944000 | P14: =I14*15% -> 3000 | Q14: =I14+M14+N14+O14+P14 -> 23000 | R14: =Q14*E14 -> 2944000 | S14: =R14/$R$6 -> 0.0020935991 | T14: =S14/2 -> 0.0010467995 | U14: =T14 -> 0.0010467995 | AW14: =SUM(T14:AU14) -> 0.0020935991 | AX14: =S14-AW14 -> 0
A15: 2 | B15: Pembersihan | E15: 854 | F15: m2 | G15: 0 | H15: 2000 | I15: =H15+G15 -> 2000 | J15: =E15*G15 -> 0 | K15: =E15*H15 -> 1708000 | L15: 1964200 | P15: =I15*15% -> 300 | Q15: =I15+M15+N15+O15+P15 -> 2300 | R15: =Q15*E15 -> 1964200 | S15: =R15/$R$6 -> 0.0013968231 | T15: =S15/2 -> 0.00069841157 | U15: =T15 -> 0.00069841157 | AW15: =SUM(T15:AU15) -> 0.0013968231 | AX15: =S15-AW15 -> 0
A16: 3 | B16: Instalasi Air Bersih, Sumur Bor | E16: 30 | F16: m | G16: 183333 | H16: 100000 | I16: =H16+G16 -> 283333 | J16: =E16*G16 -> 5499990 | K16: =E16*H16 -> 3000000 | L16: 9774988.5 | P16: =I16*15% -> 42499.95 | Q16: =I16+M16+N16+O16+P16 -> 325832.95 | R16: =Q16*E16 -> 9774988.5 | S16: =R16/$R$6 -> 0.006951395 | T16: =S16/2 -> 0.0034756975 | U16: =T16 -> 0.0034756975 | AW16: =SUM(T16:AU16) -> 0.006951395 | AX16: =S16-AW16 -> 0
A17: 4 | B17: Token Listrik | D17: (Daya Listrik 2200 Watt By owner) | E17: 1 | F17: ls | G17: 1500000 | H17: 1000000 | I17: =H17+G17 -> 2500000 | J17: =E17*G17 -> 1500000 | K17: =E17*H17 -> 1000000 | L17: 2875000 | P17: =I17*15% -> 375000 | Q17: =I17+M17+N17+O17+P17 -> 2875000 | R17: =Q17*E17 -> 2875000 | S17: =R17/$R$6 -> 0.0020445304 | T17: =S17/2 -> 0.0010222652 | U17: =T17 -> 0.0010222652 | AW17: =SUM(T17:AU17) -> 0.0020445304 | AX17: =S17-AW17 -> 0
A18: 5 | B18: Mobilisasi dan Remobilisasi | E18: 1 | F18: ls | G18: 0 | H18: 7500000 | I18: =H18+G18 -> 7500000 | J18: =E18*G18 -> 0 | K18: =E18*H18 -> 7500000 | L18: 7500000 | Q18: =I18+M18+N18+O18+P18 -> 7500000 | R18: =Q18*E18 -> 7500000 | S18: =R18/$R$6 -> 0.0053335575 | T18: =S18/2 -> 0.0026667787 | U18: =T18 -> 0.0026667787 | AW18: =SUM(T18:AU18) -> 0.0053335575 | AX18: =S18-AW18 -> 0
A19: 6 | B19: MCK | E19: 3 | F19: unit | G19: 111333 | H19: 39000 | I19: =H19+G19 -> 150333 | J19: =E19*G19 -> 333999 | K19: =E19*H19 -> 117000 | L19: 518648.85 | P19: =I19*15% -> 22549.95 | Q19: =I19+M19+N19+O19+P19 -> 172882.95 | R19: =Q19*E19 -> 518648.85 | S19: =R19/$R$6 -> 0.00036883246 | T19: =S19/2 -> 0.00018441623 | U19: =T19 -> 0.00018441623 | AW19: =SUM(T19:AU19) -> 0.00036883246 | AX19: =S19-AW19 -> 0
A20: 7 | B20: K3 Tools | E20: 1 | F20: ls | G20: 10000000 | J20: =E20*G20 -> 10000000 | L20: 10000000 | R20: =Q20+L20 -> 10000000 | S20: =R20/$R$6 -> 0.0071114099 | T20: =S20/2 -> 0.003555705 | U20: =T20 -> 0.003555705 | AW20: =SUM(T20:AU20) -> 0.0071114099 | AX20: =S20-AW20 -> 0
A21: 8 | B21: Keamanan | E21: 8 | F21: ls | H21: 1000000 | J21: =E21*G21 -> 0 | K21: =H21*E21 -> 8000000 | L21: 8000000 | P21: =I21*15% -> 0 | R21: 8000000 | S21: =R21/$R$6 -> 0.005689128 | T21: =S21/28 -> 0.00020318314 | U21: =T21 -> 0.00020318314 | V21: =U21 -> 0.00020318314 | W21: =V21 -> 0.00020318314 | X21: =W21 -> 0.00020318314 | Y21: =X21 -> 0.00020318314 | Z21: =Y21 -> 0.00020318314 | AA21: =Z21 -> 0.00020318314 | AB21: =AA21 -> 0.00020318314 | ... AU21: =AT21 -> 0.00020318314 | AW21: =SUM(T21:AU21) -> 0.005689128 | AX21: =S21-AW21 -> 0
A22: 9 | B22: Direksi Keet, Bedeng tenaga dan gudang material | E22: 30 | F22: m2 | G22: 250000 | H22: 50000 | I22: =H22+G22 -> 300000 | J22: =E22*G22 -> 7500000 | K22: =E22*H22 -> 1500000 | L22: 9000000 | Q22: =I22+M22+N22+O22+P22 -> 300000 | R22: =Q22*E22 -> 9000000 | S22: =R22/$R$6 -> 0.006400269 | T22: =S22/28 -> 0.00022858103 | U22: =T22 -> 0.00022858103 | V22: =U22 -> 0.00022858103 | W22: =V22 -> 0.00022858103 | X22: =W22 -> 0.00022858103 | Y22: =X22 -> 0.00022858103 | Z22: =Y22 -> 0.00022858103 | AA22: =Z22 -> 0.00022858103 | AB22: =AA22 -> 0.00022858103 | ... AU22: =AT22 -> 0.00022858103 | AW22: =SUM(T22:AU22) -> 0.006400269 | AX22: =S22-AW22 -> 0
L23: =SUM(L14:L22) -> 52576837 | Q23: Total | R23: =SUM(R14:R22) -> 52576837 | AW23: =SUM(T23:AU23) -> 0 | AX23: =S23-AW23 -> 0
AW24: =SUM(T24:AU24) -> 0 | AX24: =S24-AW24 -> 0
A25: II | B25: PEKERJAAN TANAH + PONDASI | AW25: =SUM(T25:AU25) -> 0 | AX25: =S25-AW25 -> 0
A26: 1 | B26: Urugan Field | E26: 1 | F26: ls | H26: 60000000 | I26: =H26+G26 -> 60000000 | J26: =E26*G26 -> 0 | K26: =E26*H26 -> 60000000 | L26: =K26+J26 -> 60000000 | M26: 10000000 | Q26: =M26+I26 -> 70000000 | R26: =Q26*E26 -> 70000000 | S26: =R26/$R$6 -> 0.04977987 | T26: =S26/3 -> 0.01659329 | U26: =T26 -> 0.01659329 | V26: =U26 -> 0.01659329 | AW26: =SUM(T26:AU26) -> 0.04977987 | AX26: =S26-AW26 -> 0
A27: =A26+1 -> 2 | B27: Pekerjaan Beton Bore Pile BP-01 - K175 | E27: =3.14*0.15*0.15*6*18 -> 7.6302 | F27: m3 | G27: =650000+(650000*10%) -> 715000 | H27: 300000 | I27: =H27+G27 -> 1015000 | J27: =E27*G27 -> 5455593 | K27: =E27*H27 -> 2289060 | L27: =K27+J27 -> 7744653 | P27: 152250 | Q27: =I27+M27+N27+O27+P27 -> 1167250 | R27: =Q27*E27 -> 8906350.9 | S27: =R27/$R$6 -> 0.0063336713 | V27: =S27/3 -> 0.0021112238 | W27: =V27 -> 0.0021112238 | X27: =W27 -> 0.0021112238 | AW27: =SUM(T27:AU27) -> 0.0063336713 | AX27: =S27-AW27 -> 0
A28: =A27+1 -> 3 | B28: Pekerjaan Beton Bore Pile BP-02 - K175 | E28: =3.14*0.1*0.1*4*42 -> 5.2752 | F28: m3 | G28: =G27 -> 715000 | H28: 300000 | I28: =H28+G28 -> 1015000 | J28: =E28*G28 -> 3771768 | K28: =E28*H28 -> 1582560 | L28: =K28+J28 -> 5354328 | P28: 152250 | Q28: =I28+M28+N28+O28+P28 -> 1167250 | R28: =Q28*E28 -> 6157477.2 | S28: =R28/$R$6 -> 0.0043788345 | V28: =S28/3 -> 0.0014596115 | W28: =V28 -> 0.0014596115 | X28: =W28 -> 0.0014596115 | AW28: =SUM(T28:AU28) -> 0.0043788345 | AX28: =S28-AW28 -> 0
A29: =A28+1 -> 4 | B29: Pekerjaan Pembesian Bore Pile BP-01 | E29: 877.61 | F29: kg | G29: =8400+(8400*10%) -> 9240 | H29: 2000 | I29: =H29+G29 -> 11240 | J29: =E29*G29 -> 8109116.4 | K29: =E29*H29 -> 1755220 | L29: =K29+J29 -> 9864336.4 | P29: 1686 | Q29: =I29+M29+N29+O29+P29 -> 12926 | R29: =Q29*E29 -> 11343987 | S29: =R29/$R$6 -> 0.0080671741 | V29: =S29/3 -> 0.002689058 | W29: =V29 -> 0.002689058 | X29: =W29 -> 0.002689058 | AW29: =SUM(T29:AU29) -> 0.0080671741 | AX29: =S29-AW29 -> 0
A30: =A29+1 -> 5 | B30: Pekerjaan Pembesian Bore Pile BP-02 | E30: 1411.64 | F30: kg | G30: =G29 -> 9240 | H30: 2000 | I30: =H30+G30 -> 11240 | J30: =E30*G30 -> 13043554 | K30: =E30*H30 -> 2823280 | L30: =K30+J30 -> 15866834 | P30: 1686 | Q30: =I30+M30+N30+O30+P30 -> 12926 | R30: =Q30*E30 -> 18246859 | S30: =R30/$R$6 -> 0.012976089 | V30: =S30/3 -> 0.0043253631 | W30: =V30 -> 0.0043253631 | X30: =W30 -> 0.0043253631 | AW30: =SUM(T30:AU30) -> 0.012976089 | AX30: =S30-AW30 -> 0
A31: =A30+1 -> 6 | B31: Galian Tanah : PC-01 (0,6x0,6) | E31: =0.6*0.6*0.3*50 -> 5.4 | F31: m3 | G31: 0 | H31: 65000 | I31: =H31+G31 -> 65000 | J31: =E31*G31 -> 0 | K31: =E31*H31 -> 351000 | L31: =(K31+J31)*130% -> 456300 | M31: 6500 | N31: 10000 | O31: 5000 | P31: 9750 | Q31: =I31+N31+O31+P31 -> 89750 | R31: =Q31*E31 -> 484650 | S31: =R31/$R$6 -> 0.00034465448 | W31: =S31/2 -> 0.00017232724 | X31: =W31 -> 0.00017232724 | AW31: =SUM(T31:AU31) -> 0.00034465448 | AX31: =S31-AW31 -> 0
A32: =A31+1 -> 7 | B32: Galian Tanah : PC-02 (0,8x0,8) | E32: =0.8*0.8*0.3*30 -> 5.76 | F32: m3 | G32: 0 | H32: 65000 | I32: =H32+G32 -> 65000 | J32: =E32*G32 -> 0 | K32: =E32*H32 -> 374400 | L32: =(K32+J32)*130% -> 486720 | M32: 6500 | N32: 10000 | O32: 5000 | P32: 9750 | Q32: =I32+N32+O32+P32 -> 89750 | R32: =Q32*E32 -> 516960 | S32: =R32/$R$6 -> 0.00036763145 | W32: =S32/2 -> 0.00018381572 | X32: =W32 -> 0.00018381572 | AW32: =SUM(T32:AU32) -> 0.00036763145 | AX32: =S32-AW32 -> 0
A33: =A32+1 -> 8 | B33: Pasir Urug : PC-01 (Tebal 5 cm) | E33: =(0.6*0.6*0.05)*50 -> 0.9 | F33: m3 | G33: 15400 | H33: 47500 | I33: =H33+G33 -> 62900 | J33: =E33*G33 -> 13860 | K33: =E33*H33 -> 42750 | L33: =K33+J33 -> 56610 | M33: 6290 | N33: 10000 | O33: 5000 | P33: 9435 | Q33: =I33+N33+O33+P33 -> 87335 | R33: =Q33*E33 -> 78601.5 | S33: =R33/$R$6 -> 5.5896749e-05 | W33: =S33/2 -> 2.7948374e-05 | X33: =W33 -> 2.7948374e-05 | AW33: =SUM(T33:AU33) -> 5.5896749e-05 | AX33: =S33-AW33 -> 0
A34: =A33+1 -> 9 | B34: Pasir Urug : PC-02 (Tebal 5 cm) | E34: =(0.8*0.8*0.05)*30 -> 0.96 | F34: m3 | G34: 15400 | H34: 47500 | I34: =H34+G34 -> 62900 | J34: =E34*G34 -> 14784 | K34: =E34*H34 -> 45600 | L34: =K34+J34 -> 60384 | M34: 6290 | N34: 10000 | O34: 5000 | P34: 9435 | Q34: =I34+N34+O34+P34 -> 87335 | R34: =Q34*E34 -> 83841.6 | S34: =R34/$R$6 -> 5.9623199e-05 | W34: =S34/2 -> 2.9811599e-05 | X34: =W34 -> 2.9811599e-05 | AW34: =SUM(T34:AU34) -> 5.9623199e-05 | AX34: =S34-AW34 -> 0
A35: =A34+1 -> 10 | B35: Lantai Kerja : PC-01 (Tebal 5 cm) | E35: =0.6*0.6*50 -> 18 | F35: m2 | G35: 13200 | H35: 36000 | I35: =H35+G35 -> 49200 | J35: =E35*G35 -> 237600 | K35: =E35*H35 -> 648000 | L35: =K35+J35 -> 885600 | M35: 4920 | N35: 10000 | O35: 5000 | P35: 7380 | Q35: =I35+N35+O35+P35 -> 71580 | R35: =Q35*E35 -> 1288440 | S35: =R35/$R$6 -> 0.0009162625 | W35: =S35/2 -> 0.00045813125 | X35: =W35 -> 0.00045813125 | AW35: =SUM(T35:AU35) -> 0.0009162625 | AX35: =S35-AW35 -> 0
A36: =A35+1 -> 11 | B36: Lantai Kerja : PC-02 (Tebal 5 cm) | E36: =0.8*0.8*30 -> 19.2 | F36: m2 | G36: 13200 | H36: 36000 | I36: =H36+G36 -> 49200 | J36: =E36*G36 -> 253440 | K36: =E36*H36 -> 691200 | L36: =K36+J36 -> 944640 | M36: 4920 | N36: 10000 | O36: 5000 | P36: 7380 | Q36: =I36+N36+O36+P36 -> 71580 | R36: =Q36*E36 -> 1374336 | S36: =R36/$R$6 -> 0.00097734667 | W36: =S36/2 -> 0.00048867334 | X36: =W36 -> 0.00048867334 | AW36: =SUM(T36:AU36) -> 0.00097734667 | AX36: =S36-AW36 -> 0
A37: =A36+1 -> 12 | B37: Pekerjaan Beton Pile Cap : PC-01 | E37: ='[40]VOLUME PC'!G16 -> 5.4 | F37: m3 | G37: =G28 -> 715000 | H37: 300000 | I37: =H37+G37 -> 1015000 | J37: =E37*G37 -> 3861000 | K37: =E37*H37 -> 1620000 | L37: =K37+J37 -> 5481000 | P37: 152250 | Q37: =I37+M37+N37+O37+P37 -> 1167250 | R37: =Q37*E37 -> 6303150 | S37: =R37/$R$6 -> 0.0044824284 | X37: =S37/3 -> 0.0014941428 | Y37: =X37 -> 0.0014941428 | Z37: =Y37 -> 0.0014941428 | AW37: =SUM(T37:AU37) -> 0.0044824284 | AX37: =S37-AW37 -> 0
A38: =A37+1 -> 13 | B38: Pekerjaan Beton Pile Cap : PC-02 | E38: ='[40]VOLUME PC'!G17 -> 7.488 | F38: m3 | G38: 715000 | H38: 300000 | I38: =H38+G38 -> 1015000 | J38: =E38*G38 -> 5353920 | K38: =E38*H38 -> 2246400 | L38: =K38+J38 -> 7600320 | P38: 152250 | Q38: =I38+M38+N38+O38+P38 -> 1167250 | R38: =Q38*E38 -> 8740368 | S38: =R38/$R$6 -> 0.006215634 | X38: =S38/3 -> 0.002071878 | Y38: =X38 -> 0.002071878 | Z38: =Y38 -> 0.002071878 | AW38: =SUM(T38:AU38) -> 0.006215634 | AX38: =S38-AW38 -> 0
A39: =A38+1 -> 14 | B39: Pekerjaan Pembesian Pile Cap : PC-01 | E39: 588.6 | F39: kg | G39: =G30 -> 9240 | H39: 2000 | I39: =H39+G39 -> 11240 | J39: =E39*G39 -> 5438664 | K39: =E39*H39 -> 1177200 | L39: =K39+J39 -> 6615864 | P39: 1686 | Q39: =I39+M39+N39+O39+P39 -> 12926 | R39: =Q39*E39 -> 7608243.6 | S39: =R39/$R$6 -> 0.0054105339 | X39: =S39/3 -> 0.0018035113 | Y39: =X39 -> 0.0018035113 | Z39: =Y39 -> 0.0018035113 | AW39: =SUM(T39:AU39) -> 0.0054105339 | AX39: =S39-AW39 -> 0
A40: =A39+1 -> 15 | B40: Pekerjaan Pembesian Pile Cap : PC-02 | E40: 900.25 | F40: kg | G40: 9240 | H40: 2000 | I40: =H40+G40 -> 11240 | J40: =E40*G40 -> 8318310 | K40: =E40*H40 -> 1800500 | L40: =K40+J40 -> 10118810 | P40: 1686 | Q40: =I40+M40+N40+O40+P40 -> 12926 | R40: =Q40*E40 -> 11636632 | S40: =R40/$R$6 -> 0.0082752857 | X40: =S40/3 -> 0.0027584286 | Y40: =X40 -> 0.0027584286 | Z40: =Y40 -> 0.0027584286 | AW40: =SUM(T40:AU40) -> 0.0082752857 | AX40: =S40-AW40 -> 0
...

Sheet RAB
A1: RENCANA ANGGARAN BIAYA
A2: PEKERJAAN | C2: : | D2: RUMAH Qur'an Az'Zakir
A3: OWNER | C3: : | D3: PT. Cipta Karya Serasi
A4: LOKASI | C4: : | D4: Cibinong, Bogor
A6: NO | B6: URAIAN PEKERJAAN | E6: VOLUME | G6: Haga Satuan Material | H6: Harga Satuan Upah | I6: Material + Upah | J6: Jumlah Harga Material | K6: Jumlah Harga Upah | L6: Jumlah Material + Upah
G7: (Rp) | H7: (Rp) | I7: (Rp) | J7: (Rp) | K7: (Rp) | L7: (Rp)
A8: I | B8: LANTAI 1
A9: I | B9: PEKERJAAN PERSIAPAN
A10: 1 | B10: Uitzet / Bowplank : | E10: 128 | F10: m1 | G10: 10000 | H10: 10000 | I10: =H10+G10 -> 20000 | J10: =E10*G10 -> 1280000 | K10: =E10*H10 -> 1280000 | L10: 2944000
A11: 2 | B11: Pembersihan | E11: 854 | F11: m2 | G11: 0 | H11: 5000 | I11: =H11+G11 -> 5000 | J11: =E11*G11 -> 0 | K11: =E11*H11 -> 4270000 | L11: 1964200
A12: 3 | B12: Instalasi Air Bersih, Sumur Bor | E12: 30 | F12: m | G12: 183333 | H12: 100000 | I12: =H12+G12 -> 283333 | J12: =E12*G12 -> 5499990 | K12: =E12*H12 -> 3000000 | L12: 9774988.5
A13: 4 | B13: Instalasi Listrik | E13: 1 | F13: ls | G13: 1500000 | H13: 1000000 | I13: =H13+G13 -> 2500000 | J13: =E13*G13 -> 1500000 | K13: =E13*H13 -> 1000000 | L13: 2875000
A14: 5 | B14: Mobilisasi dan Remobilisasi | E14: 1 | F14: ls | G14: 0 | H14: 7500000 | I14: =H14+G14 -> 7500000 | J14: =E14*G14 -> 0 | K14: =E14*H14 -> 7500000 | L14: 7500000
A15: 6 | B15: MCK | E15: 3 | F15: unit | G15: 111333 | H15: 39000 | I15: =H15+G15 -> 150333 | J15: =E15*G15 -> 333999 | K15: =E15*H15 -> 117000 | L15: 518648.85
A16: 7 | B16: K3 Tools | E16: 1 | F16: ls | G16: 10000000 | J16: =E16*G16 -> 10000000 | L16: 10000000
A17: 8 | B17: Keamanan | E17: 8 | F17: ls | H17: 1000000 | J17: =E17*G17 -> 0 | K17: =H17*E17 -> 8000000 | L17: 8000000
A18: 9 | B18: Direksi Keet, Bedeng tenaga dan gudang material | E18: 30 | F18: m2 | G18: 250000 | H18: 50000 | I18: =H18+G18 -> 300000 | J18: =E18*G18 -> 7500000 | K18: =E18*H18 -> 1500000 | L18: 9000000
L19: =SUM(L10:L18) -> 52576837
A21: II | B21: PEKERJAAN TANAH + PONDASI
A22: 1 | B22: Galian Tanah : PC-01 (0,6x0,6) | E22: =0.6*0.6*0.3*50 -> 5.4 | F22: m3 | G22: 0 | H22: 65000 | I22: =H22+G22 -> 65000 | J22: =E22*G22 -> 0 | K22: =E22*H22 -> 351000 | L22: =(K22+J22)*130% -> 456300
A23: =A22+1 -> 2 | B23: Galian Tanah : PC-02 (0,8x0,8) | E23: =0.8*0.8*0.3*30 -> 5.76 | F23: m3 | G23: 0 | H23: 65000 | I23: =H23+G23 -> 65000 | J23: =E23*G23 -> 0 | K23: =E23*H23 -> 374400 | L23: =(K23+J23)*130% -> 486720
A24: =A23+1 -> 3 | B24: Pasir Urug : PC-01 (Tebal 5 cm) | E24: =(0.6*0.6*0.05)*50 -> 0.9 | F24: m3 | G24: 15400 | H24: 37500 | I24: =H24+G24 -> 52900 | J24: =E24*G24 -> 13860 | K24: =E24*H24 -> 33750 | L24: =K24+J24 -> 47610
A25: =A24+1 -> 4 | B25: Pasir Urug : PC-02 (Tebal 5 cm) | E25: =(0.8*0.8*0.05)*30 -> 0.96 | F25: m3 | G25: 15400 | H25: 37500 | I25: =H25+G25 -> 52900 | J25: =E25*G25 -> 14784 | K25: =E25*H25 -> 36000 | L25: =K25+J25 -> 50784
A26: =A25+1 -> 5 | B26: Lantai Kerja : PC-01 (Tebal 5 cm) | E26: =0.6*0.6*50 -> 18 | F26: m2 | G26: 13200 | H26: 36000 | I26: =H26+G26 -> 49200 | J26: =E26*G26 -> 237600 | K26: =E26*H26 -> 648000 | L26: =K26+J26 -> 885600
A27: =A26+1 -> 6 | B27: Lantai Kerja : PC-02 (Tebal 5 cm) | E27: =0.8*0.8*30 -> 19.2 | F27: m2 | G27: 13200 | H27: 36000 | I27: =H27+G27 -> 49200 | J27: =E27*G27 -> 253440 | K27: =E27*H27 -> 691200 | L27: =K27+J27 -> 944640
A28: =A27+1 -> 7 | B28: Galian Tie Footplate F2 | E28: =(0.6*0.6*0.3)*17 -> 1.836 | F28: m3 | G28: 0 | H28: 65000 | I28: =H28+G28 -> 65000 | J28: =E28*G28 -> 0 | K28: =E28*H28 -> 119340 | L28: =K28+J28 -> 119340
A29: =A28+1 -> 8 | B29: Pasir Urug F2 (Tebal 5 cm) | E29: =(0.6*0.6*0.5)*17 -> 3.06 | F29: m3 | G29: 15400 | H29: 47500 | I29: =H29+G29 -> 62900 | J29: =E29*G29 -> 47124 | K29: =E29*H29 -> 145350 | L29: =K29+J29 -> 192474
A30: =A29+1 -> 9 | B30: Lantai Kerja F2 (Tebal 5 cm) | E30: =E29 -> 3.06 | F30: m3 | G30: 13200 | H30: 36000 | I30: =H30+G30 -> 49200 | J30: =E30*G30 -> 40392 | K30: =E30*H30 -> 110160 | L30: =K30+J30 -> 150552
A31: =A30+1 -> 10 | B31: Galian Tie Beam 2 | E31: ='[40]VOLUME BP & GALIAN'!F61 -> 18.013 | F31: m3 | H31: 65000 | I31: =H31+G31 -> 65000 | J31: =E31*G31 -> 0 | K31: =E31*H31 -> 1170845 | L31: =K31+J31 -> 1170845
A32: =A31+1 -> 11 | B32: Galian Tie Beam 3 | E32: ='[40]VOLUME BP & GALIAN'!F76 -> 9.769375 | F32: m3 | H32: 65000 | I32: =H32+G32 -> 65000 | J32: =E32*G32 -> 0 | K32: =E32*H32 -> 635009.38 | L32: =K32+J32 -> 635009.38
A33: =A32+1 -> 12 | B33: Galian Tie Beam 4 | E33: ='[40]VOLUME BP & GALIAN'!F108 -> 5.57388 | F33: m3 | H33: 65000 | I33: =H33+G33 -> 65000 | J33: =E33*G33 -> 0 | K33: =E33*H33 -> 362302.2 | L33: =K33+J33 -> 362302.2
A34: =A33+1 -> 13 | B34: Urugan Tanah Kembali | E34: =E22+E23 -> 11.16 | F34: m3 | H34: 35000 | I34: =H34+G34 -> 35000 | K34: =E34*H34 -> 390600 | L34: =K34+J34 -> 390600
A35: =A34+1 -> 14 | B35: Pekerjaan Beton Bore Pile BP-01 - K175 | E35: =3.14*0.15*0.15*6*18 -> 7.6302 | F35: m3 | G35: =650000+(650000*10%) -> 715000 | H35: 250000 | I35: =H35+G35 -> 965000 | J35: =E35*G35 -> 5455593 | K35: =E35*H35 -> 1907550 | L35: =K35+J35 -> 7363143
A36: =A35+1 -> 15 | B36: Pekerjaan Beton Bore Pile BP-02 - K175 | E36: =3.14*0.1*0.1*4*42 -> 5.2752 | F36: m3 | G36: =G35 -> 715000 | H36: 250000 | I36: =H36+G36 -> 965000 | J36: =E36*G36 -> 3771768 | K36: =E36*H36 -> 1318800 | L36: =K36+J36 -> 5090568
A37: =A36+1 -> 16 | B37: Pekerjaan Pembesian Bore Pile BP-01 | E37: 877.61 | F37: kg | G37: =8400+(8400*10%) -> 9240 | H37: 5000 | I37: =H37+G37 -> 14240 | J37: =E37*G37 -> 8109116.4 | K37: =E37*H37 -> 4388050 | L37: =K37+J37 -> 12497166
A38: =A37+1 -> 17 | B38: Pekerjaan Pembesian Bore Pile BP-02 | E38: 1411.64 | F38: kg | G38: =G37 -> 9240 | H38: 5000 | I38: =H38+G38 -> 14240 | J38: =E38*G38 -> 13043554 | K38: =E38*H38 -> 7058200 | L38: =K38+J38 -> 20101754
A39: =A38+1 -> 18 | B39: Pekerjaan Beton Pile Cap : PC-01 | E39: ='[40]VOLUME PC'!G16 -> 5.4 | F39: m3 | G39: 825000 | H39: 250000 | I39: =H39+G39 -> 1075000 | J39: =E39*G39 -> 4455000 | K39: =E39*H39 -> 1350000 | L39: =K39+J39 -> 5805000
A40: =A39+1 -> 19 | B40: Pekerjaan Beton Pile Cap : PC-02 | E40: ='[40]VOLUME PC'!G17 -> 7.488 | F40: m3 | G40: 825000 | H40: 250000 | I40: =H40+G40 -> 1075000 | J40: =E40*G40 -> 6177600 | K40: =E40*H40 -> 1872000 | L40: =K40+J40 -> 8049600
A41: =A40+1 -> 20 | B41: Pekerjaan Pembesian Pile Cap : PC-01 | E41: 588.6 | F41: kg | G41: =G38 -> 9240 | H41: 5000 | I41: =H41+G41 -> 14240 | J41: =E41*G41 -> 5438664 | K41: =E41*H41 -> 2943000 | L41: =K41+J41 -> 8381664
A42: =A41+1 -> 21 | B42: Pekerjaan Pembesian Pile Cap : PC-02 | E42: 900.25 | F42: kg | G42: 9240 | H42: 5000 | I42: =H42+G42 -> 14240 | J42: =E42*G42 -> 8318310 | K42: =E42*H42 -> 4501250 | L42: =K42+J42 -> 12819560
...

Sheet VOLUME
A1: No | B1: Item | C1: Jumlah Pondasi (pcs) | D1: Diameter (m) | E1: Kedalaman (m) | F1: Jumlah Tulangan Besi Utama | G1: Diameter Besi Utama (m) | H1: Panjang Besi Tulangan Utama (m) | I1: Jarak Antar Besi Sengkang (m) | J1: Diameter Besi Sengkang (m) | K1: Jumlah Tulangan Besi Sengkang | L1: Panjang Besi Sengkang (m) | M1: Berat Besi Utama (btg) | N1: Berat Besi Sengkang (btg) | O1: Berat Besi Utama (kg) | P1: Berat Besi Sengkang (kg) | Q1: Total Kebutuhan Besi Utama (btg) | R1: Total Kebutuhan Besi Sengkang (btg) | S1: Total Berat Besi Utama (kg) | T1: Total Berat Besi Sengkang (kg) | U1: Panjang Overlap (m) | V1: Total Berat Besi Overlap (kg) | W1: Total Berat Besi (kg)
A2: 1 | B2: BP-01 | C2: 18 | D2: 0.3 | E2: 6 | F2: 6 | G2: 0.013 | H2: =E2*F2 -> 36 | I2: 0.15 | J2: 0.008 | K2: =(E2/I2)+1 -> 41 | L2: =K2*(0.942478) -> 38.641598 | M2: 12.5 | N2: 4.74 | O2: =(H2/12)*M2 -> 37.5 | P2: =(L2/12)*N2 -> 15.263431 | Q2: =ROUNDUP(H2/12,0) -> 3 | R2: =ROUNDUP(L2/12,0) -> 4 | S2: =C2*O2 -> 675 | T2: =C2*P2 -> 274.74176 | U2: =40*G2*F2*C2 -> 56.16 | V2: =U2/12*M2 -> 58.5 | W2: =S2+T2+U2 -> 1005.9018
A3: 2 | B3: BP-02 | C3: 42 | D3: 0.2 | E3: 4 | F3: 6 | G3: 0.013 | H3: =E3*F3 -> 24 | I3: 0.15 | J3: 0.008 | K3: =(E3/I3)+1 -> 27.666667 | L3: =K3*(0.942478) -> 26.075225 | M3: 12.5 | N3: 4.74 | O3: =(H3/12)*M3 -> 25 | P3: =(L3/12)*N3 -> 10.299714 | Q3: =ROUNDUP(H3/12,0) -> 2 | R3: =ROUNDUP(L3/12,0) -> 3 | S3: =C3*O3 -> 1050 | T3: =C3*P3 -> 432.58798 | U3: =40*G3*F3*C3 -> 131.04 | V3: =U3/12*M3 -> 136.5 | W3: =S3+T3+U3 -> 1613.628

Sheet REKAP
A1: REKAPITULASI RENCANA ANGGARAN BIAYA | E1: =E22-E4 -> 109000000
A2: PEKERJAAN | C2: : | D2: RUMAH Qur'an Az'Zakir
A3: OWNER | C3: : | D3: PT. Cipta Karya Serasi | E3: Final harga
A4: LOKASI | C4: : | D4: Cibinong, Bogor | E4: 1325000000
A5: No | B5: URAIAN PEKERJAAN | E5: JUMLAH | F5: Bobot
E6: (Rp) | F6: (%)
A8: I | B8: =BOQ!B9 -> PEKERJAAN PERSIAPAN | E8: 52576837 | F8: =E8/$E$18 -> 0.037389544
A9: II | B9: PEKERJAAN TANAH + PONDASI | E9: 8088203.9 | F9: =E9/$E$18 -> 0.0057518534
A10: III | B10: =BOQ!B62 -> PEKERJAAN BETON | E10: 5.0271761e+08 | F10: =E10/$E$18 -> 0.3575031
A11: IV | B11: PEKERJAAN STRUKTUR BAJA | E11: 2.2447383e+08 | F11: =E11/$E$18 -> 0.15963254
A12: V | B12: PEKERJAAN PASANGAN DINDING, LANTAI, PLESTERAN DAN ACIAN | E12: 2.4097868e+08 | F12: =E12/$E$18 -> 0.17136982
A13: VI | B13: PEKERJAAN Instalasi M & E | E13: 15700000 | F13: =E13/$E$18 -> 0.011164914
A14: VII | B14: PEKERJAAN SANITAIR | E14: 51573270 | F14: =E14/$E$18 -> 0.036675867
A15: VIII | B15: PEKERJAAN ATAP | E15: 153268916 | F15: =E15/$E$18 -> 0.10899581
A16: IX | B16: PEKERJAAN CARPORT | E16: 26703560 | F16: =E16/$E$18 -> 0.018989996
A17: X | B17: PEKERJAAN LAIN-LAIN | E17: 130110000 | F17: =E17/$E$18 -> 0.092526555
D18: JUMLAH I | E18: =SUM(E8:E17) -> 1.4061909e+09
D19: PPH 23 (2%) | E19: =E18*2% -> 28123818
E21: =E18+E19 -> 1.4343147e+09
D22: DIBULATKAN | E22: =ROUND(E21,-6) -> 1434000000

Sheet BOQ
A1: RENCANA ANGGARAN BIAYA
A2: PEKERJAAN | C2: : | D2: RUMAH Qur'an Az'Zakir | Q2: Nilai Kontrak | R2: 1325000000
A3: OWNER | C3: : | D3: PT. Cipta Karya Serasi | Q3: BOQ | R3: =REKAP!E18 -> 1.4061909e+09
A4: LOKASI | C4: : | D4: Cibinong, Bogor | R4: =R2-R3 -> -81190907
A6: NO | B6: URAIAN PEKERJAAN | E6: VOLUME | G6: Haga Satuan Material | H6: Harga Satuan Upah | I6: Material + Upah | J6: Jumlah Harga Material | K6: Jumlah Harga Upah | L6: Jumlah Material + Upah | M6: K1 (10%) | N6: K2 (2,5%) | O6: K3 (2,5%) | P6: GM (15%) | Q6: Harga Satuan Material + Upah | R6: Total | S6: Bobot
G7: (Rp) | H7: (Rp) | I7: (Rp) | J7: (Rp) | K7: (Rp) | L7: (Rp) | S7: (%)
A8: I | B8: LANTAI 1
A9: I | B9: PEKERJAAN PERSIAPAN
A10: 1 | B10: Uitzet / Bowplank : | E10: 128 | F10: m1 | G10: 10000 | H10: 10000 | I10: =H10+G10 -> 20000 | J10: =E10*G10 -> 1280000 | K10: =E10*H10 -> 1280000 | L10: 2944000 | P10: =I10*15% -> 3000 | Q10: =I10+M10+N10+O10+P10 -> 23000 | R10: =Q10*E10 -> 2944000 | S10: =R10/$R$3 -> 0.0020935991
A11: 2 | B11: Pembersihan | E11: 854 | F11: m2 | G11: 0 | H11: 2000 | I11: =H11+G11 -> 2000 | J11: =E11*G11 -> 0 | K11: =E11*H11 -> 1708000 | L11: 1964200 | P11: =I11*15% -> 300 | Q11: =I11+M11+N11+O11+P11 -> 2300 | R11: =Q11*E11 -> 1964200 | S11: =R11/$R$3 -> 0.0013968231
A12: 3 | B12: Instalasi Air Bersih, Sumur Bor | E12: 30 | F12: m | G12: 183333 | H12: 100000 | I12: =H12+G12 -> 283333 | J12: =E12*G12 -> 5499990 | K12: =E12*H12 -> 3000000 | L12: 9774988.5 | P12: =I12*15% -> 42499.95 | Q12: =I12+M12+N12+O12+P12 -> 325832.95 | R12: =Q12*E12 -> 9774988.5 | S12: =R12/$R$3 -> 0.006951395
A13: 4 | B13: Instalasi Listrik | E13: 1 | F13: ls | G13: 1500000 | H13: 1000000 | I13: =H13+G13 -> 2500000 | J13: =E13*G13 -> 1500000 | K13: =E13*H13 -> 1000000 | L13: 2875000 | P13: =I13*15% -> 375000 | Q13: =I13+M13+N13+O13+P13 -> 2875000 | R13: =Q13*E13 -> 2875000 | S13: =R13/$R$3 -> 0.0020445304
A14: 5 | B14: Mobilisasi dan Remobilisasi | E14: 1 | F14: ls | G14: 0 | H14: 7500000 | I14: =H14+G14 -> 7500000 | J14: =E14*G14 -> 0 | K14: =E14*H14 -> 7500000 | L14: 7500000 | Q14: =I14+M14+N14+O14+P14 -> 7500000 | R14: =Q14*E14 -> 7500000 | S14: =R14/$R$3 -> 0.0053335575
A15: 6 | B15: MCK | E15: 3 | F15: unit | G15: 111333 | H15: 39000 | I15: =H15+G15 -> 150333 | J15: =E15*G15 -> 333999 | K15: =E15*H15 -> 117000 | L15: 518648.85 | P15: =I15*15% -> 22549.95 | Q15: =I15+M15+N15+O15+P15 -> 172882.95 | R15: =Q15*E15 -> 518648.85 | S15: =R15/$R$3 -> 0.00036883246
A16: 7 | B16: K3 Tools | E16: 1 | F16: ls | G16: 10000000 | J16: =E16*G16 -> 10000000 | L16: 10000000 | R16: =Q16+L16 -> 10000000 | S16: =R16/$R$3 -> 0.0071114099
A17: 8 | B17: Keamanan | E17: 8 | F17: ls | H17: 1000000 | J17: =E17*G17 -> 0 | K17: =H17*E17 -> 8000000 | L17: 8000000 | P17: =I17*15% -> 0 | R17: 8000000 | S17: =R17/$R$3 -> 0.005689128
A18: 9 | B18: Direksi Keet, Bedeng tenaga dan gudang material | E18: 30 | F18: m2 | G18: 250000 | H18: 50000 | I18: =H18+G18 -> 300000 | J18: =E18*G18 -> 7500000 | K18: =E18*H18 -> 1500000 | L18: 9000000 | Q18: =I18+M18+N18+O18+P18 -> 300000 | R18: =Q18*E18 -> 9000000 | S18: =R18/$R$3 -> 0.006400269
L19: =SUM(L10:L18) -> 52576837 | Q19: Total | R19: =SUM(R10:R18) -> 52576837
A21: II | B21: PEKERJAAN TANAH + PONDASI
A22: 1 | B22: Galian Tanah : PC-01 (0,6x0,6) | E22: =0.6*0.6*0.3*50 -> 5.4 | F22: m3 | G22: 0 | H22: 65000 | I22: =H22+G22 -> 65000 | J22: =E22*G22 -> 0 | K22: =E22*H22 -> 351000 | L22: =(K22+J22)*130% -> 456300 | M22: 6500 | N22: 10000 | O22: 5000 | P22: 9750 | Q22: =I22+N22+O22+P22 -> 89750 | R22: =Q22*E22 -> 484650 | S22: =R22/$R$3 -> 0.00034465448
A23: 2 | B23: Galian Tanah : PC-02 (0,8x0,8) | E23: =0.8*0.8*0.3*30 -> 5.76 | F23: m3 | G23: 0 | H23: 65000 | I23: =H23+G23 -> 65000 | J23: =E23*G23 -> 0 | K23: =E23*H23 -> 374400 | L23: =(K23+J23)*130% -> 486720 | M23: 6500 | N23: 10000 | O23: 5000 | P23: 9750 | Q23: =I23+N23+O23+P23 -> 89750 | R23: =Q23*E23 -> 516960 | S23: =R23/$R$3 -> 0.00036763145
A24: 4 | B24: Pasir Urug : PC-01 (Tebal 5 cm) | E24: =(0.6*0.6*0.05)*50 -> 0.9 | F24: m3 | G24: 15400 | H24: 47500 | I24: =H24+G24 -> 62900 | J24: =E24*G24 -> 13860 | K24: =E24*H24 -> 42750 | L24: =K24+J24 -> 56610 | M24: 6290 | N24: 10000 | O24: 5000 | P24: 9435 | Q24: =I24+N24+O24+P24 -> 87335 | R24: =Q24*E24 -> 78601.5 | S24: =R24/$R$3 -> 5.5896749e-05
A25: 5 | B25: Pasir Urug : PC-02 (Tebal 5 cm) | E25: =(0.8*0.8*0.05)*30 -> 0.96 | F25: m3 | G25: 15400 | H25: 47500 | I25: =H25+G25 -> 62900 | J25: =E25*G25 -> 14784 | K25: =E25*H25 -> 45600 | L25: =K25+J25 -> 60384 | M25: 6290 | N25: 10000 | O25: 5000 | P25: 9435 | Q25: =I25+N25+O25+P25 -> 87335 | R25: =Q25*E25 -> 83841.6 | S25: =R25/$R$3 -> 5.9623199e-05
A26: 7 | B26: Lantai Kerja : PC-01 (Tebal 5 cm) | E26: =0.6*0.6*50 -> 18 | F26: m2 | G26: 13200 | H26: 36000 | I26: =H26+G26 -> 49200 | J26: =E26*G26 -> 237600 | K26: =E26*H26 -> 648000 | L26: =K26+J26 -> 885600 | M26: 4920 | N26: 10000 | O26: 5000 | P26: 7380 | Q26: =I26+N26+O26+P26 -> 71580 | R26: =Q26*E26 -> 1288440 | S26: =R26/$R$3 -> 0.0009162625
A27: 8 | B27: Lantai Kerja : PC-02 (Tebal 5 cm) | E27: =0.8*0.8*30 -> 19.2 | F27: m2 | G27: 13200 | H27: 36000 | I27: =H27+G27 -> 49200 | J27: =E27*G27 -> 253440 | K27: =E27*H27 -> 691200 | L27: =K27+J27 -> 944640 | M27: 4920 | N27: 10000 | O27: 5000 | P27: 7380 | Q27: =I27+N27+O27+P27 -> 71580 | R27: =Q27*E27 -> 1374336 | S27: =R27/$R$3 -> 0.00097734667
A28: 10 | B28: Galian Tie Footplate F2 | E28: =(0.6*0.6*0.3)*17 -> 1.836 | F28: m3 | G28: 0 | H28: 65000 | I28: =H28+G28 -> 65000 | J28: =E28*G28 -> 0 | K28: =E28*H28 -> 119340 | L28: =K28+J28 -> 119340 | M28: 6500 | N28: 10000 | O28: 5000 | P28: 9750 | Q28: =I28+N28+O28+P28 -> 89750 | R28: =Q28*E28 -> 164781 | S28: =R28/$R$3 -> 0.00011718252
A29: 11 | B29: Pasir Urug F2 (Tebal 5 cm) | E29: =(0.6*0.6*0.5)*17 -> 3.06 | F29: m3 | G29: 15400 | H29: 47500 | I29: =H29+G29 -> 62900 | J29: =E29*G29 -> 47124 | K29: =E29*H29 -> 145350 | L29: =K29+J29 -> 192474 | M29: 6290 | N29: 10000 | O29: 5000 | P29: 9435 | Q29: =I29+N29+O29+P29 -> 87335 | R29: =Q29*E29 -> 267245.1 | S29: =R29/$R$3 -> 0.00019004895
A30: 12 | B30: Lantai Kerja F2 (Tebal 5 cm) | E30: =E29 -> 3.06 | F30: m3 | G30: 13200 | H30: 36000 | I30: =H30+G30 -> 49200 | J30: =E30*G30 -> 40392 | K30: =E30*H30 -> 110160 | L30: =K30+J30 -> 150552 | M30: 4920 | N30: 10000 | O30: 5000 | P30: 7380 | Q30: =I30+N30+O30+P30 -> 71580 | R30: =Q30*E30 -> 219034.8 | S30: =R30/$R$3 -> 0.00015576463
A31: 13 | B31: Galian Tie Beam 2 | E31: ='[40]VOLUME BP & GALIAN'!F61 -> 18.013 | F31: m3 | H31: 65000 | I31: =H31+G31 -> 65000 | J31: =E31*G31 -> 0 | K31: =E31*H31 -> 1170845 | L31: =K31+J31 -> 1170845 | M31: 6500 | N31: 10000 | O31: 5000 | P31: 9750 | Q31: =I31+N31+O31+P31 -> 89750 | R31: =Q31*E31 -> 1616666.8 | S31: =R31/$R$3 -> 0.001149678
A32: 14 | B32: Galian Tie Beam 3 | E32: ='[40]VOLUME BP & GALIAN'!F76 -> 9.769375 | F32: m3 | H32: 65000 | I32: =H32+G32 -> 65000 | J32: =E32*G32 -> 0 | K32: =E32*H32 -> 635009.38 | L32: =K32+J32 -> 635009.38 | M32: 6500 | N32: 10000 | O32: 5000 | P32: 9750 | Q32: =I32+N32+O32+P32 -> 89750 | R32: =Q32*E32 -> 876801.41 | S32: =R32/$R$3 -> 0.00062352942
A33: 15 | B33: Galian Tie Beam 4 | E33: ='[40]VOLUME BP & GALIAN'!F108 -> 5.57388 | F33: m3 | H33: 65000 | I33: =H33+G33 -> 65000 | J33: =E33*G33 -> 0 | K33: =E33*H33 -> 362302.2 | L33: =K33+J33 -> 362302.2 | M33: 6500 | N33: 10000 | O33: 5000 | P33: 9750 | Q33: =I33+N33+O33+P33 -> 89750 | R33: =Q33*E33 -> 500255.73 | S33: =R33/$R$3 -> 0.00035575236
A34: 16 | B34: Urugan Tanah Kembali | E34: =E22+E23 -> 11.16 | F34: m3 | H34: 35000 | I34: =H34+G34 -> 35000 | K34: =E34*H34 -> 390600 | L34: =K34+J34 -> 390600 | M34: 3500 | N34: 10000 | O34: 5000 | P34: 5250 | Q34: =I34+N34+O34+P34 -> 55250 | R34: =Q34*E34 -> 616590 | S34: =R34/$R$3 -> 0.00043848243
A35: 16 | B35: Pekerjaan Beton Bore Pile BP-01 - K175 | E35: =3.14*0.15*0.15*6*18 -> 7.6302 | F35: m3 | G35: =650000+(650000*10%) -> 715000 | H35: 300000 | I35: =H35+G35 -> 1015000 | J35: =E35*G35 -> 5455593 | K35: =E35*H35 -> 2289060 | L35: =K35+J35 -> 7744653 | P35: 152250 | Q35: =I35+M35+N35+O35+P35 -> 1167250 | R35: =Q35*E35 -> 8906350.9 | S35: =R35/$R$3 -> 0.0063336713
A36: =A35+1 -> 17 | B36: Pekerjaan Beton Bore Pile BP-02 - K175 | E36: =3.14*0.1*0.1*4*42 -> 5.2752 | F36: m3 | G36: =G35 -> 715000 | H36: 300000 | I36: =H36+G36 -> 1015000 | J36: =E36*G36 -> 3771768 | K36: =E36*H36 -> 1582560 | L36: =K36+J36 -> 5354328 | P36: 152250 | Q36: =I36+M36+N36+O36+P36 -> 1167250 | R36: =Q36*E36 -> 6157477.2 | S36: =R36/$R$3 -> 0.0043788345
A37: =A36+1 -> 18 | B37: Pekerjaan Pembesian Bore Pile BP-01 | E37: 877.61 | F37: kg | G37: =8400+(8400*10%) -> 9240 | H37: 2000 | I37: =H37+G37 -> 11240 | J37: =E37*G37 -> 8109116.4 | K37: =E37*H37 -> 1755220 | L37: =K37+J37 -> 9864336.4 | P37: 1686 | Q37: =I37+M37+N37+O37+P37 -> 12926 | R37: =Q37*E37 -> 11343987 | S37: =R37/$R$3 -> 0.0080671741
A38: =A37+1 -> 19 | B38: Pekerjaan Pembesian Bore Pile BP-02 | E38: 1411.64 | F38: kg | G38: =G37 -> 9240 | H38: 2000 | I38: =H38+G38 -> 11240 | J38: =E38*G38 -> 13043554 | K38: =E38*H38 -> 2823280 | L38: =K38+J38 -> 15866834 | P38: 1686 | Q38: =I38+M38+N38+O38+P38 -> 12926 | R38: =Q38*E38 -> 18246859 | S38: =R38/$R$3 -> 0.012976089
A39: =A38+1 -> 20 | B39: Pekerjaan Beton Pile Cap : PC-01 | E39: ='[40]VOLUME PC'!G16 -> 5.4 | F39: m3 | G39: =G36 -> 715000 | H39: 300000 | I39: =H39+G39 -> 1015000 | J39: =E39*G39 -> 3861000 | K39: =E39*H39 -> 1620000 | L39: =K39+J39 -> 5481000 | P39: 152250 | Q39: =I39+M39+N39+O39+P39 -> 1167250 | R39: =Q39*E39 -> 6303150 | S39: =R39/$R$3 -> 0.0044824284
A40: =A39+1 -> 21 | B40: Pekerjaan Beton Pile Cap : PC-02 | E40: ='[40]VOLUME PC'!G17 -> 7.488 | F40: m3 | G40: 715000 | H40: 300000 | I40: =H40+G40 -> 1015000 | J40: =E40*G40 -> 5353920 | K40: =E40*H40 -> 2246400 | L40: =K40+J40 -> 7600320 | P40: 152250 | Q40: =I40+M40+N40+O40+P40 -> 1167250 | R40: =Q40*E40 -> 8740368 | S40: =R40/$R$3 -> 0.006215634
A41: =A40+1 -> 22 | B41: Pekerjaan Pembesian Pile Cap : PC-01 | E41: 588.6 | F41: kg | G41: =G38 -> 9240 | H41: 2000 | I41: =H41+G41 -> 11240 | J41: =E41*G41 -> 5438664 | K41: =E41*H41 -> 1177200 | L41: =K41+J41 -> 6615864 | P41: 1686 | Q41: =I41+M41+N41+O41+P41 -> 12926 | R41: =Q41*E41 -> 7608243.6 | S41: =R41/$R$3 -> 0.0054105339
A42: =A41+1 -> 23 | B42: Pekerjaan Pembesian Pile Cap : PC-02 | E42: 900.25 | F42: kg | G42: 9240 | H42: 2000 | I42: =H42+G42 -> 11240 | J42: =E42*G42 -> 8318310 | K42: =E42*H42 -> 1800500 | L42: =K42+J42 -> 10118810 | P42: 1686 | Q42: =I42+M42+N42+O42+P42 -> 12926 | R42: =Q42*E42 -> 11636632 | S42: =R42/$R$3 -> 0.0082752857
...
