Workbook
Name \0: [1]Penjumlahan!#REF!
Name \0: [1]Penjumlahan!#REF!
Name \A: '[2]304-06'!#REF!
Name \A: '[2]304-06'!#REF!
Name \B: #REF!
Name \B: #REF!
Name \C: #REF!
Name \C: #REF!
Name \D: #REF!
Name \D: #REF!
Name \E: #REF!
Name \E: #REF!
Name \F: #REF!
Name \F: #REF!
Name \G: #REF!
Name \G: #REF!
Name \H: #REF!
Name \H: #REF!
Name \I: #REF!
Name \I: #REF!
Name \J: #REF!
Name \J: #REF!
Name \K: #REF!
Name \K: #REF!
Name \L: #REF!
Name \L: #REF!
Name \M: #REF!
Name \M: #REF!
Name \N: #REF!
Name \N: #REF!
Name \O: #REF!
Name \O: #REF!
Name \P: #REF!
Name \P: #REF!
Name \Q: #REF!
Name \Q: #REF!
Name \R: #REF!
Name \R: #REF!
Name \S: #REF!
Name \S: #REF!
Name \T: #REF!
Name \T: #REF!
Name \U: #REF!
Name \U: #REF!
Name \V: #REF!
Name \V: #REF!
Name \W: #REF!
Name \W: #REF!
Name \WQ: '[3]BAG-2'!#REF!
Name \WQ: '[3]BAG-2'!#REF!
Name \x: [4]Cover1!#REF!
Name \x: [4]Cover1!#REF!
Name \Y: #REF!
Name \Y: #REF!
Name \Z: #REF!
Name \Z: #REF!
Name ___: [5]ANALIS!#REF!
Name ___: [5]ANALIS!#REF!
Name ________C: #REF!
Name ________C: #REF!

Sheet Volume
B2: LEMBAR PERHITUNGAN VOLUME PEKERJAAN
B3: PROYEK | C3: : | D3: RENOVASI RUMAH TINGGAL
B4: LOKASI | C4: :
B5: TAHUN ANGGARAN | C5: : | D5: 2023
B6: BANGUNAN | C6: : | D6: RUMAH TINGGAL PONDOK INDAH
B7: GAMBAR SKET | E7: DIMENSI/PERHITUNGAN | P7: SCHEDULE | U7: Day
P8: PERSONIL
B9: CODE | C9: : | D9: PEKERJAAN CLEANING & PEMBONGKARAN | E9: 1 | F9: Pekerjaan Bongkaran dinding Pagar | P9: 4 | Q9: Hari | R9: x | S9: 3 | T9: Org | X9: 170000 | Y9: =P9*S9*X9 -> 2040000
F10: V | G10: = | H10: P (m) | J10: T (m)
H11: =3+5.3+6+6.3+4.6+4.5+7.5+17+6 -> 60.2 | I11: x | J11: 4 | K11: = | L11: =H11*J11 -> 240.8 | M11: m2
E13: 2 | F13: Pekerjaan Perbaikan Pagar Sementara (Seng) | P13: 4 | Q13: Hari | R13: x | S13: 4 | T13: Org
F14: V horizontal | G14: = | H14: P (m) | J14: T (m)
H15: =3+5.3+6+6.3+4.6+4.5+7.5+15 -> 52.2 | I15: x | J15: 2.5 | K15: = | L15: =H15*J15 -> 130.5 | M15: m2
F17: V Vertikal | G17: = | H17: P (m) | J17: T (m)
H18: =17+6+8 -> 31 | I18: x | J18: 2.5 | K18: = | L18: =H18*J18 -> 77.5 | M18: m2
E19: =E13+1 -> 3 | F19: Pekerjaan Cleaning Area Bedeng & Gudang
F20: V bedeng | G20: = | H20: P (m) | J20: L (m)
H21: 9 | I21: x | J21: 3 | K21: = | L21: =H21*J21 -> 27 | M21: m2 | P21: 3 | Q21: Hari | R21: x | S21: 3 | T21: Org | X21: 170000 | Y21: =P21*S21*X21 -> 1530000
F22: V Gudang | G22: = | H22: P (m) | J22: L (m) | Y22: 500000
H23: 9 | I23: x | J23: 3 | K23: = | L23: =H23*J23 -> 27 | M23: m2 | P23: 3 | Q23: Hari | R23: x | S23: 3 | T23: Org | X23: 170000 | Y23: =P23*S23*X23 -> 1530000
E24: =E19+1 -> 4 | F24: Pekerjaan Cleaning & Dewatering Basemant
F25: V | G25: = | H25: P (m) | J25: L (m) | P25: 5 | Q25: Hari | R25: x | S25: 4 | T25: Org
H26: =3+5.3+6+6.3+4.6+4.5+7.5 -> 37.2 | I26: x | J26: 16.5 | K26: = | L26: =H26*J26 -> 613.8 | M26: m2
E28: =E24+1 -> 5 | F28: Pekerjaan Cleaning & Dewatering Lantai 1
F29: V Area Kolam Renang | G29: = | H29: P (m) | J29: L (m) | P29: 4 | Q29: Hari | R29: x | S29: 4 | T29: Org
H30: =6.3+4.6+4.4+8.4 -> 23.7 | I30: x | J30: 5.6 | K30: = | L30: =H30*J30 -> 132.72 | M30: m2
F31: V Area Taman Depan | G31: = | H31: P (m) | J31: L (m) | P31: 3 | Q31: Hari | R31: x | S31: 3 | T31: Org
H32: =6.3+4.6+4.4+8.4+7 -> 30.7 | I32: x | J32: 9 | K32: = | L32: =H32*J32 -> 276.3 | M32: m2
E34: =E28+1 -> 6 | F34: Pembuangan Material Bekas Bongkaran
F35: Vol | G35: = | H35: 1 | I35: Ls | P35: 3 | Q35: Hari | R35: x | S35: 4 | T35: Org
B41: CODE | C41: : | D41: PEKERJAAN BEDENG, KANTOR DAN GUDANG | E41: 1 | F41: Sumber Air Bersih & Pompa (Oprasional) | P41: 6 | Q41: Hari | R41: x | S41: 3 | T41: Org
F42: Vol pompa | G42: = | H42: 1 | I42: Unit
F43: Vol Instalasi | G43: = | H43: 1 | I43: set
E45: =E41+1 -> 2 | F45: Pembuatan Bedeng | P45: 5 | Q45: Hari | R45: x | S45: 6 | T45: Org | X45: 170000 | Y45: =P45*S45*X45 -> 5100000
F46: V bedeng | G46: = | H46: P (m) | J46: L (m) | Y46: 7000000 | Z46: =SUM(Y45:Y46) -> 12100000
H47: 9 | I47: x | J47: 3 | K47: = | L47: =H47*J47 -> 27 | M47: m2
E49: =E45+1 -> 3 | F49: Instalasi Listrik & Air Bersih Bedeng & Kantor | P49: 2 | Q49: Hari | R49: x | S49: 2 | T49: Org
F50: V | G50: = | H50: 1 | I50: Ls
B56: CODE | C56: : | D56: PEKERJAAN STECKING OUT | E56: 1 | F56: Stecking Out | Z56: =SUM(Z57:Z66) -> 14540000
F57: Sewa Alat Total Station | G57: = | H57: 1 | I57: set | J57: x | K57: 5 | L57: Hr | Y57: 350000 | Z57: =H57*K57*Y57 -> 1750000
...

Sheet ANALISA ME
A2: DAFTAR ANALISA HARGA SATUAN PEKERJAAN
A3: Macam Pekerjaan (Bahan) | B3: Satuan | C3: Koef | D3: Harga Bahan/Upah | E3: Jumlah Harga Bahan | F3: Jumlah Harga Upah | G3: Total
A4: Pekerjaan Persiapan | B4: ( RSNI T-12-2002 )
A5: Pembersihan lahan | B5: RSNI T-12 : 6 .8
A6: Upah
A7: Pekerja | B7: OH | C7: 0.1 | D7: 121243 | F7: =D7*C7 -> 12124.3
A8: Peralatan | B8: Is | C8: 1 | D8: 42000 | F8: =D8*C8 -> 42000
A9: Mandor | B9: OH | C9: 0.005 | D9: 212400 | F9: =D9*C9 -> 1062
A10: Total | E10: 0 | F10: =SUM(F7:F9) -> 55186.3 | G10: =SUM(E10:F10) -> 55186.3
A12: Pengukuran dan Pemasangan Bouwplank | B12: RSNI T-12 : 6 . 4
A13: Bahan
A14: Kayu 5/7 (paling murah) | B14: m3 | C14: 0.012 | D14: 39000 | E14: =C14*D14 -> 468
A15: Kayu Papan Borneo super | B15: m3 | C15: 0.02 | D15: 6176400 | E15: =C15*D15 -> 123528
A16: paku 5-7 inch | B16: kg | C16: 0.007 | D16: 20700 | E16: =C16*D16 -> 144.9
A17: Upah
A18: Pekerja | B18: OH | C18: 0.1 | D18: 130000 | F18: =D18*C18 -> 13000
A19: Tukang Kayu | B19: OH | C19: 0.1 | D19: 200000 | F19: =D19*C19 -> 20000
A20: Kepala Tukang Kayu | B20: OH | C20: 0.01 | D20: 250000 | F20: =D20*C20 -> 2500
A21: Mandor | B21: OH | C21: 0.005 | D21: 260000 | F21: =D21*C21 -> 1300
A22: Total | E22: =SUM(E14:E21) -> 124140.9 | F22: =SUM(F18:F21) -> 36800 | G22: =SUM(E22:F22) -> 160940.9
A23: Pekerjaan Tanah | B23: ( SNI 2835 )
A24: Pek. Galian tanah pondasi | B24: SNI 2835 : 6 . 1
A25: Upah
A26: Pekerja | B26: OH | C26: 0.75 | D26: =D18 -> 130000 | F26: =C26*D26 -> 97500
A27: Mandor | B27: OH | C27: 0.025 | D27: =D19 -> 200000 | F27: =C27*D27 -> 5000
A28: Total | E28: 0 | F28: =SUM(F26:F27) -> 102500 | G28: =SUM(E28:F28) -> 102500
A30: Pek. Urugan Tanah Kembali | B30: SNI 2835 : 6 .9
A31: Upah
A32: Pekerja | B32: OH | C32: =C26/3 -> 0.25 | D32: =D18 -> 130000 | F32: =C32*D32 -> 32500
A33: Mandor | B33: OH | C33: =C27/3 -> 0.0083333333 | D33: =D19 -> 200000 | F33: =C33*D33 -> 1666.6667
A34: Total | E34: 0 | F34: =SUM(F32:F33) -> 34166.667 | G34: =SUM(E34:F34) -> 34166.667
A36: Pek.Urugan Pasir bawah pondasi | B36: SNI 2835 : 6 . 11
A37: Bahan
A38: Pasir urug | B38: m3 | C38: 1.2 | D38: 120000 | E38: =C38*D38 -> 144000
A39: Upah
A40: Pekerja | B40: OH | C40: 0.3 | D40: =D32 -> 130000 | F40: =C40*D40 -> 39000
A41: Mandor | B41: OH | C41: 0.01 | D41: =D33 -> 200000 | F41: =C41*D41 -> 2000
A42: Total | E42: =SUM(E38:E41) -> 144000 | F42: =SUM(F40:F41) -> 41000 | G42: =SUM(E42:F42) -> 185000
A44: Pekerjaan pondasi dan pasangan | B44: SNI 2836 & SNI 6897 & SNI 2837
A45: Pek. Pondasi batu kali 1:4 | B45: SNI 2836 : 6 . 2
...

Sheet ANALISA_BONGKAR DAN CLEANING
A13: Analisa Harga Satuan | G13: Lampiran-04
A14: Proyek : Pembangunan ASRAMA YAYASAN HASANAH KEBAJIKAN
A15: Lokasi : Bukit Cirendeu
A16: 1 | B16: m2 | C16: Membersihkan lapangan dan perataan
A18: Jenis Pekerjaan | D18: Harga satuan | E18: Upah | F18: Bahan | G18: Jumlah
A19: 0.1 | B19: org | C19: Pekerja | D19: 160000 | E19: =A19*D19 -> 16000 | F19: 0 | G19: =E19+F19 -> 16000
A20: 0.05 | B20: org | C20: Mandor | D20: 265000 | E20: =A20*D20 -> 13250 | F20: 0 | G20: =E20+F20 -> 13250
C21: JUMLAH ( BELUM PPN ) | E21: =SUM(E19:E20) -> 29250 | F21: 0 | G21: =SUM(G19:G20) -> 29250
C22: JASA 30 % | D22: 0.3 | E22: =E21*D22 -> 8775 | F22: =F21*D22 -> 0 | G22: =D22*G21 -> 8775
C23: JUMLAH | E23: =SUM(E21:E22) -> 38025 | F23: 0 | G23: =SUM(G21:G22) -> 38025
A25: 1 | B25: m3 | C25: Bongkaran Beton Bertulang
A27: Jenis Pekerjaan | D27: Harga satuan | E27: Upah | F27: Bahan | G27: Jumlah
A28: 6.667 | B28: org | C28: Pekerja | D28: 130000 | E28: =A28*D28 -> 866710 | F28: 0 | G28: =E28+F28 -> 866710
A29: 0.333 | B29: org | C29: Mandor | D29: 265000 | E29: =A29*D29 -> 88245 | F29: 0 | G29: =E29+F29 -> 88245
C30: JUMLAH ( BELUM PPN ) | E30: =SUM(E28:E29) -> 954955 | F30: 0 | G30: =SUM(G28:G29) -> 954955
C31: JASA 10 % | D31: 0.1 | E31: =E30*D31 -> 95495.5 | F31: =F30*D31 -> 0 | G31: =D31*G30 -> 95495.5
C32: JUMLAH | E32: =SUM(E30:E31) -> 1050450.5 | F32: 0 | G32: =SUM(G30:G31) -> 1050450.5 | R32: 19
R33: 12
A34: 1 | B34: m3 | C34: Bongkaran dinding tembok Bata Merah | H34: =7*1*0.15 -> 1.05 | R34: =R33*R32 -> 228
A36: Jenis Pekerjaan | D36: Harga satuan | E36: Upah | F36: Bahan | G36: Jumlah
A37: 6.667 | B37: org | C37: Pekerja | D37: 130000 | E37: =A37*D37 -> 866710 | F37: 0 | G37: =E37+F37 -> 866710
A38: 0.333 | B38: org | C38: Mandor | D38: 265000 | E38: =A38*D38 -> 88245 | F38: 0 | G38: =E38+F38 -> 88245
A39: 1 | B39: Ls | C39: Alat Bantu | D39: 13000 | E39: =A39*D39 -> 13000 | F39: 0 | G39: =E39+F39 -> 13000
C40: JUMLAH ( BELUM PPN ) | E40: =SUM(E37:E39) -> 967955 | F40: 0 | G40: =SUM(G37:G39) -> 967955
C41: JASA 10 % | D41: 0.3 | E41: =E40*D41 -> 290386.5 | F41: =F40*D41 -> 0 | G41: =D41*G40 -> 290386.5
A42: JUMLAH 1 M3 | E42: =SUM(E40:E41) -> 1258341.5 | F42: 0 | G42: =SUM(G40:G41) -> 1258341.5
A43: JUMLAH 7 M2 | E43: =E42/7 -> 179763.07 | F43: 0 | G43: =G42/7 -> 179763.07
A44: JUMLAH 1 M2 | E44: =E43/10 -> 17976.307 | F44: 0 | G44: =G43/10 -> 17976.307
A46: 1 | B46: m2 | C46: Pagar Sementara dari seng Gelombang tinggi 2 m
A48: Jenis Pekerjaan | D48: Harga satuan | E48: Upah | F48: Bahan | G48: Jumlah
A49: 1.25 | B49: btng | C49: Dolken Kayu Diameter 8-10/400cm | D49: 12000 | E49: 0 | F49: =A49*D49 -> 15000 | G49: =E49+F49 -> 15000
A50: 2.5 | B50: Kg | C50: Semen Portland | D50: 1200 | E50: 0 | F50: =A50*D50 -> 3000 | G50: =E50+F50 -> 3000
A51: 0.005 | B51: m3 | C51: Pasir Beton | D51: 283333.33 | E51: 0 | F51: =A51*D51 -> 1416.6667 | G51: =E51+F51 -> 1416.6667
A52: 0.009 | B52: m3 | C52: Koral Beton | D52: 283333.33 | E52: 0 | F52: =A52*D52 -> 2550 | G52: =E52+F52 -> 2550
A53: 1.2 | B53: Lbr | C53: Seng Gelombang Bwg 32 | D53: =0*120000 -> 0 | E53: 0 | F53: =A53*D53 -> 0 | G53: =E53+F53 -> 0
A54: 0.06 | B54: Kg | C54: Paku Biasa 2"-5" | D54: 40000 | E54: 0 | F54: =A54*D54 -> 2400 | G54: =E54+F54 -> 2400
A55: 0.072 | B55: m3 | C55: Kayu 5/7 | D55: =300000 -> 300000 | E55: 0 | F55: =A55*D55 -> 21600 | G55: =E55+F55 -> 21600
A56: 0.45 | B56: Liter | C56: Meni Besi | D56: 5000 | E56: 0 | F56: =A56*D56 -> 2250 | G56: =E56+F56 -> 2250
A57: 0.1 | B57: OH | C57: Pekerja | D57: 130000 | E57: =A57*D57 -> 13000 | F57: 0 | G57: =E57+F57 -> 13000
A58: 0.02 | B58: OH | C58: Kepala Tukang | D58: 250000 | E58: =A58*D58 -> 5000 | F58: 0 | G58: =E58+F58 -> 5000
...

Sheet Lantai
B1: PEKERJAAN PENUTUP LANTAI
B5: NO. | C5: NAMA RUANG | D5: SATUAN | E5: SPESIFIKASI MATERIAL | F5: VOLUME
C7: LANTAI BASEMENT
B8: 1 | C8: Foyer | D8: m2 | F8: 10.33
B9: =B8+1 -> 2 | C9: Storage | D9: m2 | F9: 4.32
B10: =B9+1 -> 3 | C10: Kitchen | D10: m2 | F10: 19.44
B11: =B10+1 -> 4 | C11: Service Area | D11: m2 | F11: 5.73
B12: =B11+1 -> 5 | C12: Toilet | D12: m2 | F12: 3.58
B13: =B12+1 -> 6 | C13: Bedroom ART 1 | D13: m2 | F13: 10.68
B14: =B13+1 -> 7 | C14: Bedroom ART 2 | D14: m2 | F14: 10.68
B15: =B14+1 -> 8 | C15: Pool Maintance | D15: m2 | F15: 10.72
B16: =B15+1 -> 9 | C16: Storage Room | D16: m2 | F16: 3.43
B17: =B16+1 -> 10 | C17: Prayer Room | D17: m2 | F17: 6.53
B18: =B17+1 -> 11 | C18: Sidewalk | D18: m2 | E18: valentino gress sedona black 60x60 | F18: 34.87
B19: =B18+1 -> 12 | C19: Genset area, Parking and circulation | D19: m2 | F19: 250.22
C20: TOTAL | F20: =SUM(F8:F19) -> 370.53
C22: LANTAI DASAR
B23: 1 | C23: Foyer | D23: m2 | F23: 28.22
B24: =B23+1 -> 2 | C24: Shoe Rack and Storage | D24: m2 | F24: 4.16
B25: =B24+1 -> 3 | C25: Bathroom | D25: m2 | F25: 3.58
B26: =B25+1 -> 4 | C26: Living Room | D26: m2 | F26: 65.59
B27: =B26+1 -> 5 | C27: Outdoor Lounge | D27: m2 | F27: 27.36
B28: =B27+1 -> 6 | C28: Dining Area | D28: m2 | F28: 38.52
B29: =B28+1 -> 7 | C29: Kitchen | D29: m2 | F29: 15.09
B30: =B29+1 -> 8 | C30: Service Stair | D30: m2 | F30: 8.16
B31: =B30+1 -> 9 | C31: Stair Area | D31: m2 | F31: 10.41
B32: =B31+1 -> 10 | C32: Kids Playing Area | D32: m2 | F32: 39.55
B33: =B32+1 -> 11 | C33: Terrace | D33: m2 | F33: 27.12
B34: =B33+1 -> 12 | C34: Outdoor Lounge | D34: m2 | F34: 12.25
B35: TOTAL | F35: =SUM(F23:F34) -> 280.01
C37: LANTAI 1
B38: 1 | C38: Corridor | D38: m2 | F38: 39.3
B39: =B38+1 -> 2 | C39: Kids Bedroom 1 | D39: m2 | F39: 19.54
B40: =B39+1 -> 3 | C40: Kids Bedroom 2 | D40: m2 | F40: 19.62
B41: =B40+1 -> 4 | C41: Kids WIC 1 | D41: m2 | F41: 4.28
B42: =B41+1 -> 5 | C42: Kids WIC 2 | D42: m2 | F42: 4.57
B43: =B42+1 -> 6 | C43: Kids Bathroom 1 | D43: m2 | F43: 6.81
B44: =B43+1 -> 7 | C44: Kids Bathroom 2 | D44: m2 | F44: 7.08
B45: =B44+1 -> 8 | C45: Guest Bedroom | D45: m2 | F45: 15.99
B46: =B45+1 -> 9 | C46: Guest Bathroom | D46: m2 | F46: 5.88
...

Sheet MEP
B1: PEKERJAAN MEP
B5: NO. | C5: MATERIAL | D5: SATUAN | E5: SPESIFIKASI MATERIAL | F5: VOLUME
C7: LANTAI BASEMENT
B8: A | C8: Instalasi
B9: 1 | C9: Kabel NYM 3x2,5 mm 100m/roll | D9: roll | F9: 6
B10: =B9+1 -> 2 | C10: Kabel NYM 2x1,5 mm 100m/roll | D10: roll | F10: 3
B11: =B10+1 -> 3 | C11: Kabell NYY 3x2.5 mm | D11: m1 | F11: 20
B12: =B11+1 -> 4 | C12: Pipa conduit | D12: btg | F12: 190
B13: =B12+1 -> 5 | C13: Klem pipa conduit | D13: pcs | F13: 95
B14: =B13+1 -> 6 | C14: Sok pipa conduit | D14: pcs | F14: 95
B15: =B14+1 -> 7 | C15: Terminal listrik/krustin 10 mm | D15: pack | F15: 2
B16: =B15+1 -> 8 | C16: Tdus cabang 3 | D16: pcs | F16: 115
B17: =B16+1 -> 9 | C17: Tdus cabang 4 | D17: pcs | F17: 40
B18: =B17+1 -> 10 | C18: Solasi listrik | D18: pcs | F18: 20
B19: =B18+1 -> 11 | C19: Box panel 60x50x20 cm | D19: unit | F19: 1
B20: =B19+1 -> 12 | C20: MCB 6A 1 phase | D20: unit | F20: 6
B21: =B20+1 -> 13 | C21: MCB 10A 1 phase | D21: unit | F21: 5
... B30: =B29+1 -> 22 | C30: Bracket MCB | D30: btg | F30: 1
B31: B | C31: Armature
B32: 1 | C32: Lampu downlight | D32: unit | F32: 32
B33: 2 | C33: Lampu TL 18W/6500K + housing | D33: set | F33: 29
B34: 3 | C34: Stop kontak 2 gang | D34: unit | F34: 20
B35: 4 | C35: Saklar seri | D35: unit | F35: 10
B36: =B35+1 -> 5 | C36: Stop kontak genset/ surface mounting | D36: unit | F36: 1
B37: =B36+1 -> 6 | C37: Gas detector | D37: unit | F37: 1
B38: =B37+1 -> 7 | C38: Heat detector | D38: unit | F38: 1
B39: =B38+1 -> 8 | C39: Smoke detector | D39: unit | F39: 10
B40: C | C40: Plumbing
B41: 1 | C41: Pipa PVC AW dia. 1 inch dari PDAM ke roof tank | D41: btg | F41: 10
B42: =B41+1 -> 2 | C42: Pipa PVC AW dia. 3/4 inch dari roof tank ke Lt. Basement incl mainline | D42: btg | F42: 18
B43: =B42+1 -> 3 | C43: Pipa PVC AW dia. 1/2 inch | D43: btg | F43: 4
B44: =B43+1 -> 4 | C44: Pipa PVC D dia. 3 inch | D44: btg | F44: 30
B45: =B44+1 -> 5 | C45: Knee pipa PVC 3 inch | D45: pcs | F45: 30
B46: =B45+1 -> 6 | C46: Tee pipa PVC 3 inch | D46: pcs | F46: 10
B47: =B46+1 -> 7 | C47: Knee pipa PVC 1 inch | D47: pcs | F47: 4
B48: =B47+1 -> 8 | C48: Knee pipa PVC 3/4 inch | D48: pcs | F48: 9
B49: =B48+1 -> 9 | C49: Tee pipa PVC 3/4 inch | D49: pcs | F49: 3
B50: =B49+1 -> 10 | C50: Reducer pipa 3/4 inch ke 1/2 inch | D50: pcs | F50: 5
B51: =B50+1 -> 11 | C51: Gate valve pipa 1 inch | D51: pcs | F51: 2
B52: =B51+1 -> 12 | C52: Gate valve pipa 3/4 inch | D52: pcs | F52: 5
...

Sheet ANALISA_BONGKAR DAN CLEANIN (2)
A13: Analisa Harga Satuan | G13: Lampiran-04
A14: Proyek : Pembangunan ASRAMA YAYASAN HASANAH KEBAJIKAN
A15: Lokasi : Bukit Cirendeu
A16: 1 | B16: m2 | C16: Membersihkan lapangan dan perataan
A18: Jenis Pekerjaan | D18: Harga satuan | E18: Upah | F18: Bahan | G18: Jumlah
A19: 0.1 | B19: org | C19: Pekerja | D19: 130000 | E19: =A19*D19 -> 13000 | F19: 0 | G19: =E19+F19 -> 13000
A20: 0.05 | B20: org | C20: Mandor | D20: 265000 | E20: =A20*D20 -> 13250 | F20: 0 | G20: =E20+F20 -> 13250
C21: JUMLAH ( BELUM PPN ) | E21: =SUM(E19:E20) -> 26250 | F21: 0 | G21: =SUM(G19:G20) -> 26250
C22: JASA 10 % | D22: 0.1 | E22: =E21*D22 -> 2625 | F22: =F21*D22 -> 0 | G22: =D22*G21 -> 2625
C23: JUMLAH | E23: =SUM(E21:E22) -> 28875 | F23: 0 | G23: =SUM(G21:G22) -> 28875
A25: 1 | B25: m3 | C25: Bongkaran Beton Bertulang
A27: Jenis Pekerjaan | D27: Harga satuan | E27: Upah | F27: Bahan | G27: Jumlah
A28: 6.667 | B28: org | C28: Pekerja | D28: 130000 | E28: =A28*D28 -> 866710 | F28: 0 | G28: =E28+F28 -> 866710
A29: 0.333 | B29: org | C29: Mandor | D29: 265000 | E29: =A29*D29 -> 88245 | F29: 0 | G29: =E29+F29 -> 88245
C30: JUMLAH ( BELUM PPN ) | E30: =SUM(E28:E29) -> 954955 | F30: 0 | G30: =SUM(G28:G29) -> 954955
C31: JASA 10 % | D31: 0.1 | E31: =E30*D31 -> 95495.5 | F31: =F30*D31 -> 0 | G31: =D31*G30 -> 95495.5
C32: JUMLAH | E32: =SUM(E30:E31) -> 1050450.5 | F32: 0 | G32: =SUM(G30:G31) -> 1050450.5 | R32: 19
R33: 12
A34: 1 | B34: m3 | C34: Bongkaran dinding tembok Bata Merah | R34: =R33*R32 -> 228
A36: Jenis Pekerjaan | D36: Harga satuan | E36: Upah | F36: Bahan | G36: Jumlah
A37: 6.667 | B37: org | C37: Pekerja | D37: 130000 | E37: =A37*D37 -> 866710 | F37: 0 | G37: =E37+F37 -> 866710
A38: 0.333 | B38: org | C38: Mandor | D38: 265000 | E38: =A38*D38 -> 88245 | F38: 0 | G38: =E38+F38 -> 88245
C39: JUMLAH ( BELUM PPN ) | E39: =SUM(E37:E38) -> 954955 | F39: 0 | G39: =SUM(G37:G38) -> 954955
C40: JASA 10 % | D40: 0.1 | E40: =E39*D40 -> 95495.5 | F40: =F39*D40 -> 0 | G40: =D40*G39 -> 95495.5
C41: JUMLAH | E41: =SUM(E39:E40) -> 1050450.5 | F41: 0 | G41: =SUM(G39:G40) -> 1050450.5
A43: 1 | B43: m2 | C43: Pagar Sementara dari seng Gelombang tinggi 2 m
A45: Jenis Pekerjaan | D45: Harga satuan | E45: Upah | F45: Bahan | G45: Jumlah
A46: 1.25 | B46: btng | C46: Dolken Kayu Diameter 8-10/400cm | D46: 40000 | E46: 0 | F46: =A46*D46 -> 50000 | G46: =E46+F46 -> 50000
A47: 2.5 | B47: Kg | C47: Semen Portland | D47: 1200 | E47: 0 | F47: =A47*D47 -> 3000 | G47: =E47+F47 -> 3000
A48: 0.005 | B48: m3 | C48: Pasir Beton | D48: 283333.33 | E48: 0 | F48: =A48*D48 -> 1416.6667 | G48: =E48+F48 -> 1416.6667
A49: 0.009 | B49: m3 | C49: Koral Beton | D49: 283333.33 | E49: 0 | F49: =A49*D49 -> 2550 | G49: =E49+F49 -> 2550
A50: 1.2 | B50: Lbr | C50: Seng Gelombang Bwg 32 | D50: 120000 | E50: 0 | F50: =A50*D50 -> 144000 | G50: =E50+F50 -> 144000
A51: 0.06 | B51: Kg | C51: Paku Biasa 2"-5" | D51: 40000 | E51: 0 | F51: =A51*D51 -> 2400 | G51: =E51+F51 -> 2400
A52: 0.072 | B52: m3 | C52: Kayu 5/7 | D52: 1500000 | E52: 0 | F52: =A52*D52 -> 108000 | G52: =E52+F52 -> 108000
A53: 0.45 | B53: Liter | C53: Meni Besi | D53: 65000 | E53: 0 | F53: =A53*D53 -> 29250 | G53: =E53+F53 -> 29250
A54: 0.2 | B54: OH | C54: Pekerja | D54: 130000 | E54: =A54*D54 -> 26000 | F54: 0 | G54: =E54+F54 -> 26000
A55: 0.02 | B55: OH | C55: Kepala Tukang | D55: 250000 | E55: =A55*D55 -> 5000 | F55: 0 | G55: =E55+F55 -> 5000
A56: 0.02 | B56: OH | C56: Mandor | D56: 265000 | E56: =A56*D56 -> 5300 | F56: 0 | G56: =E56+F56 -> 5300
C57: JUMLAH ( BELUM PPN ) | E57: =SUM(E46:E56) -> 36300 | F57: =SUM(F46:F56) -> 340616.67 | G57: =SUM(G46:G56) -> 376916.67
C58: JASA 10 % | D58: 0.1 | E58: =E57*0.1 -> 3630 | F58: =F57*0.1 -> 34061.667 | G58: =D58*G57 -> 37691.667
...

Sheet Sheet2
B5: Vol | D5: Dimensi Ruangan | F5: Luas | G5: Keliling
B6: No | C6: Item | D6: P | E6: L | F6: M2 | G6: M'
B7: A | C7: Baseman
B8: 1 | C8: Plafond Expose, ex skimcoat finish | F8: ='6. Pekerjaan Plafond'!G32 -> 267.83
B9: 2 | C9: Pekerjaan Plafond Gypsum Area Koridor dan Lobby Lift | F9: 134.35
B10: B | C10: Lantai Dasar
B11: 1 | C11: VOYER ENTRANCE | D11: 4.43 | E11: 6.03 | F11: =D11*E11 -> 26.7129 | G11: =(D11*2)+(E11*2) -> 20.92
B12: =B11+1 -> 2 | C12: LIVING ROOM | D12: 11.2 | E12: 6 | F12: =D12*E12 -> 67.2 | G12: =(D12*2)+(E12*2) -> 34.4
B13: =B12+1 -> 3 | C13: TERRACE | D13: 6 | E13: 4.8 | F13: =D13*E13 -> 28.8 | G13: =(D13*2)+(E13*2) -> 21.6
B14: =B13+1 -> 4 | C14: TOILET | D14: =2.66-1.57 -> 1.09 | E14: 1.225 | F14: =D14*E14 -> 1.33525 | G14: =(D14*2)+(E14*2) -> 4.63
B15: =B14+1 -> 5 | C15: TOILET (wastafel) | D15: 1.255 | E15: 2.666 | F15: =D15*E15 -> 3.34583 | G15: =(D15*2)+(E15*2) -> 7.842
B16: =B15+1 -> 6 | C16: DINING ROOM | D16: 4.8 | E16: 8 | F16: =D16*E16 -> 38.4 | G16: =(D16*2)+(E16*2) -> 25.6
B17: =B16+1 -> 7 | C17: PANTRY | D17: 6.23 | E17: 2.442 | F17: =D17*E17 -> 15.21366 | G17: =(D17*2)+(E17*2) -> 17.344
B18: =B17+1 -> 8 | C18: STAIR AREA LV 1 | D18: 6.4 | E18: 8 | F18: =D18*E18 -> 51.2 | G18: =(D18*2)+(E18*2) -> 28.8
B19: =B18+1 -> 9 | C19: LOUNGE OUTDOOR LV 1 | D19: 8.2 | E19: 5.6 | F19: =D19*E19 -> 45.92 | G19: =(D19*2)+(E19*2) -> 27.6
B20: C | C20: Lantai 1
B21: 1 | C21: PLAN BEDROOM 1 LV.2 | D21: 5.5 | E21: 8 | F21: =D21*E21 -> 44 | G21: =(D21*2)+(E21*2) -> 27
B22: =B21+1 -> 2 | C22: PLAN BEDROOM 2 LV.2 | D22: 5.5 | E22: 8 | F22: =D22*E22 -> 44 | G22: =(D22*2)+(E22*2) -> 27
B23: =B22+1 -> 3 | C23: Guest Bedroom LV2 | F23: =4.3+1.6+0.9 -> 6.8
B24: =B23+1 -> 4 | C24: MASTER BEDROOM LV.2 | F24: 14
B25: =B24+1 -> 5 | C25: Corridor LV2 | F25: 38.8
B26: D | C26: Lantai 2
B27: 1 | C27: Gym | F27: 42.8
B28: =B27+1 -> 2 | C28: Billiard | F28: 24.14
B29: =B28+1 -> 3 | C29: Home Office & Fowder room | F29: =62.67-42.8 -> 19.87
B30: =B29+1 -> 4 | C30: Stair Area | F30: 11.62

Sheet ANALISA_Plambing
A15: 1 | B15: bh | C15: Memasang kloset duduk/monoblock
A17: Jenis Pekerjaan | D17: Harga satuan | E17: Upah | F17: Bahan | G17: Jumlah
A18: 1 | B18: bh | C18: Kloset duduk / monoblock | D18: 2000000 | E18: 0 | F18: =A18*D18 -> 2000000 | G18: =E18+F18 -> 2000000
A19: 0.06 | B19: x | C19: Harga kloset (Perlengkapan) | D19: =D18 -> 2000000 | E19: 0 | F19: =A19*D19 -> 120000 | G19: =E19+F19 -> 120000
A20: 3.3 | B20: org | C20: Pekerja | D20: =D310 -> 130000 | E20: =A20*D20 -> 429000 | F20: 0 | G20: =E20+F20 -> 429000
A21: 1.1 | B21: org | C21: Tukang batu | D21: =D311 -> 180000 | E21: =A21*D21 -> 198000 | F21: 0 | G21: =E21+F21 -> 198000
A22: 0.16 | B22: org | C22: Mandor | D22: =D312 -> 260000 | E22: =A22*D22 -> 41600 | F22: 0 | G22: =E22+F22 -> 41600
C23: JUMLAH ( BELUM PPN ) | E23: =SUM(E18:E22) -> 668600 | F23: =SUM(F18:F22) -> 2120000 | G23: =SUM(G18:G22) -> 2788600
C24: JASA 35 % | D24: 0.35 | E24: =E23*D24 -> 234010 | F24: =F23*D24 -> 742000 | G24: =G23*D24 -> 976010
C25: JUMLAH | E25: =SUM(E23:E24) -> 902610 | F25: =SUM(F23:F24) -> 2862000 | G25: =SUM(G23:G24) -> 3764610
A27: 1 | B27: bh | C27: Memasang bak kontrol pas. bata (60 x 60) cm, tingg 65 cm
A29: Jenis Pekerjaan | D29: Harga satuan | E29: Upah | F29: Bahan | G29: Jumlah
A30: 222 | B30: bh | C30: Batu bata | D30: 600 | E30: 0 | F30: =A30*D30 -> 133200 | G30: =E30+F30 -> 133200
A31: 114 | B31: kg | C31: PC | D31: 1260 | E31: 0 | F31: =A31*D31 -> 143640 | G31: =E31+F31 -> 143640
A32: 0.184 | B32: m3 | C32: Pasir pasang | D32: 250000 | E32: 0 | F32: =A32*D32 -> 46000 | G32: =E32+F32 -> 46000
A33: 0.033 | B33: m3 | C33: Batu kerikil | D33: 78650 | E33: 0 | F33: =A33*D33 -> 2595.45 | G33: =E33+F33 -> 2595.45
A34: 4.85 | B34: kg | C34: Besi beton | D34: 8000 | E34: 0 | F34: =A34*D34 -> 38800 | G34: =E34+F34 -> 38800
A35: 0.12 | B35: m3 | C35: Pasir beton | D35: 250000 | E35: 0 | F35: =A35*D35 -> 30000 | G35: =E35+F35 -> 30000
A36: 2.16 | B36: org | C36: Pekerja | D36: =D310 -> 130000 | E36: =A36*D36 -> 280800 | F36: 0 | G36: =E36+F36 -> 280800
A37: 0.72 | B37: org | C37: Tukang batu | D37: =D311 -> 180000 | E37: =A37*D37 -> 129600 | F37: 0 | G37: =E37+F37 -> 129600
A38: 0.1 | B38: org | C38: Mandor | D38: =D312 -> 260000 | E38: =A38*D38 -> 26000 | F38: 0 | G38: =E38+F38 -> 26000
C39: JUMLAH ( BELUM PPN ) | E39: =SUM(E30:E38) -> 436400 | F39: =SUM(F30:F38) -> 394235.45 | G39: =SUM(G30:G38) -> 830635.45
C40: JASA 35 % | D40: 0.35 | E40: =E39*D40 -> 152740 | F40: =F39*D40 -> 137982.41 | G40: =G39*D40 -> 290722.41
C41: JUMLAH | E41: =SUM(E39:E40) -> 589140 | F41: =SUM(F39:F40) -> 532217.86 | G41: =SUM(G39:G40) -> 1121357.9
A43: 1 | B43: Btg | C43: Memasang pipa PVC tipe AW diameter 1/2"
A45: Jenis Pekerjaan | D45: Harga satuan | E45: Upah | F45: Bahan | G45: Jumlah
A46: 1.2 | B46: m1 | C46: pipa PVC tipe AW diameter 1/2" | D46: =26000 -> 26000 | E46: 0 | F46: =A46*D46 -> 31200 | G46: =E46+F46 -> 31200
A47: 0.35 | B47: x | C47: Harga pipa (Perlengkapan) | D47: =D46 -> 26000 | E47: 0 | F47: =A47*D47 -> 9100 | G47: =E47+F47 -> 9100
A48: =1.5*0.036 -> 0.054 | B48: org | C48: Pekerja | D48: =D310 -> 130000 | E48: =A48*D48 -> 7020 | F48: 0 | G48: =E48+F48 -> 7020
A49: =2*0.06 -> 0.12 | B49: org | C49: Tukang batu | D49: =D311 -> 180000 | E49: =A49*D49 -> 21600 | F49: 0 | G49: =E49+F49 -> 21600
A50: =2*0.0018 -> 0.0036 | B50: org | C50: Mandor | D50: =D312 -> 260000 | E50: =A50*D50 -> 936 | F50: 0 | G50: =E50+F50 -> 936
C51: JUMLAH ( BELUM PPN ) | E51: =SUM(E46:E50) -> 29556 | F51: =SUM(F46:F50) -> 40300 | G51: =SUM(G46:G50) -> 69856
C52: JASA 35 % | D52: 0.35 | E52: =E51*D52 -> 10344.6 | F52: =F51*D52 -> 14105 | G52: =G51*D52 -> 24449.6
C53: JUMLAH | E53: =SUM(E51:E52) -> 39900.6 | F53: =SUM(F51:F52) -> 54405 | G53: =SUM(G51:G52) -> 94305.6
A55: 1 | B55: Btg | C55: Memasang pipa PVC tipe AW diameter 3/4"
A57: Jenis Pekerjaan | D57: Harga satuan | E57: Upah | F57: Bahan | G57: Jumlah
A58: 1 | B58: btg | C58: pipa PVC tipe AW diameter 3/4" | D58: =39300 -> 39300 | E58: 0 | F58: =A58*D58 -> 39300 | G58: =E58+F58 -> 39300
A59: 0.35 | B59: x | C59: Harga pipa (Perlengkapan) | D59: =D58 -> 39300 | E59: 0 | F59: =A59*D59 -> 13755 | G59: =E59+F59 -> 13755
A60: =3*0.036 -> 0.108 | B60: org | C60: Pekerja | D60: =D310 -> 130000 | E60: =A60*D60 -> 14040 | F60: 0 | G60: =E60+F60 -> 14040
A61: =3*0.06 -> 0.18 | B61: org | C61: Tukang batu | D61: =D311 -> 180000 | E61: =A61*D61 -> 32400 | F61: 0 | G61: =E61+F61 -> 32400
...

Sheet ANALISA_LANTAI
A1: 1 | B1: m3 | C1: Cipping Beton Bertulang & Perapihan
A3: Jenis Pekerjaan | D3: Harga satuan | E3: Upah | F3: Bahan | G3: Jumlah
A4: 6.667 | B4: org | C4: Pekerja | D4: 130000 | E4: =A4*D4 -> 866710 | F4: 0 | G4: =E4+F4 -> 866710
A5: 0.333 | B5: org | C5: Mandor | D5: 200000 | E5: =A5*D5 -> 66600 | F5: 0 | G5: =E5+F5 -> 66600
C6: JUMLAH ( BELUM PPN ) | E6: =SUM(E4:E5) -> 933310 | F6: 0 | G6: =SUM(G4:G5) -> 933310 | I6: =0.02*10*5 -> 1
C7: Keuntungan 15 % | D7: 0.15 | E7: =E6*D7 -> 139996.5 | F7: =F6*D7 -> 0 | G7: =D7*G6 -> 139996.5
C8: JUMLAH | E8: =SUM(E6:E7) -> 1073306.5 | F8: 0 | G8: =SUM(G6:G7) -> 1073306.5 | R8: 19
C9: Harga untuk permeter | E9: =E8/50 -> 21466.13 | F9: 0 | G9: =G8/50 -> 21466.13 | R9: 19
A12: 1 | B12: m2 | C12: Pasang Granite 60x60
A14: Jenis Pekerjaan | D14: Harga satuan | E14: Upah | F14: Bahan | G14: Jumlah
A15: 1 | B15: m2 | C15: Granite uk. 60x60 | D15: 300000 | E15: 0 | F15: =A15*D15 -> 300000 | G15: =E15+F15 -> 300000
A16: 4.08 | B16: kg | C16: PC | D16: 1700 | E16: 0 | F16: =A16*D16 -> 6936 | G16: =E16+F16 -> 6936
A17: 0.009 | B17: m3 | C17: Pasir pasang | D17: 345000 | E17: 0 | F17: =A17*D17 -> 3105 | G17: =E17+F17 -> 3105
A18: 0.6 | B18: kg | C18: Semen putih | D18: =55000/40 -> 1375 | E18: 0 | F18: =A18*D18 -> 825 | G18: =E18+F18 -> 825
A19: 0.25 | B19: org | C19: Pekerja | D19: 130000 | E19: =A19*D19 -> 32500 | F19: 0 | G19: =E19+F19 -> 32500
A20: 0.5 | B20: org | C20: Tukang batu | D20: 180000 | E20: =A20*D20 -> 90000 | F20: 0 | G20: =E20+F20 -> 90000
A21: 0.0125 | B21: org | C21: Mandor | D21: 250000 | E21: =A21*D21 -> 3125 | F21: 0 | G21: =E21+F21 -> 3125
C22: JUMLAH ( BELUM PPN ) | E22: =SUM(E15:E21) -> 125625 | F22: =SUM(F15:F21) -> 310866 | G22: =SUM(G15:G21) -> 436491
C23: Keuntungan 15 % | D23: 0.15 | E23: =E22*D23 -> 18843.75 | F23: =F22*D23 -> 46629.9 | G23: =D23*G22 -> 65473.65
C24: JUMLAH | E24: =SUM(E22:E23) -> 144468.75 | F24: =SUM(F22:F23) -> 357495.9 | G24: =SUM(G22:G23) -> 501964.65
A26: 1 | B26: m2 | C26: Acian Lantai (Finishing Skeamcoat)
A28: Jenis Pekerjaan | D28: Harga satuan | E28: Upah | F28: Bahan | G28: Jumlah
A29: 3.5 | B29: kg | C29: PC | D29: =113000/50 -> 2260 | E29: 0 | F29: =A29*D29 -> 7910 | G29: =E29+F29 -> 7910
A30: 1 | B30: Ls | C30: Alat Bantu | D30: 800 | E30: 0 | F30: =A30*D30 -> 800 | G30: =E30+F30 -> 800
A31: 0.07 | B31: org | C31: Pekerja | D31: 130000 | E31: =A31*D31 -> 9100 | F31: 0 | G31: =E31+F31 -> 9100
A32: 0.033 | B32: org | C32: Tukang batu | D32: 200000 | E32: =A32*D32 -> 6600 | F32: 0 | G32: =E32+F32 -> 6600
A33: 0.0035 | B33: org | C33: Mandor | D33: 250000 | E33: =A33*D33 -> 875 | F33: 0 | G33: =E33+F33 -> 875
C34: JUMLAH ( BELUM PPN ) | E34: =SUM(E29:E33) -> 16575 | F34: =SUM(F29:F33) -> 8710 | G34: =SUM(G29:G33) -> 25285
C35: Keuntungan 15 % | D35: 0.15 | E35: =E34*D35 -> 2486.25 | F35: =F34*D35 -> 1306.5 | G35: =D35*G34 -> 3792.75
C36: JUMLAH | E36: =SUM(E34:E35) -> 19061.25 | F36: =SUM(F34:F35) -> 10016.5 | G36: =SUM(G34:G35) -> 29077.75

Sheet ANALISA_KOLAM RENANG
A1: 1 | B1: m3 | C1: Cipping Beton Bertulang & Perapihan
A3: Jenis Pekerjaan | D3: Harga satuan | E3: Upah | F3: Bahan | G3: Jumlah
A4: 6.667 | B4: org | C4: Pekerja | D4: 130000 | E4: =A4*D4 -> 866710 | F4: 0 | G4: =E4+F4 -> 866710
A5: 0.333 | B5: org | C5: Mandor | D5: 200000 | E5: =A5*D5 -> 66600 | F5: 0 | G5: =E5+F5 -> 66600
C6: JUMLAH ( BELUM PPN ) | E6: =SUM(E4:E5) -> 933310 | F6: 0 | G6: =SUM(G4:G5) -> 933310 | I6: =0.02*10*5 -> 1
C7: Keuntungan 10 % | D7: 0.15 | E7: =E6*D7 -> 139996.5 | F7: =F6*D7 -> 0 | G7: =D7*G6 -> 139996.5
C8: JUMLAH | E8: =SUM(E6:E7) -> 1073306.5 | F8: 0 | G8: =SUM(G6:G7) -> 1073306.5 | R8: 19
C9: Harga untuk permeter | E9: =E8/50 -> 21466.13 | F9: 0 | G9: =G8/50 -> 21466.13 | R9: 19
A12: 1 | B12: m2 | C12: Pasang Batualam
A14: Jenis Pekerjaan | D14: Harga satuan | E14: Upah | F14: Bahan | G14: Jumlah
A15: 1 | B15: m2 | C15: Granite uk. 60x60 | D15: 350000 | E15: 0 | F15: =A15*D15 -> 350000 | G15: =E15+F15 -> 350000
A16: 4.08 | B16: kg | C16: PC | D16: 1700 | E16: 0 | F16: =A16*D16 -> 6936 | G16: =E16+F16 -> 6936
A17: 0.009 | B17: m3 | C17: Pasir pasang | D17: 345000 | E17: 0 | F17: =A17*D17 -> 3105 | G17: =E17+F17 -> 3105
A18: 0.6 | B18: kg | C18: Semen putih | D18: =55000/40 -> 1375 | E18: 0 | F18: =A18*D18 -> 825 | G18: =E18+F18 -> 825
A19: 0.25 | B19: org | C19: Pekerja | D19: 130000 | E19: =A19*D19 -> 32500 | F19: 0 | G19: =E19+F19 -> 32500
A20: 0.5 | B20: org | C20: Tukang batu | D20: 180000 | E20: =A20*D20 -> 90000 | F20: 0 | G20: =E20+F20 -> 90000
A21: 0.0125 | B21: org | C21: Mandor | D21: 250000 | E21: =A21*D21 -> 3125 | F21: 0 | G21: =E21+F21 -> 3125
C22: JUMLAH ( BELUM PPN ) | E22: =SUM(E15:E21) -> 125625 | F22: =SUM(F15:F21) -> 360866 | G22: =SUM(G15:G21) -> 486491
C23: Keuntungan 10 % | D23: 0.15 | E23: =E22*D23 -> 18843.75 | F23: =F22*D23 -> 54129.9 | G23: =D23*G22 -> 72973.65
C24: JUMLAH | E24: =SUM(E22:E23) -> 144468.75 | F24: =SUM(F22:F23) -> 414995.9 | G24: =SUM(G22:G23) -> 559464.65
A26: 1 | B26: m2 | C26: Acian Lantai (Finishing Skeamcoat)
A28: Jenis Pekerjaan | D28: Harga satuan | E28: Upah | F28: Bahan | G28: Jumlah
A29: 3.5 | B29: kg | C29: PC | D29: =113000/50 -> 2260 | E29: 0 | F29: =A29*D29 -> 7910 | G29: =E29+F29 -> 7910
A30: 1 | B30: Ls | C30: Alat Bantu | D30: 800 | E30: 0 | F30: =A30*D30 -> 800 | G30: =E30+F30 -> 800
A31: 0.07 | B31: org | C31: Pekerja | D31: 130000 | E31: =A31*D31 -> 9100 | F31: 0 | G31: =E31+F31 -> 9100
A32: 0.033 | B32: org | C32: Tukang batu | D32: 200000 | E32: =A32*D32 -> 6600 | F32: 0 | G32: =E32+F32 -> 6600
A33: 0.0035 | B33: org | C33: Mandor | D33: 250000 | E33: =A33*D33 -> 875 | F33: 0 | G33: =E33+F33 -> 875
C34: JUMLAH ( BELUM PPN ) | E34: =SUM(E29:E33) -> 16575 | F34: =SUM(F29:F33) -> 8710 | G34: =SUM(G29:G33) -> 25285
C35: JASA 10 % | D35: 0.15 | E35: =E34*D35 -> 2486.25 | F35: =F34*D35 -> 1306.5 | G35: =D35*G34 -> 3792.75
C36: JUMLAH | E36: =SUM(E34:E35) -> 19061.25 | F36: =SUM(F34:F35) -> 10016.5 | G36: =SUM(G34:G35) -> 29077.75

Sheet ANALISA_DINDING
A14: 1 | B14: m2 | C14: Pasangan Dinding Bata Merah
A16: Jenis Pekerjaan | D16: Harga satuan | E16: Upah | F16: Bahan | G16: Jumlah
A17: 140 | B17: m2 | C17: Bata Merah | D17: 1100 | E17: 0 | F17: =A17*D17 -> 154000 | G17: =E17+F17 -> 154000
A18: 32.95 | B18: kg | C18: Semen Portan | D18: 1720 | E18: 0 | F18: =A18*D18 -> 56674 | G18: =E18+F18 -> 56674
A19: 0.091 | B19: m3 | C19: Pasir pasang | D19: 267000 | E19: 0 | F19: =A19*D19 -> 24297 | G19: =E19+F19 -> 24297
A20: 0.6 | B20: org | C20: Pekerja | D20: 130000 | E20: =A20*D20 -> 78000 | F20: 0 | G20: =E20+F20 -> 78000
A21: 0.2 | B21: org | C21: Tukang batu | D21: 200000 | E21: =A21*D21 -> 40000 | F21: 0 | G21: =E21+F21 -> 40000
A22: 0.02 | B22: org | C22: Kepala Tukang | D22: 250000 | E22: =A22*D22 -> 5000 | F22: 0 | G22: =E22+F22 -> 5000
A23: 0.03 | B23: org | C23: Mandor | D23: 265000 | E23: =A23*D23 -> 7950 | F23: 0 | G23: =E23+F23 -> 7950
C24: JUMLAH ( BELUM PPN ) | E24: =SUM(E17:E23) -> 130950 | F24: =SUM(F17:F23) -> 234971 | G24: =SUM(G17:G23) -> 365921
C25: JASA 10 % | D25: 1.15 | E25: =E24*0.1 -> 13095 | F25: =F24*0.1 -> 23497.1 | G25: =D25*G24 -> 420809.15
C26: JUMLAH | E26: =SUM(E24:E25) -> 144045 | F26: =SUM(F24:F25) -> 258468.1 | G26: =SUM(G24:G25) -> 786730.15
A29: 1 | B29: m2 | C29: Pasangan bata Hebel HB/CB 20, Campuran Spesi 1PC:3PP
A31: Jenis Pekerjaan | D31: Harga satuan | E31: Upah | F31: Bahan | G31: Jumlah
A32: 9 | B32: bh | C32: Bata Hebbel Ukuran | D32: =700000/85 -> 8235.2941 | E32: 0 | F32: =A32*D32 -> 74117.647 | G32: =E32+F32 -> 74117.647
A33: =50/9 -> 5.5555556 | B33: kg | C33: Mu Perekat | D33: =114000/50 -> 2280 | E33: 0 | F33: =A33*D33 -> 12666.667 | G33: =E33+F33 -> 12666.667
A34: 1 | B34: Ls | C34: Alat Bantu | D34: 2000 | E34: 0 | F34: =A34*D34 -> 2000 | G34: =E34+F34 -> 2000
A35: 0.28 | B35: kg | C35: Besi Angkur D8 mm | D35: 8122.3629 | E35: 0 | F35: =A35*D35 -> 2274.2616 | G35: =E35+F35 -> 2274.2616
A36: 0.25 | B36: org | C36: Pekerja | D36: 130000 | E36: =A36*D36 -> 32500 | F36: 0 | G36: =E36+F36 -> 32500
A37: 0.15 | B37: org | C37: Tukang batu | D37: 200000 | E37: =A37*D37 -> 30000 | F37: 0 | G37: =E37+F37 -> 30000
A38: 0.018 | B38: org | C38: Mandor | D38: 265000 | E38: =A38*D38 -> 4770 | F38: 0 | G38: =E38+F38 -> 4770
A39: 1 | B39: Ls | C39: Alat Bantu | E39: 7000 | F39: =60000/4 -> 15000 | G39: =E39+F39 -> 22000
C40: JUMLAH ( BELUM PPN ) | E40: =SUM(E32:E39) -> 74270 | F40: =SUM(F32:F39) -> 106058.58 | G40: =SUM(G32:G39) -> 180328.58
C41: JASA 10 % | D41: 0.15 | E41: =E40*D41 -> 11140.5 | F41: =F40*D41 -> 15908.786 | G41: =D41*G40 -> 27049.286
C42: JUMLAH | E42: =SUM(E40:E41) -> 85410.5 | F42: =SUM(F40:F41) -> 121967.36 | G42: =SUM(G40:G41) -> 207377.86
A44: 1 | B44: m2 | C44: Plesteran 1 Pc : 3 Ps, tebal 15 mm
A46: Jenis Pekerjaan | D46: Harga satuan | E46: Upah | F46: Bahan | G46: Jumlah
A47: 7.776 | B47: kg | C47: PC | D47: 1700 | E47: 0 | F47: =A47*D47 -> 13219.2 | G47: =E47+F47 -> 13219.2
A48: 0.023 | B48: m3 | C48: Pasir pasang | D48: 342000 | E48: 0 | F48: =A48*D48 -> 7866 | G48: =E48+F48 -> 7866
A49: 0.2 | B49: org | C49: Pekerja | D49: 130000 | E49: =A49*D49 -> 26000 | F49: 0 | G49: =E49+F49 -> 26000
A50: 0.15 | B50: org | C50: Tukang batu | D50: 180000 | E50: =A50*D50 -> 27000 | F50: 0 | G50: =E50+F50 -> 27000
A51: 0.015 | B51: org | C51: Kepala Tukang | D51: 250000 | E51: =A51*D51 -> 3750 | F51: 0 | G51: =E51+F51 -> 3750
A52: 0.015 | B52: org | C52: Mandor | D52: 250000 | E52: =A52*D52 -> 3750 | F52: 0 | G52: =E52+F52 -> 3750
A53: 1 | B53: Ls | C53: Alat Bantu | E53: 3000 | F53: =60000/4 -> 15000 | G53: =E53+F53 -> 18000
C54: JUMLAH ( BELUM PPN ) | E54: =SUM(E47:E53) -> 63500 | F54: =SUM(F47:F53) -> 36085.2 | G54: =SUM(G47:G52) -> 81585.2
C55: JASA 10 % | D55: 0.15 | E55: =E54*D55 -> 9525 | F55: =F54*D55 -> 5412.78 | G55: =D55*G54 -> 12237.78
C56: JUMLAH | E56: =SUM(E54:E55) -> 73025 | F56: =SUM(F54:F55) -> 41497.98 | G56: =SUM(G54:G55) -> 93822.98
A58: 1 | B58: m1 | C58: Acian Dinding Bata
A60: Jenis Pekerjaan | D60: Harga satuan | E60: Upah | F60: Bahan | G60: Jumlah
A61: 0.5 | B61: kg | C61: PC | D61: 1700 | E61: 0 | F61: =A61*D61 -> 850 | G61: =E61+F61 -> 850
...

Sheet ANALISA
K2: Harga 2023 | L2: bahan | M2: upah | N2: angkut | P2: jumlah asesoris pintu masih kurang, ikuti volume diamond
A3: 1 | C3: Pasang Bata Ringan / m2 | P3: harga keramik belum update
C4: Celcon t=7.5 cm | F4: m3 | G4: 0.075 | H4: 985000 | I4: =G4*H4 -> 73875
C5: Kolom praktis canal c | F5: m' | G5: 0.38 | H5: 49666.667 | I5: =G5*H5 -> 18873.333 | L5: =30000/3 -> 10000 | M5: 39000 | N5: =1000000/1500 -> 666.66667 | O5: =SUM(L5:N5) -> 49666.667
C6: MU 380 | F6: zak | G6: 0.11 | H6: 135000 | I6: =G6*H6 -> 14850
C7: Upah pasang | F7: m2 | G7: 1 | H7: 55000 | I7: =G7*H7 -> 55000
C8: Alat bantu | F8: ls | G8: 1 | H8: 250 | I8: =G8*H8 -> 250
I9: =SUM(I4:I8) -> 162848.33
I10: =INT(I9/1000*1000) -> 162848
A11: =A1+1 -> 1 | C11: Plesteran adukan instant / m2
C12: MU 301 | F12: zak | G12: 0.65 | H12: 135000 | I12: =G12*H12 -> 87750
C13: Upah plester | F13: m2 | G13: 1 | H13: 34000 | I13: =G13*H13 -> 34000
C14: Alat bantu | F14: ls | G14: 1 | H14: 9000 | I14: =G14*H14 -> 9000
I15: =SUM(I12:I14) -> 130750
A16: =A9+1 -> 1 | C16: Acian semen / m2
C17: PC Setara Tigaroda | F17: zak | G17: 0.25 | H17: 135000 | I17: =G17*H17 -> 33750
C18: Upah aci | F18: ls | G18: 1 | H18: 34000 | I18: =G18*H18 -> 34000
I19: =SUM(I17:I18) -> 67750
A20: =A13+1 -> 1 | C20: Kolom Praktis 100 x 100 / m'
C21: Beton | F21: m³ | G21: =0.1*0.1*1 -> 0.01 | H21: 1002920 | I21: =G21*H21 -> 10029.2
C22: Besi | F22: m1 | G22: 1 | H22: =(((7.4/12)*4))+((4.74/12)*(0.45*5))*19500 -> 17333.092 | I22: =G22*H22 -> 17333.092
C23: Bekisting | F23: m² | G23: =0.1*1*4 -> 0.4 | H23: =(234000/2.97)+(4*4*5000)+(23000/12) -> 160704.55 | I23: =G23*H23 -> 64281.818
C24: Upah & alat | E24: =(I26*0.1) -> 0 | F24: m' | G24: 1 | H24: =SUM(I21:I23)/2 -> 45822.055 | I24: =G24*H24 -> 45822.055
H25: per m1 | I25: =SUM(I21:I24) -> 137466.16
A27: =1+A4 -> 1 | C27: Perapihan Beton Exposed (skim coat) / m2
C28: MU 270 | F28: m2 | G28: 0.25 | H28: 89800 | I28: =G28*H28 -> 22450
C29: Upah aci | F29: ls | G29: 1 | H29: 34000 | I29: =G29*H29 -> 34000
C30: Upah ketrik beton | F30: m2 | G30: 1 | H30: 15000 | I30: =G30*H30 -> 15000
C31: Alat bantu | F31: ls | G31: 1 | H31: 250 | I31: =G31*H31 -> 250
I32: =SUM(I28:I31) -> 71700
A33: =1 -> 1 | C33: Urugan Pasir / m3
C34: Pasir urug | F34: m3 | G34: 1 | H34: =1800000/7 -> 257142.86 | I34: =G34*H34 -> 257142.86
C35: Upah urug | F35: m3 | G35: 1 | H35: 7500 | I35: =G35*H35 -> 7500
C36: Alat bantu | F36: ls | G36: 1 | H36: 1000 | I36: =G36*H36 -> 1000
I37: =SUM(I34:I36) -> 265642.86 | L37: /m2
H38: t=10 cm | I38: =I37*0.1 -> 26564.286 | L38: 23000
A39: 1 | C39: Lantai Granite Tile 60 x 60 / m2 (Verona GB 126005S) BY OWNER
C40: Bahan :
C41: Granite tile 60x60 ex. Wisma Sehati (BY OWNER) | F41: m2 | G41: 1.02 | H41: =85000*0 -> 0 | I41: =G41*H41 -> 0
C42: Perekat MU-450 | F42: zak | G42: 0.125 | H42: 97125 | I42: =G42*H42 -> 12140.625
...

Sheet hardscape
A1: BILL OF ITEM
A3: Proyek | D3: =+#REF! -> #REF! | H3: PEMBERI TUGAS :
A4: Lokasi Proyek | D4: =+#REF! -> #REF! | H4: PT. PRASETYA AGUNG CIPTA ABADI
A5: Paket Pekerjaan | D5: =+#REF! -> #REF!
A6: Kontraktor | D6: =+#REF! -> #REF!
A7: Catatan | D7: =+#REF! -> #REF!
D8: =+#REF! -> #REF!
M10: koef | N10: =+'3. Struktur'!T10 -> 0
A11: NO | B11: URAIAN PEKERJAAN | E11: SPESIFIKASI | F11: SAT | G11: Volume | H11: Harga Satuan | J11: Jumlah | L11: Jumlah | N11: -2
H12: Material Utama | I12: Mat bantu+upah | J12: Material Utama | K12: Mat bantu+upah | L12: Total | N12: 0.75 | O12: =1-N12 -> 0.25
A13: V | B13: PEKERJAAN HARDSCAPE "LAGOON"
A14: A. | B14: AREA "ADULT POOL"
A15: 1 | B15: Finishing "Adult Pool" dan "Kolam Rendam"
A16: 1.1 | B16: Finishing Lantai dan dinding "ADULT POOL" termasuk "KOLAM RENDAM"
B17: Keramik Lantai, tangga dan dinding Kolam 100x100 mm warna random
C18: - warna biru tua | E18: Blue berry ex. Samson | F18: m2 | G18: =35+165 -> 200 | H18: ='Ars Diamond'!V681 -> #REF! | I18: ='Ars Diamond'!W681 -> #REF! | J18: =G18*H18 -> #REF! | K18: =G18*I18 -> #REF! | L18: =J18+K18 -> #REF!
C19: - warna biru sedang | E19: Navy Blue ex. Samson | F19: m2 | G19: 164 | H19: ='Ars Diamond'!V682 -> #REF! | I19: ='Ars Diamond'!W682 -> #REF! | J19: =G19*H19 -> #REF! | K19: =G19*I19 -> #REF! | L19: =J19+K19 -> #REF!
C20: - warna biru muda | E20: Marina Blue ex. Samson | F20: m2 | G20: =280+164 -> 444 | H20: ='Ars Diamond'!V683 -> #REF! | I20: ='Ars Diamond'!W683 -> #REF! | J20: =G20*H20 -> #REF! | K20: =G20*I20 -> #REF! | L20: =J20+K20 -> #REF!
C21: - warna putih | E21: Cico white ex. Samson | F21: m2 | G21: 164 | H21: ='Ars Diamond'!V684 -> #REF! | I21: ='Ars Diamond'!W684 -> #REF! | J21: =G21*H21 -> #REF! | K21: =G21*I21 -> #REF! | L21: =J21+K21 -> #REF!
B22: Coping dinding kolam | E22: Batu salagedang warna abu-abu hitam | F22: m' | G22: 108 | H22: ='Ars Diamond'!V685 -> #REF! | I22: ='Ars Diamond'!W685 -> #REF! | J22: =G22*H22 -> #REF! | K22: =G22*I22 -> #REF! | L22: =J22+K22 -> #REF!
E23: uk. 300x300x50mm rata mesin ; clear coating ex. Propan | J23: =G23*H23 -> 0 | K23: =G23*I23 -> 0 | L23: =J23+K23 -> 0
B24: Waterproofing untuk lantai, dinding dan deck | F24: m2 | G24: 1067 | H24: ='Ars Diamond'!V687 -> #REF! | I24: ='Ars Diamond'!W687 -> #REF! | J24: =G24*H24 -> #REF! | K24: =G24*I24 -> #REF! | L24: =J24+K24 -> #REF!
B25: Gutter overflow sekeliling kolam t=30 cm ; lebar = 25 cm | F25: m' | G25: 61 | H25: ='Ars Diamond'!V688 -> #REF! | I25: ='Ars Diamond'!W688 -> #REF! | J25: =G25*H25 -> #REF! | K25: =G25*I25 -> #REF! | L25: =J25+K25 -> #REF!
B26: Penutup Gutter over flow | E26: batu salagedang 300x300x50 mm ; rata mesin | F26: m' | G26: 61 | H26: ='Ars Diamond'!V689 -> #REF! | I26: ='Ars Diamond'!W689 -> #REF! | J26: =G26*H26 -> #REF! | K26: =G26*I26 -> #REF! | L26: =J26+K26 -> #REF!
E27: finish clear coating ex. Propan | J27: =G27*H27 -> 0 | K27: =G27*I27 -> 0 | L27: =J27+K27 -> 0
J28: =G28*H28 -> 0 | K28: =G28*I28 -> 0 | L28: =J28+K28 -> 0
A29: 1.2 | B29: Finishing Planter | J29: =G29*H29 -> 0 | K29: =G29*I29 -> 0 | L29: =J29+K29 -> 0
B30: - waterproofing dinding dan dasar planter | F30: m2 | G30: 120 | H30: =H24 -> #REF! | I30: =I24 -> #REF! | J30: =G30*H30 -> #REF! | K30: =G30*I30 -> #REF! | L30: =J30+K30 -> #REF!
B31: - Pengadaan sistem drainasi planter | F31: m2 | G31: 109 | H31: ='Ars Diamond'!V674 -> #REF! | I31: ='Ars Diamond'!W674 -> #REF! | J31: =G31*H31 -> #REF! | K31: =G31*I31 -> #REF! | L31: =J31+K31 -> #REF!
B32: - Coping planter | E32: Batu salagedang warna abu-abu hitam | F32: m' | G32: 45 | H32: ='Ars Diamond'!V675 -> #REF! | I32: ='Ars Diamond'!W675 -> #REF! | J32: =G32*H32 -> #REF! | K32: =G32*I32 -> #REF! | L32: =J32+K32 -> #REF!
E33: uk. 200x200x50mm rata mesin ; clear coating ex. Propan | J33: =G33*H33 -> 0 | K33: =G33*I33 -> 0 | L33: =J33+K33 -> 0
J34: =G34*H34 -> 0 | K34: =G34*I34 -> 0 | L34: =J34+K34 -> 0
A35: 2 | B35: Cabana | J35: =G35*H35 -> 0 | K35: =G35*I35 -> 0 | L35: =J35+K35 -> 0
A36: 2.1 | B36: Pembuatan Dudukan Cabana | J36: =G36*H36 -> 0 | K36: =G36*I36 -> 0 | L36: =J36+K36 -> 0
B37: - Balok 30x50 | F37: m' | G37: 25 | H37: =ROUND(N37*$N$10,$N$11) -> 0 | I37: =ROUND(O37*$N$10,$N$11) -> 0 | J37: =G37*H37 -> 0 | K37: =G37*I37 -> 0 | L37: =J37+K37 -> 0 | N37: =+P37*$N$12 -> 281250 | O37: =+$O$12*P37 -> 93750 | P37: =0.3*0.5*2500000 -> 375000
B38: - Pasangan bata ringan | F38: m2 | G38: 3.6 | H38: ='Ars Diamond'!V46 -> 107848.33 | I38: ='Ars Diamond'!W46 -> 55000 | J38: =G38*H38 -> 388254 | K38: =G38*I38 -> 198000 | L38: =J38+K38 -> 586254
B39: - screed lantai cabana | F39: m2 | G39: 31.25 | H39: =ROUND(N39*$N$10,$N$11) -> 0 | I39: =ROUND(O39*$N$10,$N$11) -> 0 | J39: =G39*H39 -> 0 | K39: =G39*I39 -> 0 | L39: =J39+K39 -> 0 | N39: 30000 | O39: 0
B40: - Lantai cabana | E40: batu salagedang warna abu-abu uk.300x300x20 mm | F40: m2 | G40: 31.25 | H40: =ROUND(N40*$N$10,$N$11) -> 0 | I40: =ROUND(O40*$N$10,$N$11) -> 0 | J40: =G40*H40 -> 0 | K40: =G40*I40 -> 0 | L40: =J40+K40 -> 0 | N40: 230000 | O40: 23000
E41: rata alam finish clear coating ; ex. Propan | J41: =G41*H41 -> 0 | K41: =G41*I41 -> 0 | L41: =J41+K41 -> 0
J42: =G42*H42 -> 0 | K42: =G42*I42 -> 0 | L42: =J42+K42 -> 0
...

Sheet Ars Diamond
A1: BILL OF ITEM
A3: Proyek | D3: =+#REF! -> #REF! | G3: =+#REF! -> #REF! | V3: PEMBERI TUGAS :
A4: Lokasi Proyek | D4: =+#REF! -> #REF! | G4: =+#REF! -> #REF! | V4: PT. BINAKARYA BANGUN PROPERTINDO
A5: Paket Pekerjaan | D5: =+#REF! -> #REF!
A6: Kontraktor | D6: =+#REF! -> #REF!
A7: Catatan | D7: =+#REF! -> #REF!
D8: =+#REF! -> #REF!
AA10: koef | AB10: =+'Ars topaz'!R10 -> #REF!
A11: NO | B11: URAIAN PEKERJAAN | E11: SPESIFIKASI | F11: SAT | G11: VOLUME | U11: Volume | V11: Harga Satuan | X11: Jumlah | Z11: Jumlah | AB11: 0
G12: Basement | H12: Lt. Dasar | I12: Lt. 1 | J12: Lt. 2 | K12: Lt. 3 | L12: Lt. 4 | M12: Lt. 5 | N12: Lt. 6 | O12: Lt. 7 | P12: Lt. 8 | Q12: Lt. 9 | R12: Lt. 10 | S12: Lt. 11 | T12: Lt. Atap + R.Mesin | U12: Total | V12: Material Utama | W12: Mat bantu+upah | X12: Material Utama | Y12: Mat bantu+upah | Z12: Total | AB12: 0.75 | AC12: =1-AB12 -> 0.25
A13: III | B13: PEKERJAAN ARSITEKTUR
A14: B | B14: PEKERJAAN ARSITEKTUR TOWER DIAMOND
B15: Catatan :
B16: Pekerjaan pasangan dinding bata ringan
B17: Harga satuan dinding bata dinding bata ringan ex. Primacon/setara
B18: yang disetujui dengan perekat dan adukan khusus, sudah termasuk angkur
B19: untuk setiap pasangan dinding yang berhubungan dengan kolom struktur
B20: (besi n 8 mm, p=40cm/titik ; setiap sisi dipasang 2 buah), termasuk juga
B21: sparing, dan semua pekerjaan bantu yang berhubungan dengan pekerjaan.
B23: Harga satuan plesteran sudah termasuk acian, ketrikan atau bobokan beton
B24: maupun bata, kawat ayam (bila diperlukan) dan semua pekerjaan
B25: bantu yang diperlukan.
B27: Plesteran dan acian dinding bata ringan ex. Primacon/setara yang disetujui,
B28: menggunakan adukan mortar ex. Mortar Utama atau setara yang disetujui
... B40: 2 sisi masing-masing tebal 9 mm
A42: B.1 | B42: PEKERJAAN PASANGAN DINDING
A43: 1 | B43: Pekerjaan Pasangan untuk Dinding Ruangan
B44: Pasangan bata ringan t=7,5 cm untuk dinding penyekat ruangan di unit, KM, dan
B45: ruang-ruang fasilitas lainnya tidak termasuk dinding lift :
B46: - Pasangan bata ringan tebal = 7,5 cm [tebal finish=10cm] + thinbed | E46: Bata ringan ex. Primacon/setara + thinbed MU-380/setara | F46: m2 | G46: 4159 | H46: 2107 | I46: 1787 | J46: 1787 | K46: 1787 | L46: 1787 | M46: 1787 | N46: 1787 | O46: 1713 | P46: 1694 | Q46: 1695 | R46: 1696 | S46: 1697 | T46: 264 | U46: =SUM(G46:T46) -> 25747 | V46: ='Ars topaz'!L40 -> 107848.33 | W46: ='Ars topaz'!M40 -> 55000 | X46: =U46*V46 -> 2.776771e+09 | Y46: =U46*W46 -> 1416085000 | Z46: =X46+Y46 -> 4.192856e+09
B47: - Plesteran mortar t=1 cm/sisi, | E47: ex. MU-301/setara | F47: m2 | G47: 7454.5918 | H47: 3174 | I47: 4335.5816 | J47: 3174 | K47: 4335.5816 | L47: 3174 | M47: 4335.5816 | N47: 3174 | O47: 4335.5816 | P47: 3174 | Q47: 3174 | R47: 3174 | S47: 3174 | T47: 528 | U47: =SUM(G47:T47) -> 50716.918 | V47: ='Ars topaz'!L41 -> 90750 | W47: ='Ars topaz'!M41 -> 40000 | X47: =U47*V47 -> 4.6025603e+09 | Y47: =U47*W47 -> 2.0286767e+09 | Z47: =X47+Y47 -> 6.631237e+09
B48: - Acian mortar t=2,5mm/sisi | E48: ex. MU-250/setara | F48: m2 | G48: 7275.1118 | H48: 2601.32 | I48: 3883.4402 | J48: 2601.32 | K48: 3883.4402 | L48: 2601.32 | M48: 3883.4402 | N48: 2601.32 | O48: 3883.4402 | P48: 2601.32 | Q48: 2601.32 | R48: 2601.32 | S48: 2601.32 | T48: 428 | U48: =SUM(G48:T48) -> 44047.433 | V48: ='Ars topaz'!L42 -> 33750 | W48: ='Ars topaz'!M42 -> 34000 | X48: =U48*V48 -> 1.4866008e+09 | Y48: =U48*W48 -> 1.4976127e+09 | Z48: =X48+Y48 -> 2.9842136e+09
B49: - Penebalan dinding belakang shower, setinggi plafond | F49: m2 | H49: 99 | I49: 117 | J49: 117 | K49: 117 | L49: 117 | M49: 117 | N49: 117 | O49: 117 | P49: 128 | Q49: 128 | R49: 128 | S49: 128 | U49: =SUM(G49:T49) -> 1430 | V49: ='Ars topaz'!#REF! -> #REF! | W49: ='Ars topaz'!#REF! -> #REF! | X49: =U49*V49 -> #REF! | Y49: =U49*W49 -> #REF! | Z49: =X49+Y49 -> #REF!
A50: 2 | B50: Pekerjaan Pasangan untuk Dinding Lift | U50: =SUM(G50:T50) -> 0 | X50: =U50*V50 -> 0 | Y50: =U50*W50 -> 0 | Z50: =X50+Y50 -> 0
B51: =+B46 -> - Pasangan bata ringan tebal = 7,5 cm [tebal finish=10cm] + thinbed | E51: =+E46 -> Bata ringan ex. Primacon/setara + thinbed MU-380/setara | F51: m2 | G51: 116 | H51: 116 | I51: 95 | J51: 95 | K51: 95 | L51: 95 | M51: 95 | N51: 95 | O51: 95 | P51: 95 | Q51: 95 | R51: 95 | S51: 95 | U51: =SUM(G51:T51) -> 1277 | V51: ='Ars topaz'!#REF! -> #REF! | W51: ='Ars topaz'!#REF! -> #REF! | X51: =U51*V51 -> #REF! | Y51: =U51*W51 -> #REF! | Z51: =X51+Y51 -> #REF!
B52: =+B47 -> - Plesteran mortar t=1 cm/sisi, | E52: =+E47 -> ex. MU-301/setara | F52: m2 | G52: 232 | H52: 232 | I52: 190 | J52: 190 | K52: 190 | L52: 190 | M52: 190 | N52: 190 | O52: 190 | P52: 190 | Q52: 190 | R52: 190 | S52: 190 | U52: =SUM(G52:T52) -> 2554 | V52: ='Ars topaz'!#REF! -> #REF! | W52: ='Ars topaz'!#REF! -> #REF! | X52: =U52*V52 -> #REF! | Y52: =U52*W52 -> #REF! | Z52: =X52+Y52 -> #REF!
B53: - Acian mortar t=2,5mm (sisi Luar) | E53: =+E48 -> ex. MU-250/setara | F53: m2 | G53: 232 | H53: 232 | I53: 190 | J53: 190 | K53: 190 | L53: 190 | M53: 190 | N53: 190 | O53: 190 | P53: 190 | Q53: 190 | R53: 190 | S53: 190 | U53: =SUM(G53:T53) -> 2554 | V53: ='Ars topaz'!#REF! -> #REF! | W53: ='Ars topaz'!#REF! -> #REF! | X53: =U53*V53 -> #REF! | Y53: =U53*W53 -> #REF! | Z53: =X53+Y53 -> #REF!
A54: 3 | B54: Pekerjaan Pasangan Dinding Precast | U54: =SUM(G54:T54) -> 0 | X54: =U54*V54 -> 0 | Y54: =U54*W54 -> 0 | Z54: =X54+Y54 -> 0
B55: Pasangan dinding precast beton tampak exterior fasade dari lantai 1-11 : | U55: =SUM(G55:T55) -> 0 | X55: =U55*V55 -> 0 | Y55: =U55*W55 -> 0 | Z55: =X55+Y55 -> 0
B56: ◦ Dinding precast tampak exterior : | U56: =SUM(G56:T56) -> 0 | X56: =U56*V56 -> 0 | Y56: =U56*W56 -> 0 | Z56: =X56+Y56 -> 0
...

Sheet Ars topaz
A1: BILL OF ITEM
A3: Proyek | D3: =+#REF! -> #REF! | G3: =+#REF! -> #REF! | L3: PEMBERI TUGAS :
A4: Lokasi Proyek | D4: =+#REF! -> #REF! | G4: =+#REF! -> #REF! | L4: PT. BINAKARYA BANGUN PROPERTINDO
A5: Paket Pekerjaan | D5: =+#REF! -> #REF!
A6: Kontraktor | D6: =+#REF! -> #REF!
A7: Catatan | D7: =+#REF! -> #REF!
D8: =+#REF! -> #REF!
Q10: koef | R10: =+#REF! -> #REF! | S10: 1
A11: NO | B11: URAIAN PEKERJAAN | E11: SPESIFIKASI | F11: SAT | G11: VOLUME | K11: Volume | L11: Harga Satuan | N11: Jumlah | P11: Jumlah | R11: -2
G12: Basement | H12: Lt. Dasar | I12: Lt. 1 | J12: Lt. 2 | K12: Total | L12: Material Utama | M12: Mat bantu+upah | N12: Material Utama | O12: Mat bantu+upah | P12: Total | R12: 0.75 | S12: =1-R12 -> 0.25
A13: III | B13: PEKERJAAN ARSITEKTUR
A14: A | B14: PEKERJAAN ARSITEKTUR TOWER TOPAZ
B15: Catatan :
B16: Pekerjaan pasangan dinding bata ringan
B17: Harga satuan dinding bata dinding bata ringan ex. Primacon/setara
B18: yang disetujui dengan perekat dan adukan khusus, sudah termasuk angkur
B19: untuk setiap pasangan dinding yang berhubungan dengan kolom struktur
B20: (besi n 8 mm, p=40cm/titik ; setiap sisi dipasang 2 buah), termasuk juga
B21: sparing, dan semua pekerjaan bantu yang berhubungan dengan pekerjaan.
B23: Harga satuan plesteran sudah termasuk acian, ketrikan atau bobokan beton
B24: maupun bata, kawat ayam (bila diperlukan) dan semua pekerjaan
B25: bantu yang diperlukan.
B27: Plesteran dan acian dinding bata ringan ex. Pc Tigaroda, pasir pasang/setara,
B29: Pembetukan sudutan pada pertemuan dinding sisi luar, sudutan kolom,
... B34: dimana permukaan expose beton rata dan pembentukan sudutan rapi/lurus
A36: A.1 | B36: PEKERJAAN PASANGAN DINDING
A37: 1 | B37: Pekerjaan Pasangan untuk Dinding Ruangan
B38: Pasangan bata ringan t=7,5 cm untuk dinding penyekat ruangan di unit, KM, dan
B39: ruang-ruang fasilitas lainnya tidak termasuk dinding lift :
B40: - Pasangan bata ringan tebal = 7,5 cm [tebal finish=10cm] + thinbed | E40: Bata ringan ex. Primacon/setara + thinbed MU-380/setara | F40: m2 | G40: 145.15 | H40: 101.35 | I40: 312.2 | J40: 193.4 | K40: =SUM(G40:J40) -> 752.1 | L40: =ANALISA!$I$9-55000 -> 107848.33 | M40: 55000 | N40: =K40*L40 -> 81112731 | O40: =K40*M40 -> 41365500 | P40: =N40+O40 -> 1.2247823e+08 | R40: 97898.65 | S40: 17030
B41: - Plesteran t=2,5 cm/sisi, | E41: 1Pc : 3 Ps | F41: m2 | G41: =G40*2 -> 290.3 | H41: =H40*2 -> 202.7 | I41: =I40*2 -> 624.4 | J41: =J40*2 -> 386.8 | K41: =SUM(G41:J41) -> 1504.2 | L41: =ANALISA!$I$15-40000 -> 90750 | M41: 40000 | N41: =K41*L41 -> 136506150 | O41: =K41*M41 -> 60168000 | P41: =N41+O41 -> 196674150 | R41: 24381.5 | S41: 16740
B42: - Acian mortar t=0,05mm/sisi | E42: Potland Cemen Setara Tigaroda | F42: m2 | G42: =G41 -> 290.3 | H42: =H41 -> 202.7 | I42: =I41 -> 624.4 | J42: =J41 -> 386.8 | K42: =SUM(G42:J42) -> 1504.2 | L42: =ANALISA!$I$17 -> 33750 | M42: =ANALISA!$I$18 -> 34000 | N42: =K42*L42 -> 50766750 | O42: =K42*M42 -> 51142800 | P42: =N42+O42 -> 101909550 | R42: 14842.5 | S42: 10390
A43: 2 | B43: Dinding Toilet Keramik uk.20x40 cm
B44: Pasangan Keramik Toilet setara Roman
B45: - Dinding Toilet | E45: Keramik setara roman, perekat pc setara tigaroda | F45: m2 | G45: 59.3 | H45: 47.5 | I45: 173 | J45: 43 | K45: =SUM(G45:J45) -> 322.8 | L45: 245000 | M45: 35000 | N45: =K45*L45 -> 79086000 | O45: =K45*M45 -> 11298000 | P45: =N45+O45 -> 90384000 | R45: 97898.65 | S45: 17030
O46: SUB TOTAL A.1 | P46: =SUM(P13:P45) -> 5.1144593e+08
A48: A.2 | B48: PEKERJAAN FINISHING PLAFOND DAN DINDING
B49: Catatan harga :
B50: Pekerjaan dan Pemasangan plafond gypsum
B51: Harga satuan biaya pemasangan sudah termasuk upah angkut bahan, pemotongan
...

Sheet ANALISA ATAP
A3: 1 | C3: Kuda-kuda baja ringan M2
C4: Baja ringan Canal 0,75 | F4: M' | G4: 6 | H4: =160000/6 -> 26666.667 | I4: =G4*H4 -> 160000
C5: Baud | F5: bh | G5: 28 | H5: 1000 | I5: =G5*H5 -> 28000
C6: Dynabolt | F6: bh | G6: 1 | H6: 10000 | I6: =G6*H6 -> 10000
C7: Alat bantu | F7: ls | G7: 1 | H7: 7000 | I7: =G7*H7 -> 7000
I8: =SUM(I4:I6) -> 198000
E9: keuntungan | H9: 0.15 | I9: =I8*H9 -> 29700
I10: =SUM(I8:I9) -> 227700
C11: Upah :
C12: Pekerja | F12: OH | G12: 0.2 | H12: 130000 | I12: =G12*H12 -> 26000
C13: Tukang Besi | F13: OH | G13: 0.45 | H13: 180000 | I13: =G13*H13 -> 81000
C14: Kepala Tukang | F14: OH | G14: 0.01 | H14: 200000 | I14: =G14*H14 -> 2000
C15: Mandor | F15: OH | G15: 0.05 | H15: 260000 | I15: =G15*H15 -> 13000
I16: =SUM(I12:I15) -> 122000
E17: keuntungan | H17: 0.15 | I17: =I16*H17 -> 18300
I18: =SUM(I16:I17) -> 140300
A20: =A3+1 -> 2 | C20: Reng Kuda-kuda baja ringan M2
C21: Reng ringan Canal 0,45 | F21: M' | G21: 4 | H21: =45000/4 -> 11250 | I21: =G21*H21 -> 45000
C22: Baud | F22: bh | G22: 28 | H22: 500 | I22: =G22*H22 -> 14000
C23: Alat bantu | F23: ls | G23: 1 | H23: =800 -> 800 | I23: =G23*H23 -> 800
I24: =SUM(I21:I22) -> 59000
E25: keuntungan | H25: 0.15 | I25: =I24*H25 -> 8850
I26: =SUM(I24:I25) -> 67850
C27: Upah :
C28: Pekerja | F28: OH | G28: 0.005 | H28: 130000 | I28: =G28*H28 -> 650
C29: Tukang Besi | F29: OH | G29: 0.015 | H29: 180000 | I29: =G29*H29 -> 2700
C30: Kepala Tukang | F30: OH | G30: 0.01 | H30: 200000 | I30: =G30*H30 -> 2000
C31: Mandor | F31: OH | G31: 0.015 | H31: 260000 | I31: =G31*H31 -> 3900
I32: =SUM(I28:I31) -> 9250
E33: keuntungan | H33: 0.15 | I33: =I32*H33 -> 1387.5
I34: =SUM(I32:I33) -> 10637.5
A36: =A20+1 -> 3 | C36: Pekerjaan Almunium Foil M2
C37: Almunium Foil | F37: M2 | G37: 1 | H37: =300000/25 -> 12000 | I37: =G37*H37 -> 12000
C38: Baud | F38: bh | G38: 4 | H38: 500 | I38: =G38*H38 -> 2000
C39: Alat bantu | F39: ls | G39: 1 | H39: =2000 -> 2000 | I39: =G39*H39 -> 2000
I40: =SUM(I37:I38) -> 14000
E41: keuntungan | H41: 0.15 | I41: =I40*H41 -> 2100
I42: =SUM(I40:I41) -> 16100
C43: Upah :
C44: Pekerja | F44: OH | G44: 0.01 | H44: 130000 | I44: =G44*H44 -> 1300
...

Sheet ANALISA PLAFOND
A1: 1 | C1: Pekerjaan Plafond | E1: M2
C2: Gypsum Board / kisi-kisi kayu | F2: M2 | G2: 1 | H2: =190000/2.97 -> 63973.064 | I2: =G2*H2 -> 63973.064
C3: Paku Skrup | F3: bh | G3: 12 | H3: 1000 | I3: =G3*H3 -> 12000
C4: Hollo Plafond | F4: btg | G4: 1 | H4: =70000 -> 70000 | I4: =G4*H4 -> 70000
C5: Gypsum compon | F5: kg | G5: 0.1 | H5: =80000/40 -> 2000 | I5: =G5*H5 -> 200
I6: =SUM(I2:I5) -> 146173.06
E7: keuntungan | H7: 0.15 | I7: =I6*H7 -> 21925.96
I8: =SUM(I6:I7) -> 168099.02
C9: Upah :
C10: Pekerja | F10: OH | G10: 0.1 | H10: 130000 | I10: =G10*H10 -> 13000
C11: Tukang Kayu | F11: OH | G11: 0.05 | H11: 180000 | I11: =G11*H11 -> 9000
C12: Kepala Tukang | F12: OH | G12: 0.005 | H12: 220000 | I12: =G12*H12 -> 1100
C13: Mandor | F13: OH | G13: 0.005 | H13: 260000 | I13: =G13*H13 -> 1300
I14: =SUM(I10:I13) -> 24400
E15: keuntungan | H15: 0.15 | I15: =I14*H15 -> 3660
I16: =SUM(I14:I15) -> 28060
A17: =A1+1 -> 2 | C17: Pekerjaan CAT Plafond | E17: M2
C18: Plamuur | F18: Kg | G18: 0.15 | H18: =700000/20 -> 35000 | I18: =G18*H18 -> 5250
C19: Cat Dasar | F19: Kg | G19: 0.17 | H19: =700000/20 -> 35000 | I19: =G19*H19 -> 5950
C20: Cat Penutup | F20: Kg | G20: 0.35 | H20: =700000/20 -> 35000 | I20: =G20*H20 -> 12250
C21: Kuas | F21: Bh | G21: 0.01 | H21: 31000 | I21: =G21*H21 -> 310
C22: Pengencer | F22: Kg | G22: 0.03 | H22: 25000 | I22: =G22*H22 -> 750
C23: Amplas | F23: Lbr | G23: 0.2 | H23: 7500 | I23: =G23*H23 -> 1500
I24: =SUM(I18:I23) -> 26010
E25: keuntungan | H25: 0.15 | I25: =I24*H25 -> 3901.5
I26: =SUM(I24:I25) -> 29911.5
C27: Upah :
C28: Pekerja | F28: OH | G28: 0.05 | H28: =H10 -> 130000 | I28: =G28*H28 -> 6500
C29: Tukang Cat | F29: OH | G29: 0.03 | H29: =H11 -> 180000 | I29: =G29*H29 -> 5400
C30: Kepala Tukang | F30: OH | G30: 0.005 | H30: =H12 -> 220000 | I30: =G30*H30 -> 1100
C31: Mandor | F31: OH | G31: 0.005 | H31: =H13 -> 260000 | I31: =G31*H31 -> 1300
I32: =SUM(I28:I31) -> 14300
E33: keuntungan | H33: 0.15 | I33: =I32*H33 -> 2145
I34: =SUM(I32:I33) -> 16445

Sheet 9. Pekerjaan MEP
A1: BILL OF ITEM
A3: Proyek | D3: ='3. Struktur'!D3 -> : Pembangunan Rumah Tinggal di Pondok Indah Rumah Hunian
A4: Lokasi Proyek | D4: ='3. Struktur'!D4 -> : Jl. Sekolah Duta 1 Blok 1 TC No.19
A5: Paket Pekerjaan | D5: ='3. Struktur'!D5 -> : STRUKTUR - ARSITEKTUR - MEP
A6: Kontraktor | D6: ='3. Struktur'!D6 -> : PT TRIDJASA SIGMA INDONESIA
A7: Catatan | D7: ='3. Struktur'!D7 -> : Perhitungan ini merujuk pada gambar
D8: ='3. Struktur'!D8 -> FOR TENDER tanggal 28 Oktober 2023
AA10: koef | AB10: =+#REF! -> #REF! | AC10: 1
A11: NO | B11: URAIAN PEKERJAAN | E11: SPESIFIKASI | F11: SAT | G11: VOLUME | K11: Volume | L11: Harga Satuan | N11: Jumlah | P11: Harga Satuan | Q11: Jumlah | AB11: -2
G12: Basement | H12: Lt. Dasar | I12: Lt. 1 | J12: Lt. 2 | K12: Total | L12: Material Utama | M12: Mat bantu+upah | N12: Material Utama | O12: Mat bantu+upah | Q12: Total | AB12: 0.75 | AC12: =1-AB12 -> 0.25
A13: IX | B13: PEKERJAAN MEKANIKAL, ELEKTRIKAL & PLUMBING
B14: Catatan harga :
B15: Pekerjaan Mekanikal, Elektrikal & Plumbing | E15: - melakukan pembobokan untuk instalasi listrik
E16: - pekerjaan pengadaan material
B17: - material yang digunakan sesuai spesifikasi yang tertera
B18: - jika perubahan spesifikasi material maka ada penambahan biaya sesuai kesepakatan owner dan pelaksana kerja | R18: DEV | S18: PT. TSI | U18: DEV | V18: PT. MBP | X18: DEV | Y18: VENDOR
B19: - jika ada perubahan titik atau tempat pekerjaan MEP maka ada penambahan biaya dan disepakati bersama | S19: Harga Satuan | T19: Jumlah | V19: Harga Satuan | W19: Jumlah | Y19: Harga Satuan | Z19: Jumlah
A22: IX.A | B22: PEKERJAAN MEKANIKAL, ELEKTRKAL DAN PLUMBING --LANTAI BASEMAN | Q22: =Q23+Q47+Q57 -> 2.1704396e+08
A23: A | B23: Instalasi | Q23: =SUM(Q24:Q45) -> 1.2864043e+08
