Workbook
Name _\E: #REF!
Name _\F: #REF!
Name _\G: #REF!
Name _\H: #REF!
Name _\I: #REF!
Name _\J: #REF!
Name _\K: #REF!
Name _\L: #REF!
Name _\M: #REF!
Name _\N: #REF!
Name _\O: #REF!
Name _\P: #REF!
Name _\Q: #REF!
Name _\R: #REF!
Name _\S: #REF!
Name _\T: #REF!
Name _\U: #REF!
Name _\V: #REF!
Name _\W: #REF!
Name __\0: [1]Penjumlahan!#REF!
Name __\A: '[2]304-06'!#REF!
Name __\B: #REF!
Name __\C: #REF!
Name __\D: #REF!
Name __\E: #REF!
Name __\F: #REF!
Name __\G: #REF!
Name __\H: #REF!
Name __\I: #REF!
Name __\J: #REF!
Name __\K: #REF!
Name __\L: #REF!
Name __\M: #REF!
Name __\N: #REF!
Name __\O: #REF!
Name __\P: #REF!
Name __\Q: #REF!
Name __\R: #REF!
Name __\S: #REF!
Name __\T: #REF!
Name __\U: #REF!
Name __\V: #REF!
Name __\W: #REF!
Name __\WQ: '[3]BAG-2'!#REF!
Name __\x: [4]Cover1!#REF!
Name __\Y: #REF!
Name __\Z: #REF!
Name ___: [5]ANALIS!#REF!
Name ___: [5]ANALIS!#REF!
Name ___\0: [1]Penjumlahan!#REF!
Name ___\A: '[2]304-06'!#REF!
Name ___\B: #REF!
Name ___\C: #REF!
Name ___\D: #REF!
Name ___\WQ: '[3]BAG-2'!#REF!
Name ___\x: [4]Cover1!#REF!
Name ___\Y: #REF!
Name ___\Z: #REF!
Name ________C: #REF!
Name ________C: #REF!

Sheet COVER
A7: BILL OF QUANTITY
A20: PAKET
A21: PEMBANGUNAN RUMAH TINGGAL TYPE 90 DAN 134
A22: CLUSTER VARANA JAGORAWI GOLF ESTATE
A23: BOGOR - JAWA BARAT
B48: A G U S T U S 2 0 2 2

Sheet Rekap
A1: REKAPITULASI RENCANA ANGGARAN BIAYA
A2: Rumah Standar TIPE 53
A3: Cls. THE AWA 2
A4: JAGORAWI GOLF ESTATE
A5: PEMILIK PROYEK | C5: : PT. SENTOSA ASRI PROPERTINDO
A6: LOKASI | C6: : -
A8: NO. | B8: URAIAN PEKERJAAN | D8: Jumlah Harga ( Rp ) | E8: BOBOT | G8: Balance | H8: Harga Per M2
D9: TYPE 53 | F9: Koef
A12: I | B12: PEKERJAAN PERSIAPAN | D12: ='BQ L7'!O19 -> 3379584.9 | E12: =D12/$D$47 -> 0.010383389 | F12: 0.01 | G12: =F12-E12 -> -0.00038338891 | H12: =D12/$D$52 -> 63765.753
A14: II | B14: PEKERJAAN PONDASI | D14: ='BQ L7'!O41 -> 31923075 | E14: =D14/$D$47 -> 0.098080004 | F14: 0.028 | G14: =F14-E14 -> -0.070080004 | H14: =D14/$D$52 -> 602322.17
A16: III | B16: PEKERJAAN STRUKTUR | D16: ='BQ L7'!O79 -> 54709951 | E16: =D16/$D$47 -> 0.16809008 | F16: 0.23 | G16: =F16-E16 -> 0.06190992 | H16: =D16/$D$52 -> 1032263.2
A18: IV | B18: PEKERJAAN DINDING | D18: ='BQ L7'!O83 -> 26367300 | E18: =D18/$D$47 -> 0.08101052 | F18: 0.1 | G18: =F18-E18 -> 0.01898948 | H18: =D18/$D$52 -> 497496.23
A20: V | B20: PEKERJAAN PELAPIS DINDING | D20: ='BQ L7'!O93 -> 24621718 | E20: =D20/$D$47 -> 0.075647419 | F20: 0.1 | G20: =F20-E20 -> 0.024352581 | H20: =D20/$D$52 -> 464560.72
A22: VI | B22: PEKERJAAN ATAP | D22: ='BQ L7'!O103 -> 22813698 | E22: =D22/$D$47 -> 0.070092482 | F22: 0.1 | G22: =F22-E22 -> 0.029907518 | H22: =D22/$D$52 -> 430447.13
A24: VII | B24: PEKERJAAN PLAFOND | D24: ='BQ L7'!O112 -> 9348280.7 | E24: =D24/$D$47 -> 0.028721526 | F24: 0.03 | G24: =F24-E24 -> 0.0012784745 | H24: =D24/$D$52 -> 176382.65
A26: VIII | B26: PEKERJAAN LANTAI | D26: ='BQ L7'!O133 -> 17355025 | E26: =D26/$D$47 -> 0.053321332 | F26: 0.1 | G26: =F26-E26 -> 0.046678668 | H26: =D26/$D$52 -> 327453.29
A28: IX | B28: PEKERJAAN KUSEN, PINTU DAN JENDELA | D28: ='BQ L7'!O139 -> 33608660 | E28: =D28/$D$47 -> 0.10325877 | F28: 0.08 | G28: =F28-E28 -> -0.023258771 | H28: =D28/$D$52 -> 634125.66
A30: X | B30: PEKERJAAN ENGSEL DAN KUNCI | D30: ='BQ L7'!O141 -> 4650000 | E30: =D30/$D$47 -> 0.014286594 | F30: 0.02 | G30: =F30-E30 -> 0.0057134057 | H30: =D30/$D$52 -> 87735.849
A32: XI | B32: PEKERJAAN FINISHING TANGGA | D32: ='BQ L7'!O147 -> 2564388 | E32: =D32/$D$47 -> 0.0078787894 | F32: 0.04 | G32: =F32-E32 -> 0.032121211 | H32: =D32/$D$52 -> 48384.679
A34: XII | B34: PEKERJAAN PENGECATAN | D34: ='BQ L7'!O153 -> 6952892 | E34: =D34/$D$47 -> 0.021361967 | F34: 0.02 | G34: =F34-E34 -> -0.0013619671 | H34: =D34/$D$52 -> 131186.64
A36: XIII | B36: PEKERJAAN INSTALASI AIR | D36: ='BQ L7'!O168 -> 31832693 | E36: =D36/$D$47 -> 0.097802316 | F36: 0.1 | G36: =F36-E36 -> 0.0021976835 | H36: =D36/$D$52 -> 600616.85
A38: XIV | B38: PEKERJAAN INSTALASI LISTRIK | D38: ='BQ L7'!O190 -> 17821596 | E38: =D38/$D$47 -> 0.05475482 | F38: 0.03 | G38: =F38-E38 -> -0.02475482 | H38: =D38/$D$52 -> 336256.53
A40: XV | B40: PEKERJAAN ACCESSORIES SANITAIR | D40: ='BQ L7'!O203 -> 15182089 | E40: =D40/$D$47 -> 0.046645237 | F40: 0.01 | G40: =F40-E40 -> -0.036645237 | H40: =D40/$D$52 -> 286454.52
A42: XVI | B42: PEKERJAAN LAIN-LAIN | D42: ='BQ L7'!O210 -> 4328000 | E42: =D42/$D$47 -> 0.013297286 | F42: 0.002 | G42: =F42-E42 -> -0.011297286 | H42: =D42/$D$52 -> 81660.377
H43: =D43/$D$52 -> 0
A44: XVII | B44: PEKERJAAN ADDITIONAL (+/-) | D44: ='BQ L7'!O214 -> 18021000 | E44: =D44/$D$47 -> 0.055367466 | H44: =D44/$D$52 -> 340018.87
H45: =D45/$D$52 -> 0
B47: TOTAL | D47: =SUM(D12:D46) -> 3.2547995e+08 | E47: =SUM(E12:E45) -> 1 | F47: =SUM(F12:F45) -> 1 | G47: =SUM(G12:G45) -> 0.055367466 | H47: =D47-'BQ L7'!O216 -> 0 | I47: Unit Rumah
B48: Dibulatkan | D48: =ROUNDDOWN(D47,-4) -> 325470000 | E48: =D48/D52 -> 6140943.4 | G48: =F48/E48 -> 0 | H48: =F48*D52 -> 0 | I48: 187 | J48: =H48*I48 -> 0
B49: Fee & Resiko | C49: 0 | D49: =D47*C49 -> 0 | E49: =D49/D52 -> 0
B50: Biaya Percepatan | C50: 0 | D50: =D48*(C50) -> 0 | E50: =D50/D52 -> 0 | F50: 0.05
B51: Jumlah Total | D51: =SUM(D48:D50) -> 325470000
B52: Type Rumah | D52: 53
B53: Harga M2 | D53: =D51/D52 -> 6140943.4 | F53: Luas Bangunan | G53: Koef | H53: Harga Nilai Kontrak | I53: Harga Jual | J53: Dibulatkan | K53: Jumlah Harga
F54: =D52 -> 53 | G54: 0.9 | H54: =E48 -> 6140943.4 | I54: =G54*H54 -> 5526849.1 | J54: =ROUNDDOWN(I54,-4) -> 5520000 | K54: =F54*J54 -> 292560000 | L54: =1-(K54/D48) -> 0.10111531
B55: PPN 12 % | D55: =D51*0.12 -> 39056400
B56: Grand Total | D56: =D48+D49+D55 -> 364526400
B59: Harga Permeter Interior | D59: =550000000/90 -> 6111111.1 | E59: M2 | F59: =47000000*52 -> 2444000000
B60: Luas Bangunan | D60: =D52 -> 53 | E60: M2 | H60: Harga Per M2 | I60: Harga Jual | J60: Dibulatkan | K60: Jumlah Harga
B61: Jumlah Harga | D61: =D59*D60 -> 3.2388889e+08 | F61: Harga Civil & MEP | G61: 52 | H61: 4600000 | I61: =G61*H61 -> 239200000 | J61: =ROUNDDOWN(I61,-4) -> 239200000 | K61: =F61*J61 -> #VALUE! | L61: =1-(K61/D55) -> #VALUE!
...

Sheet BQ L7
A1: RENCANA ANGGARAN BIAYA KONTRAK
A2: PROYEK PEMBANGUNAN RUMAH STANDAR CLS. VARANA
A3: Tipe 6 X 14 | F3: 0.07 | G3: 1.09523 | H3: =H219 -> 414680000 | N3: 1.09523
A4: No. | B4: Uraian Pekerjaan | D4: Spesifikasi Ringkas | E4: Sat | F4: Volume | G4: Harga Satuan | H4: Jumlah Harga | K4: Harga Permeter | M4: THE AWA 2 Type 53
J5: Harga Varana Type 90 | L5: Harga The Awa 2 Type 53 | M5: Volume | N5: Harga Satuan | O5: Jumlah Harga | P5: Harga SBO | Q5: Harga Permeter | R5: Koef Eskalasi
A7: I. | B7: PEKERJAAN PERSIAPAN : | I7: Koef Type Bangunan | J7: =-(1-(90/53)) -> 0.69811321 | K7: =1-(53/90) -> 0.41111111
A8: 1 | B8: Direksi Keet & Gudang | D8: Metal / Bahan yang tidak mudah terbakar | E8: Ls | F8: 1 | G8: 750000 | H8: =F8*G8 -> 750000 | J8: =H8 -> 750000 | L8: =$J$7*J8 -> 523584.91 | M8: 1 | N8: =$L$8 -> 523584.91 | O8: =M8*N8 -> 523584.91
A9: 2 | B9: Pas. Bouwplank & Pengukuran | D9: Kayu Borneo 2/20 & Kaso 5/7 | E9: M1 | F9: 42 | G9: 16500 | H9: =F9*G9 -> 693000 | J9: =H9 -> 693000 | L9: =$J$7*J9 -> 483792.45 | M9: =(14+8)*2 -> 44 | N9: 16500 | O9: =M9*N9 -> 726000
A10: 3 | B10: Pembersihan | D10: Di Dalam Kavling | E10: M2 | F10: 98 | G10: 7500 | H10: =F10*G10 -> 735000 | J10: =H10 -> 735000 | L10: =$J$7*J10 -> 513113.21 | M10: =14*6 -> 84 | N10: 7500 | O10: =M10*N10 -> 630000
A11: 4 | B11: Air Kerja & Listrik Kerja | D11: Selama Kerja | E11: Ls | F11: 1 | G11: 95000 | H11: =F11*G11 -> 95000 | J11: =H11 -> 95000 | L11: =$J$7*J11 -> 66320.755 | M11: 1 | N11: =1500000 -> 1500000 | O11: =M11*N11 -> 1500000
A12: 5 | B12: Pengadaan & Pelaksanaan K3 (Keselamatan & Kesehatan | E12: Ls | F12: 1 | G12: 1250000 | H12: =F12*G12 -> 1250000 | J12: =H12 -> 1250000 | L12: =$J$7*J12 -> 872641.51 | M12: 1 | N12: =$L$12*0 -> 0 | O12: =M12*N12 -> 0
B13: Kerja) sesuai dengan standard safety Modernland termasuk | J13: =H13 -> 0 | L13: =$J$7*J13 -> 0 | O13: =M13*N13 -> 0
B14: pengadaan alat-alat safety seperti helm, safety shoes, | J14: =H14 -> 0 | L14: =$J$7*J14 -> 0 | O14: =M14*N14 -> 0
B15: rambu-rambu/signage metal, safety net, full body harnes, | J15: =H15 -> 0 | L15: =$J$7*J15 -> 0 | O15: =M15*N15 -> 0
B16: tabung APAR, cara penyambungan kabel, dll | J16: =H16 -> 0 | L16: =$J$7*J16 -> 0 | O16: =M16*N16 -> 0
A17: 6 | B17: Biaya Fee untuk Material MOU/PC Rate/SBO | E17: Ls | F17: 1 | H17: =F17*G17 -> 0 | J17: =H17 -> 0 | L17: =$J$7*J17 -> 0 | O17: =M17*N17 -> 0
A18: 7 | B18: Keamanan | D18: Selama Kerja | E18: Ls | F18: 1 | G18: 1250000 | H18: =F18*G18 -> 1250000 | J18: =H18 -> 1250000 | L18: =$J$7*J18 -> 872641.51 | M18: 1 | N18: =$L$18*0 -> 0 | O18: =M18*N18 -> 0
D19: Sub Total I. | H19: =SUM(H8:H18) -> 4773000 | I19: =SUM(I8:I18) -> 0 | J19: =SUM(J8:J18) -> 4773000 | K19: =H19/$H$223 -> 53033.333 | L19: =SUM(L8:L18) -> 3332094.3 | O19: =SUM(O8:O18) -> 3379584.9 | Q19: =O19/$O$223 -> 63765.753 | R19: =1-(K19/Q19)*100% -> 0.16831009
A20: II. | B20: PEKERJAAN PONDASI : | L20: =$J$7*J20 -> 0 | O20: =M20*N20 -> 0
A21: 1 | B21: Galian Tanah | D21: Manual/Excavator | E21: M3 | F21: 64.59165 | G21: 48660 | H21: =F21*G21 -> 3143029.7 | J21: =H21 -> 3143029.7 | L21: =$J$7*J21 -> 2194190.5 | M21: =Volume!Q39 -> 52.28 | N21: 48660 | O21: =M21*N21 -> 2543944.8
A22: 2 | B22: Urug Pasir Di Bawah Pondasi Pile Cap, Pondasi Rolag Bata,Pondasi tapak, Tie Beam | D22: Pasir pasang t = 5 cm | E22: M3 | F22: 1.039 | G22: 277700 | H22: =F22*G22 -> 288530.3 | J22: =H22 -> 288530.3 | L22: =$J$7*J22 -> 201426.81 | M22: =$K$7*F22 -> 0.42714444 | N22: 277700 | O22: =M22*N22 -> 118618.01
A23: 3 | B23: Lantai Kerja Di bawah Pondasi Pile Cap, Pondasi Tapak dan Tie Beam | D23: B0, t = 5 cm | E23: M3 | F23: 1.039 | G23: 638400 | H23: =F23*G23 -> 663297.6 | J23: =H23 -> 663297.6 | L23: =$J$7*J23 -> 463056.82 | M23: =$K$7*F23 -> 0.42714444 | N23: 638400 | O23: =M23*N23 -> 272689.01
A24: 4 | B24: Pondasi Tapak | D24: 0 | J24: =H24 -> 0 | L24: =$J$7*J24 -> 0 | O24: =M24*N24 -> 0
B25: - Beton | D25: K-250 Readymix | E25: M3 | F25: 2.261 | G25: 918200 | H25: =F25*G25 -> 2076050.2 | J25: =H25 -> 2076050.2 | L25: =$J$7*J25 -> 1449318.1 | M25: =Volume!$P$27 -> 2.544 | N25: =780000+150000 -> 930000 | O25: =M25*N25 -> 2365920
B26: - Besi Tulangan Ø8 | D26: BJTP 24 | E26: Kg | F26: 256.52565 | G26: 16120 | H26: =F26*G26 -> 4135193.5 | J26: =H26 -> 4135193.5 | L26: =$J$7*J26 -> 2886833.2 | M26: =M25*120 -> 305.28 | N26: =11000+5000 -> 16000 | O26: =M26*N26 -> 4884480
B27: - Bekisting | D27: 0 | E27: M2 | F27: 8.12 | G27: 82500 | H27: =F27*G27 -> 669900 | J27: =H27 -> 669900 | K27: =F27/F25 -> 3.5913313 | L27: =$J$7*J27 -> 467666.04 | M27: =M25*K27 -> 9.1363467 | N27: 105000 | O27: =M27*N27 -> 959316.41 | S27: =1.2*2.44 -> 2.928 | T27: 90000 | U27: =T27/S27 -> 30737.705 | V27: =4*13000 -> 52000 | W27: 7000 | X27: 25000
A28: 5 | B28: Pondasi Batu kali | D28: 0 | E28: M3 | F28: 21.615 | G28: 706620 | H28: =F28*G28 -> 15273591 | J28: =H28 -> 15273591 | L28: =$J$7*J28 -> 10662696 | M28: =Volume!$R$39 -> 12.666 | N28: 850000 | O28: =M28*N28 -> 10766100
A29: 6 | B29: Pedestal | D29: 0 | J29: =H29 -> 0 | L29: =$J$7*J29 -> 0 | O29: =M29*N29 -> 0
B30: - Beton | D30: K-250 Readymix | E30: M3 | F30: 0.37065 | G30: 918200 | H30: =F30*G30 -> 340330.83 | J30: =H30 -> 340330.83 | L30: =$J$7*J30 -> 237589.45 | M30: =$K$7*F30 -> 0.15237833 | N30: =$N$25 -> 930000 | O30: =M30*N30 -> 141711.85
B31: - Besi Tulangan Ø8 | D31: BJTP 24 | E31: Kg | F31: 148.06998 | G31: 16120 | H31: =F31*G31 -> 2386888.1 | J31: =H31 -> 2386888.1 | L31: =$J$7*J31 -> 1666318.1 | M31: =M30*120 -> 18.2854 | N31: =N26 -> 16000 | O31: =M31*N31 -> 292566.4
B32: - Bekisting | D32: 0 | E32: M2 | F32: 7.448 | G32: 117700 | H32: =F32*G32 -> 876629.6 | J32: =H32 -> 876629.6 | L32: =$J$7*J32 -> 611986.7 | M32: =$K$7*F32 -> 3.0619556 | N32: =N27 -> 105000 | O32: =M32*N32 -> 321505.33
A33: 7 | B33: Tie Beam | D33: 0 | J33: =H33 -> 0 | L33: =$J$7*J33 -> 0 | O33: =M33*N33 -> 0
B34: - Beton | D34: K-250 Readymix | E34: M3 | F34: 1.89375 | G34: 918200 | H34: =F34*G34 -> 1738841.2 | J34: =H34 -> 1738841.2 | L34: =$J$7*J34 -> 1213908 | M34: =Volume!L46 -> 2.13 | N34: =N30 -> 930000 | O34: =M34*N34 -> 1980900
B35: - Besi Tulangan Utama D13 | D35: BJTD 40 | E35: Kg | F35: 307.77283 | G35: 16120 | H35: =F35*G35 -> 4961298 | J35: =H35 -> 4961298 | L35: =$J$7*J35 -> 3463547.7 | M35: =M34*120 -> 255.6 | N35: =N36 -> 16000 | O35: =M35*N35 -> 4089600
B36: - Besi Sengkang Ø8 | D36: BJTP 24 | E36: Kg | F36: 60.801696 | G36: 16120 | H36: =F36*G36 -> 980123.34 | J36: =H36 -> 980123.34 | L36: =$J$7*J36 -> 684237.05 | M36: =$K$7*F36 -> 24.996253 | N36: =N26 -> 16000 | O36: =M36*N36 -> 399940.04
B37: - Bekisting | D37: 0 | E37: M2 | F37: 25.25 | G37: 117700 | H37: =F37*G37 -> 2971925 | J37: =H37 -> 2971925 | L37: =$J$7*J37 -> 2074740.1 | M37: =$K$7*F37 -> 10.380556 | N37: =N27 -> 105000 | O37: =M37*N37 -> 1089958.3
A38: 8 | B38: Pondasi Rollag batas kavling dan carport dan Teras | D38: Bata Press 1 PC : 3 PS | E38: M1 | F38: 14.96 | G38: 50296.511 | H38: =F38*G38 -> 752435.81 | J38: =H38 -> 752435.81 | L38: =$J$7*J38 -> 525285.38 | M38: =$K$7*F38 -> 6.1502222 | N38: 50296.511 | O38: =M38*N38 -> 309334.72 | T38: =300000 -> 300000
A39: 9 | B39: Pondasi Dinding penahan tanah ( Disesuaikan lapangan ) | D39: Pondasi batu kali ===> Akan menjadi kerja tambah | E39: M3 | F39: 0 | H39: =F39*G39 -> 0 | J39: =H39 -> 0 | L39: =$J$7*J39 -> 0 | O39: =M39*N39 -> 0 | T39: =3.5*1*2.5 -> 8.75
A40: 10 | B40: Urugan Tanah Kembali & Buang Tanah keluar Lokasi | D40: 0 | E40: M3 | F40: 58.3589 | G40: 35000 | H40: =F40*G40 -> 2042561.5 | J40: =H40 -> 2042561.5 | L40: =$J$7*J40 -> 1425939.2 | M40: =Volume!S39 -> 39.614 | N40: 35000 | O40: =M40*N40 -> 1386490 | T40: =T38/T39 -> 34285.714
D41: Sub Total II. | H41: =SUM(H21:H40) -> 43300626 | I41: =SUM(I21:I40) -> 0 | J41: =SUM(J21:J40) -> 43300626 | K41: =H41/$H$223 -> 481118.07 | L41: =SUM(L21:L40) -> 30228739 | O41: =SUM(O21:O40) -> 31923075 | Q41: =O41/$O$223 -> 602322.17 | R41: =1-(K41/Q41)*100% -> 0.20122803
...

Sheet Sheet4
J9: 22000000 | K9: 52 | L9: =J9/K9 -> 423076.92
N11: 2.2 | O11: m2 | P11: =N11*120 -> 264 | Q11: 11000 | R11: =P11*Q11 -> 2904000

Sheet Sheet3
K6: Harga Mang aceng | L6: 4100000 | M6: 52 | N6: =L6*M6 -> 213200000
N7: =N6+M13 -> 229880000 | O7: =N7/M6 -> 4420769.2
N8: 75000000
N9: =SUM(N7:N8) -> 304880000 | O9: =N9/M6 -> 5863076.9
K10: Plafond | L10: 90000 | M10: M2
K11: Listrik & Armatur | L11: 12000000 | M11: 52 | N11: =L11/M11 -> 230769.23 | O11: m2
M13: =N13*M11 -> 16680000 | N13: =L10+N11 -> 320769.23
K17: SBO
K18: Kusen, Jendela, Pintu, Ralling, Saniter (Toilet, Wastafel, Shower, Kran)
K22: Kusen, Jendela | L22: 20000000
K23: Pintu | L23: 20000000
K24: Saniter | L24: 21000000
K25: Ralling | L25: 5000000

Sheet HITUNGAN VOLUME
C1: FORM | G1: No. Dokumen
G2: Tgl Berlaku
C3: HITUNGAN VOLUME | G3: No Revisi
G4: Halaman
A6: PEKERJAAN | C6: : PEMBANGUNAN RUMAH TINGGAL TYPE 90
A7: LOKASI | C7: : CLUSTER VARANA JGE BOGOR - JAWA BARAT
A8: KONTRAKTOR | C8: : PT. PUTRA SUNDA MANDIRISEJAHTERA
A10: NO | B10: URAIAN | D10: UKURAN | N10: VOLUME | P10: SAT | Q10: KET
D11: P | E11: L | F11: T | G11: N1 | H11: N2 | I11: N3 | J11: N4 | K11: N5 | L11: N6 | M11: N7
A13: I. | B13: PEKERJAAN TANAH & PONDASI
A14: 1 | B14: Galian Tanah
A15: a. | B15: Galian Tanah Pilecape
C16: F1 | D16: 1.4 | E16: 1.4 | F16: =0.1+1+0.35 -> 1.45 | G16: 1 | N16: = | O16: =D16*E16*F16*G16 -> 2.842 | P16: M3
C17: F3 | D17: 1.3 | E17: 1.3 | F17: =F16 -> 1.45 | G17: 1 | N17: = | O17: =D17*E17*F17*G17 -> 2.4505
C18: F5 | D18: 0.9 | E18: 0.9 | F18: =F16 -> 1.45 | G18: 1 | N18: = | O18: =D18*E18*F18*G18 -> 1.1745
C19: F7 | D19: 1.3 | E19: 1.3 | F19: =F17 -> 1.45 | G19: 1 | N19: = | O19: =D19*E19*F19*G19 -> 2.4505
C20: F2A | D20: 1.35 | E20: 1.35 | F20: =F18 -> 1.45 | G20: 1 | N20: = | O20: =D20*E20*F20*G20 -> 2.642625
C21: F4A | D21: 1.1 | E21: 1.1 | F21: =F19 -> 1.45 | G21: 1 | N21: = | O21: =D21*E21*F21*G21 -> 1.7545
C22: F5A | D22: 0.9 | E22: 0.9 | F22: =F20 -> 1.45 | G22: 4 | N22: = | O22: =D22*E22*F22*G22 -> 4.698
C23: F6A | D23: 0.8 | E23: 0.8 | F23: =F21 -> 1.45 | G23: 1 | N23: = | O23: =D23*E23*F23*G23 -> 0.928
O24: =SUM(O16:O23) -> 18.940625 | P24: M3
A25: b. | B25: Galian Tanah Pondasi
B26: - Pondasi P1
C27: 2 | D27: =2.85-0.9-0.65 -> 1.3 | E27: 0.8 | F27: =0.1+0.7+0.35 -> 1.15 | N27: = | O27: =D27*E27*F27 -> 1.196 | P27: M3
C28: 3 | D28: =4.15-0.65-0.8 -> 2.7 | E28: =E27 -> 0.8 | F28: =F27 -> 1.15 | N28: = | O28: =D28*E28*F28 -> 2.484
C29: 6 | D29: =3-0.65-0.7 -> 1.65 | E29: =E28 -> 0.8 | F29: =F28 -> 1.15 | N29: = | O29: =D29*E29*F29 -> 1.518
C30: 8 | D30: =2.85-0.55-0.7 -> 1.6 | E30: =E29 -> 0.8 | F30: =F29 -> 1.15 | N30: = | O30: =D30*E30*F30 -> 1.472
C31: 9 | D31: =4.15-0.7-0.675 -> 2.775 | E31: =E30 -> 0.8 | F31: =F30 -> 1.15 | N31: = | O31: =D31*E31*F31 -> 2.553
C32: 11 | D32: =1.45-0.7 -> 0.75 | E32: =E31 -> 0.8 | F32: =F31 -> 1.15 | N32: = | O32: =D32*E32*F32 -> 0.69
C33: 13 | D33: =2.85 -> 2.85 | E33: =E32 -> 0.8 | F33: =F32 -> 1.15 | N33: = | O33: =D33*E33*F33 -> 2.622
C34: 15 | D34: =2.25-0.45 -> 1.8 | E34: =E33 -> 0.8 | F34: =F33 -> 1.15 | N34: = | O34: =D34*E34*F34 -> 1.656
C35: 16 | D35: =1.65-0.65 -> 1 | E35: =E34 -> 0.8 | F35: =F34 -> 1.15 | N35: = | O35: =D35*E35*F35 -> 0.92
C36: 17 | D36: 1.2 | E36: =E35 -> 0.8 | F36: =F35 -> 1.15 | N36: = | O36: =D36*E36*F36 -> 1.104
C37: 18 | D37: =2.5 -> 2.5 | E37: =E36 -> 0.8 | F37: =F36 -> 1.15 | N37: = | O37: =D37*E37*F37 -> 2.3
O38: =SUM(O27:O37) -> 18.515 | P38: M3
B39: - Pondasi P2
C40: 1 | D40: =1-0.65 -> 0.35 | E40: 0.8 | F40: =0.1+0.7+0.35 -> 1.15 | N40: = | O40: =D40*E40*F40 -> 0.322 | P40: M3
C41: 4 | D41: =2-0.45 -> 1.55 | E41: =E40 -> 0.8 | F41: =F40 -> 1.15 | N41: = | O41: =D41*E41*F41 -> 1.426
C42: 5 | D42: =3-0.45-0.675 -> 1.875 | E42: =E41 -> 0.8 | F42: =F41 -> 1.15 | N42: = | O42: =D42*E42*F42 -> 1.725
C43: 7 | D43: =3-0.45-0.4 -> 2.15 | E43: =E42 -> 0.8 | F43: =F42 -> 1.15 | N43: = | O43: =D43*E43*F43 -> 1.978
...

Sheet Harga Kusen & Pintu
B11: Harga Varana
I12: Harga Non Diskon | K12: Harga Diskon
B13: No | C13: Uraian | D13: Dimensi (M) | I13: Harga Satuan | J13: Harga Per M2 | K13: Harga Satuan | L13: Harga Per M2
B14: 1 | C14: Kusen Pintu Jendela | D14: 2.2 | E14: x | F14: 2.4 | G14: = | H14: =D14*F14 -> 5.28 | I14: 3686415 | J14: =I14/H14 -> 698184.66 | K14: 3133453 | L14: =K14/H14 -> 593457.01
B15: 2 | C15: Kusen jendela casement | D15: 1.65 | E15: x | F15: 2.4 | G15: = | H15: =D15*F15 -> 3.96 | I15: 3301230 | J15: =I15/H15 -> 833643.94 | K15: 2806046 | L15: =K15/H15 -> 708597.47
I18: Harga Non Diskon | K18: Harga Diskon
B19: No | C19: Uraian | D19: Dimensi (M) | I19: Harga Satuan | J19: Harga Per M2 | K19: Harga Satuan | L19: Harga Per M2 | N19: Qty
B20: 1 | C20: Kusen + Pintu Type PJ 1 | D20: 2.175 | E20: x | F20: 2.4 | G20: = | H20: =D20*F20 -> 5.22 | I20: 3686415 | J20: =J14 -> 698184.66 | K20: 3133453 | L20: =L14 -> 593457.01 | M20: =H20*J20 -> 3644523.9 | N20: 1 | P20: =M20*N20 -> 3644523.9
B21: =B20+1 -> 2 | C21: Kusen + Pintu Type PJ 2 | D21: 2.99 | E21: x | F21: 2.4 | G21: = | H21: =D21*F21 -> 7.176 | I21: 3301230 | J21: =J20 -> 698184.66 | K21: 2806046 | L21: =$L$20 -> 593457.01 | M21: =H21*J21 -> 5010173.1 | N21: 1 | P21: =M21*N21 -> 5010173.1
B22: =B21+1 -> 3 | C22: Kusen jendela casement J1 | D22: 2.075 | E22: x | F22: 2.3 | G22: = | H22: =D22*F22 -> 4.7725 | I22: 3301230 | J22: =J15 -> 833643.94 | K22: 2806046 | L22: =L15 -> 708597.47 | M22: =H22*J22 -> 3978565.7 | N22: 1 | P22: =M22*N22 -> 3978565.7
B23: =B22+1 -> 4 | C23: Kusen jendela casement J2 | D23: 0.8 | E23: x | F23: 0.25 | G23: = | H23: =D23*F23 -> 0.2 | I23: 3301230 | J23: =J22 -> 833643.94 | K23: 2806046 | L23: =L22 -> 708597.47 | M23: =H23*J23 -> 166728.79 | N23: 1 | P23: =M23*N23 -> 166728.79
B24: =B23+1 -> 5 | C24: Kusen jendela casement J3 | D24: 0.7 | E24: x | F24: 1.4 | G24: = | H24: =D24*F24 -> 0.98 | J24: =J23 -> 833643.94 | L24: =L23 -> 708597.47 | M24: =H24*J24 -> 816971.06 | N24: 1 | P24: =M24*N24 -> 816971.06
B25: =B24+1 -> 6 | C25: Kusen jendela casement J4 | D25: 1.548 | E25: x | F25: 2.75 | G25: = | H25: =D25*F25 -> 4.257 | J25: =J24 -> 833643.94 | L25: =L24 -> 708597.47 | M25: =H25*J25 -> 3548822.2 | N25: 1 | P25: =M25*N25 -> 3548822.2
B26: =B25+1 -> 7 | C26: Kusen jendela casement J5 | D26: 0.9 | E26: x | F26: 2.3 | G26: = | H26: =D26*F26 -> 2.07 | J26: =J25 -> 833643.94 | L26: =L25 -> 708597.47 | M26: =H26*J26 -> 1725643 | N26: 1 | P26: =M26*N26 -> 1725643
B27: =B26+1 -> 8 | C27: Kusen jendela casement J6 | D27: 1.3 | E27: x | F27: 1.4 | G27: = | H27: =D27*F27 -> 1.82 | J27: =J26 -> 833643.94 | L27: =L26 -> 708597.47 | M27: =H27*J27 -> 1517232 | N27: 1 | P27: =M27*N27 -> 1517232
P28: =SUM(P20:P27) -> 20408660
B31: No | C31: Uraian | D31: Dimensi (M) | I31: Harga Satuan
B32: 1 | C32: Daun Pintu | D32: 6 | E32: x | F32: 1 | G32: = | H32: =D32*F32 -> 6 | I32: 2200000 | J32: =H32*I32 -> 13200000
J33: =SUM(J32) -> 13200000
B34: No | C34: Uraian | D34: Vol | I34: Harga Satuan | J34: Jumlah Harga
B35: 1 | C35: Engsel Pintu | D35: 4 | E35: x | F35: 3 | G35: = | H35: =D35*F35 -> 12 | I35: 75000 | J35: =H35*I35 -> 900000
B36: 2 | C36: Kunci Pintu Utama | D36: 1 | E36: x | F36: 1 | G36: = | H36: =D36*F36 -> 1 | I36: 2700000 | J36: =H36*I36 -> 2700000
B37: 2 | C37: Kunci Pintu Indor | D37: 3 | E37: x | F37: 1 | G37: = | H37: =D37*F37 -> 3 | I37: 350000 | J37: =H37*I37 -> 1050000
J39: =SUM(J35:J38) -> 4650000

Sheet Volume
B2: LEMBAR PERHITUNGAN VOLUME PEKERJAAN
B3: PROYEK | C3: : | D3: RENOVASI A1-05
B4: LOKASI | C4: :
B5: TAHUN ANGGARAN | C5: : | D5: 2023-2024
B6: BANGUNAN | C6: : | D6: RUMAH TINGGAL JAGORAWI VARANA L7 x14
B7: GAMBAR SKET | E7: DIMENSI/PERHITUNGAN
B9: CODE | C9: : | D9: PEKERJAAN PERSIAPAN | E9: 1 | F9: Direksi Keet & Gudang | G9: = | H9: 4 | I9: x
E10: =E9+1 -> 2 | F10: Pas. Bouwplank & Pengukuran | G10: =
E11: =E10+1 -> 3 | F11: Pembersihan | G11: =
E12: =E11+1 -> 4 | F12: Air Kerja & Listrik Kerja | G12: =
E13: =E12+1 -> 5 | F13: Pengadaan & Pelaksanaan K3 (Keselamatan & Kesehatan | G13: =
F14: Kerja) sesuai dengan standard safety Modernland termasuk | G14: =
F15: pengadaan alat-alat safety seperti helm, safety shoes,
F16: rambu-rambu/signage metal, safety net, full body harnes,
F17: tabung APAR, cara penyambungan kabel, dll
E18: =E13+1 -> 6 | F18: Biaya Fee untuk Material MOU/PC Rate/SBO
E19: =E18+1 -> 7 | F19: Keamanan | G19: =
B21: CODE | C21: : | D21: PEKERJAAN FONDASI | E21: 1 | F21: Pekerjaan Fondasi
E22: A | F22: Tabel Pondasi Tapak
F23: Type Pondasi | H23: Dimensi (M) | K23: Penulangan
H24: B | I24: H | J24: T | K24: A1 | L24: A2 | M24: B1 | N24: B2 | O24: Qty
F25: F1 | H25: 1.2 | I25: 1.2 | J25: 0.15 | K25: D10-200 | L25: D10-201 | M25: D10-202 | N25: D10-203 | O25: 10 | P25: =H25*I25*J25*O25 -> 2.16 | R25: 3500
F26: F2 | H26: 0.8 | I26: 0.8 | J26: 0.15 | K26: =K25 -> D10-200 | L26: =L25 -> D10-201 | M26: =M25 -> D10-202 | N26: =N25 -> D10-203 | O26: 4 | P26: =H26*I26*J26*O26 -> 0.384 | R26: =R25/120 -> 29.166667
P27: =SUM(P25:P26) -> 2.544
E33: B | F33: Tabel Pondasi Batukali
F34: Type Pondasi | H34: Dimensi (M) | Q34: Vol Galian | R34: Vol Pond | S34: Vol Aanstampng
H35: A | I35: B | J35: H | K35: a1 | L35: a2 | M35: a3 | N35: a4 | O35: Px | P35: Py
F36: P1 | H36: 0.7 | I36: =H36/2 -> 0.35 | J36: =H36 -> 0.7 | K36: 0.2 | L36: 0.2 | M36: =L36 -> 0.2 | N36: =M36 -> 0.2 | O36: =6+1.75+1.75+6 -> 15.5 | P36: =1.2+1.5+3 -> 5.7 | Q36: =(H36+K36+L36+M36+N36)*(J36+K36)*(O36+P36) -> 28.62 | R36: =((H36+I36)/2)*J36*(O36+P36) -> 7.791
F37: P2 | H37: 0.5 | I37: =H37/2 -> 0.25 | J37: =H37 -> 0.5 | K37: 0.2 | L37: 0.2 | M37: =L37 -> 0.2 | N37: =M37 -> 0.2 | P37: =(5+4+1)*2 -> 20 | Q37: =(H37+K37+L37+M37+N37)*(J37+K37)*(O37+P37) -> 18.2 | R37: =((H37+I37)/2)*J37*(O37+P37) -> 3.75
F38: P3 | H38: =H37 -> 0.5 | I38: =I37 -> 0.25 | J38: =H38 -> 0.5 | K38: 0.2 | L38: 0.2 | M38: =L38 -> 0.2 | N38: =M38 -> 0.2 | O38: 6 | Q38: =(H38+K38+L38+M38+N38)*(J38+K38)*(O38+P38) -> 5.46 | R38: =((H38+I38)/2)*J38*(O38+P38) -> 1.125
Q39: =SUM(Q36:Q38) -> 52.28 | R39: =SUM(R36:R38) -> 12.666 | S39: =Q39-R39 -> 39.614
E40: C | F40: Tabel Sloof
F41: Type Pondasi | H41: Dimensi (M) | L41: Vol
H42: B | I42: H | J42: Px | K42: Py
F43: S1 | H43: 0.15 | I43: 0.25 | J43: =6+6+3+1.5 -> 16.5 | K43: =5.75+5.75+6 -> 17.5 | L43: =H43*I43*(J43+K43) -> 1.275
F44: S2 | H44: 0.15 | I44: 0.2 | J44: 6 | K44: =3.75+3.75+6+4.5+4.5 -> 22.5 | L44: =H44*I44*(J44+K44) -> 0.855
L46: =SUM(L43:L44) -> 2.13
E49: C | F49: Tabel Kolom
F50: Type Pondasi | H50: Dimensi (M) | L50: Vol
H51: B | I51: H | J51: t.1 | K51: t.2
...

Sheet Sheet5

Sheet Sheet2
J6: 6000000 | K6: 52 | L6: =J6*K6 -> 312000000

Sheet ANALISA PERMEN
A1: ANALISA HARGA SATUAN PEKERJAAN
A2: PERATURAN MENTERI PEKERJAAN UMUM NO. 28/PRT/M/2016 | K2: =#REF! -> #REF!
A4: A.2.2.1. HARGA SATUAN PEKERJAAN PERSIAPAN
A5: Jenis Pekerjaan | C5: : | D5: A.2.2.1.8. (K3) Pembuatan 1m2 direksi keet, los kerja dan gudang
A6: Satuan | C6: : | D6: m2
A7: NO. | B7: URAIAN | E7: Kode | F7: SATUAN | G7: Koefisien | H7: HARGA SATUAN | I7: JUMLAH HARGA
H8: (Rp.) | I8: (Rp.)
A10: 1 | B10: UPAH
C11: - | D11: Pekerja | E11: L.01 | F11: O/H | G11: 1 | H11: 133600 | I11: =G11*H11 -> 133600
C12: - | D12: Tukang Kayu | E12: L.02 | F12: O/H | G12: 2 | H12: 167000 | I12: =G12*H12 -> 334000
C13: - | D13: Kepala Tukang | E13: L.03 | F13: O/H | G13: 0.2 | H13: 200300 | I13: =G13*H13 -> 40060
C14: - | D14: Mandor | E14: L.04 | F14: O/H | G14: 0.05 | H14: 234000 | I14: =G14*H14 -> 11700
A16: 2 | B16: BAHAN
C17: - Kayu Balok 6 x 12 x 400 cm | F17: Btg | G17: 1.25 | H17: 310000 | I17: =G17*H17 -> 387500
C18: - Kayu kelas III meranti 5/7 | F18: m³ | G18: 0.186 | H18: 3500000 | I18: =G18*H18 -> 651000
C19: - Paku 5-7 | F19: kg | G19: 0.3 | H19: 18000 | I19: =G19*H19 -> 5400
C20: - PC | F20: Kg | G20: 18 | H20: 1250 | I20: =G20*H20 -> 22500
C21: - Pasir Beton | F21: m³ | G21: 0.03 | H21: 336466 | I21: =G21*H21 -> 10093.98
C22: - Split | F22: m³ | G22: 0.05 | H22: 184800 | I22: =G22*H22 -> 9240
C23: - Seng gelombang | F23: Lbr | G23: 1.5 | H23: 35000 | I23: =G23*H23 -> 52500
C24: - Triplek 4 mm | F24: Lbr | G24: 1.35 | H24: 55000 | I24: =G24*H24 -> 74250
B26: A. JUMLAH | I26: =SUM(I9:I25) -> 1731844
B27: B. BIAYA UMUM DAN KEUNTUNGAN | F27: 0 | I27: =I26*F27 -> 0
B28: C. JUMLAH (A + B) | I28: =I26+I27 -> 1731844
A31: Jenis Pekerjaan | C31: : | D31: A.2.2.1.2. (K3) Pembuatan 1m2 Pagar Sementara dari Seng Setinggi 2 m
A32: Satuan | C32: : | D32: m2
A33: NO. | B33: URAIAN | E33: Kode | F33: SATUAN | G33: Koefisien | H33: HARGA SATUAN | I33: JUMLAH HARGA
H34: (Rp.) | I34: (Rp.)
A36: 1 | B36: UPAH
C37: - | D37: Pekerja | E37: L.01 | F37: O/H | G37: 0.2 | H37: 133600 | I37: =G37*H37 -> 26720
C38: - | D38: Tukang Kayu | E38: L.02 | F38: O/H | G38: 0.4 | H38: 167000 | I38: =G38*H38 -> 66800
C39: - | D39: Kepala Tukang | E39: L.03 | F39: O/H | G39: 0.02 | H39: 200300 | I39: =G39*H39 -> 4006
C40: - | D40: Mandor | E40: L.04 | F40: O/H | G40: 0.02 | H40: 234000 | I40: =G40*H40 -> 4680
A42: 2 | B42: BAHAN
C43: - | D43: Dolken Kayu 8-10/400 cm | F43: Batang | G43: 1.25 | H43: 27500 | I43: =G43*H43 -> 34375
C44: - | D44: Semen Portland | F44: Kg | G44: 2.5 | H44: 1250 | I44: =G44*H44 -> 3125
C45: - | D45: Seng Gelombang | F45: Lbr | G45: 1.2 | H45: 35000 | I45: =G45*H45 -> 42000
C46: - | D46: Pasir Beton | F46: m3 | G46: 0.005 | H46: 336466 | I46: =G46*H46 -> 1682.33
C47: - | D47: Kerikil Beton | F47: m3 | G47: 0.009 | H47: 360000 | I47: =G47*H47 -> 3240
C48: - | D48: Kayu 5/7 | F48: m3 | G48: 0.072 | H48: 8500000 | I48: =G48*H48 -> 612000
...
